Workbook
Name BegDate1: Setup!$F$13
Name BegDate2: Setup!$G$13
Name BegDate3: Setup!$H$13
Name EndDate1: Setup!$F$14
Name EndDate2: Setup!$G$14
Name EndDate3: Setup!$H$14
Name Entity: Setup!$F$16
Name Period: Setup!$F$15

Sheet Setup
B2: Asset | C2: Liability | D2: Equity | E2: TempEq
B3: Cash | C3: Accounts Payable | D3: Common Stock | E3: Sales
B4: Accounts Receivable | C4: Accrued Expenses | D4: Retained Earnings | E4: Cost of Goods Sold
B5: Inventories | C5: Taxes Payable | E5: Selling, General & Admin Exps
B6: Property, Plant & Equipment | C6: Deferred Tax Liabilities | E6: Tax Expense
B7: Accumulated Depreciation | C7: Unearned Revenue
B8: Deferred Tax Assets
B10: Beginning balance sheet
B11: Balance Sheet | C11: Beg
B12: Assets | F12: Period 1 | G12: Period 2 | H12: Period 3
B13: Cash | C13: 100 | E13: Begin date | F13: 12/31/x0 | G13: 1/1/x2 | H13: 1/1/x3
B14: Accounts Receivable | C14: 0 | E14: End date | F14: 12/31/x1 | G14: 12/31/x2 | H14: 12/31/x3
B15: Inventories | C15: 0 | E15: Period | F15: Year
B16: Property, Plant & Equipment | C16: 0 | E16: Entity | F16: StartUp Co DefTx
B17: Accumulated Depreciation | C17: 0
B18: Deferred Tax Assets | C18: 0
B19: Total Assets | C19: =SUM(C13:C18) -> 100
B20: Liabilities
B21: Accounts Payable | C21: 0
B22: Accrued Expenses | C22: 0
B23: Taxes Payable | C23: 0
B24: Unearned Revenue | C24: 0
B25: Deferred Tax Liabilities | C25: 0
B26: Total Liabilities | C26: =SUM(C21:C25) -> 0
B27: Equities
B28: Common Stock | C28: 100
B29: Retained Earnings | C29: 0
B30: Total Equities | C30: =SUM(C28:C29) -> 100
B31: Total Liabilities + Equities | C31: =C26+C30 -> 100

Sheet Journal
A1: ref | B1: Type | C1: Dr Account | D1: Cr Account | E1: Dr Amt | F1: Cr Amt
B2: Asset | C2: Cash | G2: ="AccountTitles["&B2&"]" -> AccountTitles[Asset] | H2: Issue CS | K2: Debit Beginning Balance | P2: Credit Beginning Balance | U2: Temporary Account
B3: Equity | D3: Common Stock | G3: ="AccountTitles["&B3&"]" -> AccountTitles[Equity] | K3: AccountType | L3: Asset | M3: ="AccountTitles["&L3&"]" -> AccountTitles[Asset] | P3: AccountType | Q3: Liability | R3: ="AccountTitles["&Q3&"]" -> AccountTitles[Liability] | U3: AccountType | V3: TempEq | W3: ="AccountTitles["&V3&"]" -> AccountTitles[TempEq]
B4: Equity | D4: Additional Paid in Capital | G4: ="AccountTitles["&B4&"]" -> AccountTitles[Equity] | K4: AccountName | L4: Cash | P4: AccountName | Q4: Accounts Payable | U4: AccountName | V4: Sales
G5: ="AccountTitles["&B5&"]" -> AccountTitles[] | H5: Issue PS
B6: Asset | C6: Cash | G6: ="AccountTitles["&B6&"]" -> AccountTitles[Asset] | L6: =L4 -> Cash | Q6: =Q4 -> Accounts Payable | V6: =V4 -> Sales
B7: Equity | D7: Preferred Stock | G7: ="AccountTitles["&B7&"]" -> AccountTitles[Equity] | K7: BB | L7: =_xlfn.XLOOKUP(L6,'Financial Statements'!B2:B33,'Financial Statements'!C2:C33) -> 100 | R7: =_xlfn.XLOOKUP(Q6,'Financial Statements'!B2:B33,'Financial Statements'!C2:C33) -> 0 | S7: BB | U7: {=_xlfn._xlws.FILTER(JournalTable[ref],JournalTable[Dr Account]=V6,"")} -> CL1 | V7: {=_xlfn._xlws.FILTER(JournalTable[Dr Amt],JournalTable[Dr Account]=V6,"")} -> 0 | W7: {=_xlfn._xlws.FILTER(JournalTable[Cr Amt],JournalTable[Cr Account]=V6,"")} -> 130 | X7: {=_xlfn._xlws.FILTER(JournalTable[ref],JournalTable[Cr Account]=V6,"")} -> 1
G8: ="AccountTitles["&B8&"]" -> AccountTitles[] | H8: Issue BP | K8: {=_xlfn._xlws.FILTER(JournalTable[ref],JournalTable[Dr Account]=L6,"")} -> 0 | L8: {=_xlfn._xlws.FILTER(JournalTable[Dr Amt],JournalTable[Dr Account]=L6,"")} -> 0 | M8: {=_xlfn._xlws.FILTER(JournalTable[Cr Amt],JournalTable[Cr Account]=L6,"")} -> 0 | N8: {=_xlfn._xlws.FILTER(JournalTable[ref],JournalTable[Cr Account]=L6,"")} -> 0 | P8: {=_xlfn._xlws.FILTER(JournalTable[ref],JournalTable[Dr Account]=Q6,"")} -> 0 | Q8: {=_xlfn._xlws.FILTER(JournalTable[Dr Amt],JournalTable[Dr Account]=Q6,"")} -> 0 | R8: {=_xlfn._xlws.FILTER(JournalTable[Cr Amt],JournalTable[Cr Account]=Q6,"")} -> 0 | S8: {=_xlfn._xlws.FILTER(JournalTable[ref],JournalTable[Cr Account]=Q6,"")} -> 0 | U8: CL2 | V8: 0 | W8: 0 | X8: 2
B9: Asset | C9: Cash | G9: ="AccountTitles["&B9&"]" -> AccountTitles[Asset] | K9: 0 | L9: 0 | M9: 0 | N9: 0 | U9: CL3 | V9: 0 | W9: 0 | X9: 3
B10: Liability | D10: Bonds Payable | G10: ="AccountTitles["&B10&"]" -> AccountTitles[Liability] | K10: 0 | L10: 0 | M10: 0 | N10: 0 | U10: Cl | V10: 0
G11: ="AccountTitles["&B11&"]" -> AccountTitles[] | H11: Issue NP | K11: 0 | L11: 0 | M11: 0 | N11: 0
B12: Asset | C12: Cash | G12: ="AccountTitles["&B12&"]" -> AccountTitles[Asset] | K12: 0 | L12: 0 | M12: 0 | N12: 0
B13: Liability | D13: Notes Payable | G13: ="AccountTitles["&B13&"]" -> AccountTitles[Liability] | K13: 0 | L13: 0 | M13: 0 | N13: 0
G14: ="AccountTitles["&B14&"]" -> AccountTitles[] | H14: Issue CL | K14: 0 | L14: 0 | M14: 0 | N14: 0
B15: Asset | C15: Cash | G15: ="AccountTitles["&B15&"]" -> AccountTitles[Asset] | K15: 0 | L15: 0 | M15: 0 | N15: 1
B16: Liability | D16: Other Current Liabilities | G16: ="AccountTitles["&B16&"]" -> AccountTitles[Liability] | K16: 1 | L16: 100 | M16: 0 | N16: 1
G17: ="AccountTitles["&B17&"]" -> AccountTitles[] | H17: Issue ONL | K17: 1 | L17: 0 | M17: 50 | N17: 1
B18: Asset | C18: Cash | G18: ="AccountTitles["&B18&"]" -> AccountTitles[Asset] | K18: 2 | L18: 20 | M18: 0 | N18: 2
B19: Liability | D19: Other Noncurrent Liabilities | G19: ="AccountTitles["&B19&"]" -> AccountTitles[Liability] | K19: 3 | L19: 10 | M19: 0 | N19: 2
G20: ="AccountTitles["&B20&"]" -> AccountTitles[] | H20: Pay dividends | M20: 0 | N20: 3
B21: Liability | C21: Dividends Payable | G21: ="AccountTitles["&B21&"]" -> AccountTitles[Liability] | M21: 0 | N21: 3
B22: Asset | D22: Cash | G22: ="AccountTitles["&B22&"]" -> AccountTitles[Asset] | M22: 0 | N22: 3
G23: ="AccountTitles["&B23&"]" -> AccountTitles[] | H23: Retire BP or NP
B24: Liability | C24: Bonds Payable | G24: ="AccountTitles["&B24&"]" -> AccountTitles[Liability] | L24: =MAX(SUM(L7:L23)-SUM(M7:M23),0) -> 180 | M24: =-MIN(SUM(L7:L23)-SUM(M7:M23),0) -> 0 | Q24: =MAX(SUM(Q7:Q23)-SUM(R7:R23),0) -> 0 | R24: =-MIN(SUM(Q7:Q23)-SUM(R7:R23),0) -> 0 | V24: =MAX(SUM(V7:V23)-SUM(W7:W23),0) -> 0 | W24: =-MIN(SUM(V7:V23)-SUM(W7:W23),0) -> 130
B25: Liability | C25: Notes Payable | G25: ="AccountTitles["&B25&"]" -> AccountTitles[Liability]
B26: TempEq | C26: Loss on Retirement of Debt | G26: ="AccountTitles["&B26&"]" -> AccountTitles[TempEq]
B27: Asset | D27: Cash | G27: ="AccountTitles["&B27&"]" -> AccountTitles[Asset]
B28: TempEq | D28: Gain on Retirement of Debt | G28: ="AccountTitles["&B28&"]" -> AccountTitles[TempEq] | M28: Financing
G29: ="AccountTitles["&B29&"]" -> AccountTitles[] | H29: Buy MS | M29: Investing
B30: Asset | C30: Marketable Securities | G30: ="AccountTitles["&B30&"]" -> AccountTitles[Asset] | M30: Noncash nonoperating
B31: Asset | D31: Cash | G31: ="AccountTitles["&B31&"]" -> AccountTitles[Asset] | M31: Fair Value/Impairment
G32: ="AccountTitles["&B32&"]" -> AccountTitles[] | H32: Buy PP&E
B33: Asset | C33: Property, Plant & Equipment | G33: ="AccountTitles["&B33&"]" -> AccountTitles[Asset]
B34: Asset | D34: Cash | G34: ="AccountTitles["&B34&"]" -> AccountTitles[Asset]
G35: ="AccountTitles["&B35&"]" -> AccountTitles[] | H35: Buy Intangibles
B36: Asset | C36: Intangibles | G36: ="AccountTitles["&B36&"]" -> AccountTitles[Asset]
B37: Asset | D37: Cash | G37: ="AccountTitles["&B37&"]" -> AccountTitles[Asset]
G38: ="AccountTitles["&B38&"]" -> AccountTitles[] | H38: Buy ONA
B39: Asset | C39: Other Noncurrent Assets | G39: ="AccountTitles["&B39&"]" -> AccountTitles[Asset]
B40: Asset | D40: Cash | G40: ="AccountTitles["&B40&"]" -> AccountTitles[Asset]
...

Sheet Financial Statements
A1: OFF | B1: =Entity -> StartUp Co DefTx | E1: =Period&": "&BegDate&" to "&EndDate1 -> #NAME? | T1: =Entity -> StartUp Co DefTx
B2: Balance Sheet | C2: {=BegDate} -> #NAME? | E2: =IF(Journal!G222,"Net Income","Temporary accounts") -> Temporary accounts | H2: Statement of Changes in Shareholders' Equity | Q2: Cash Flow Statement | T2: Balance Sheet | U2: =IF(NOT(Journal!G222),"In Progress",EndDate1) -> In Progress
B3: Assets | E3: Revenues | I3: Pref Stk | J3: CS | K3: APIC | L3: RE | M3: AOCI | N3: TS | O3: Total | Q3: Cash Flow from Operations | T3: Assets
B4: Cash | C4: =Setup!C13 -> 100 | E4: Sales | F4: =SUMIF(Journal!$C$2:$C$201,E4,Journal!$E$2:$E$201)+SUMIF(Journal!$D$2:$H$201,E4,Journal!$F$2:$F$201) -> 130 | H4: Beginning Balance | I4: =C27 -> #REF! | J4: =C28 -> 100 | K4: =C29 -> #REF! | L4: =C31 -> 0 | M4: =C30 -> #REF! | N4: =C32 -> #REF! | O4: =SUM(I4:N4) -> #REF! | Q4: =IF(Journal!G222,"Net Income","Net in temporary accounts") -> Net in temporary accounts | R4: =F22 -> 96 | T4: Cash | U4: =C4+SUMIF(Journal!$C$2:$C$201,B4,Journal!$E$2:$E$201)-SUMIF(Journal!$D$2:$D$201,B4,Journal!$F$2:$F$201) -> 180
B5: Marketable Securities | C5: =Setup!#REF! -> #REF! | E5: Expenses | O5: =SUM(I5:N5) -> 0 | Q5: Adjustments: | T5: Marketable Securities | U5: =C5+SUMIF(Journal!$C$2:$C$201,B5,Journal!$E$2:$E$201)-SUMIF(Journal!$D$2:$D$201,B5,Journal!$F$2:$F$201) -> #REF!
B6: Accounts Receivable | C6: =Setup!C14 -> 0 | E6: Cost of Goods Sold | F6: =SUMIF(Journal!$C$2:$C$201,E6,Journal!$E$2:$E$201)-SUMIF(Journal!$D$2:$D$201,E6,Journal!$F$2:$F$201) -> 0 | O6: =SUM(I6:N6) -> 0 | Q6: Depreciation Expense | R6: ='IDM Worksheet'!E108 -> 0 | T6: Accounts Receivable | U6: =C6+SUMIF(Journal!$C$2:$C$201,B6,Journal!$E$2:$E$201)-SUMIF(Journal!$D$2:$D$201,B6,Journal!$F$2:$F$201) -> 0
B7: Allowance for Doubtful Accounts | C7: =Setup!#REF! -> #REF! | E7: Selling, General & Admin Exps | F7: =SUMIF(Journal!$C$2:$C$201,E7,Journal!$E$2:$E$201)-SUMIF(Journal!$D$2:$D$201,E7,Journal!$F$2:$F$201) -> 50 | O7: =SUM(I7:N7) -> 0 | Q7: Amortization Expense | R7: ='IDM Worksheet'!E109 -> 0 | T7: Allowance for Doubtful Accounts | U7: =C7+SUMIF(Journal!$C$2:$C$201,B7,Journal!$E$2:$E$201)-SUMIF(Journal!$D$2:$D$201,B7,Journal!$F$2:$F$201) -> #REF!
B8: Inventories | C8: =Setup!C15 -> 0 | E8: Interest Expense | F8: =SUMIF(Journal!$C$2:$C$201,E8,Journal!$E$2:$E$201)-SUMIF(Journal!$D$2:$D$201,E8,Journal!$F$2:$F$201) -> 0 | O8: =SUM(I8:N8) -> 0 | Q8: =E17 -> Loss on Sale of PP&E | R8: =F17 -> 0 | T8: Inventories | U8: =C8+SUMIF(Journal!$C$2:$C$201,B8,Journal!$E$2:$E$201)-SUMIF(Journal!$D$2:$D$201,B8,Journal!$F$2:$F$201) -> 0
B9: Other Current Assets | C9: =Setup!#REF! -> #REF! | E9: Tax Expense | F9: =D44+SUMIF(Journal!$C$2:$C$201,E9,Journal!$E$2:$E$201)-SUMIF(Journal!$D$2:$D$201,E9,Journal!$F$2:$F$201) -> -16 | O9: =SUM(I9:N9) -> 0 | Q9: =E18 -> Loss on Sale of Business Unit | R9: =F18 -> 0 | T9: Other Current Assets | U9: =C9+SUMIF(Journal!$C$2:$C$201,B9,Journal!$E$2:$E$201)-SUMIF(Journal!$D$2:$D$201,B9,Journal!$F$2:$F$201) -> #REF!
B10: Property, Plant & Equipment | C10: =Setup!C16 -> 0 | E10: Other Expense (Income) | F10: =D45+SUMIF(Journal!$C$2:$C$201,E10,Journal!$E$2:$E$201)-SUMIF(Journal!$D$2:$D$201,E10,Journal!$F$2:$F$201) -> 0 | O10: =SUM(I10:N10) -> 0 | Q10: =E19 -> Holding Loss on MS | R10: =F19 -> 0 | T10: Property, Plant & Equipment | U10: =C10+SUMIF(Journal!$C$2:$C$201,B10,Journal!$E$2:$E$201)-SUMIF(Journal!$D$2:$D$201,B10,Journal!$F$2:$F$201) -> 0
B11: Accumulated Depreciation | C11: =Setup!C17 -> 0 | E11: Gains | H11: Ending Balance | I11: =U27 -> #REF! | J11: =U28 -> 100 | K11: =U29 -> #REF! | L11: =U31 -> 0 | M11: =U30 -> #REF! | N11: =U32 -> #REF! | O11: =SUM(I11:N11) -> #REF! | Q11: =E20 -> Loss on Retirement of Debt | R11: =F20 -> 0 | T11: Accumulated Depreciation | U11: =C11+SUMIF(Journal!$C$2:$C$201,B11,Journal!$E$2:$E$201)-SUMIF(Journal!$D$2:$D$201,B11,Journal!$F$2:$F$201) -> 0
B12: Deferred Tax Assets | C12: =Setup!C18 -> 0 | E12: Gain on Sale of PP&E | F12: =-SUMIF(Journal!$C$2:$C$201,E12,Journal!$E$2:$E$201)+SUMIF(Journal!$D$2:$D$201,E12,Journal!$F$2:$F$201) -> 0 | Q12: =E21 -> Impairment Loss | R12: =F21 -> 0 | T12: Intangibles | U12: =C12+SUMIF(Journal!$C$2:$C$201,B12,Journal!$E$2:$E$201)-SUMIF(Journal!$D$2:$D$201,B12,Journal!$F$2:$F$201) -> 0
B13: Goodwill | C13: =Setup!#REF! -> #REF! | E13: Holding Gain on MS | F13: =-SUMIF(Journal!$C$2:$C$201,E13,Journal!$E$2:$E$201)+SUMIF(Journal!$D$2:$D$201,E13,Journal!$F$2:$F$201) -> 0 | Q13: =E12 -> Gain on Sale of PP&E | R13: =-F12 -> 0 | T13: Goodwill | U13: =C13+SUMIF(Journal!$C$2:$C$201,B13,Journal!$E$2:$E$201)-SUMIF(Journal!$D$2:$D$201,B13,Journal!$F$2:$F$201) -> #REF!
B14: Other Noncurrent Assets | C14: =Setup!#REF! -> #REF! | E14: Gain on Sale of Business Unit | F14: =-SUMIF(Journal!$C$2:$C$201,E14,Journal!$E$2:$E$201)+SUMIF(Journal!$D$2:$D$201,E14,Journal!$F$2:$F$201) -> 0 | Q14: =E13 -> Holding Gain on MS | R14: =-F13 -> 0 | T14: Other Noncurrent Assets | U14: =C14+SUMIF(Journal!$C$2:$C$201,B14,Journal!$E$2:$E$201)-SUMIF(Journal!$D$2:$D$201,B14,Journal!$F$2:$F$201) -> #REF!
B15: Total Assets | C15: =SUM(C4:C14) -> #REF! | E15: Gain on Retirement of Debt | F15: =-SUMIF(Journal!$C$2:$C$201,E15,Journal!$E$2:$E$201)+SUMIF(Journal!$D$2:$D$201,E15,Journal!$F$2:$F$201) -> 0 | Q15: =E14 -> Gain on Sale of Business Unit | R15: =-F14 -> 0 | T15: Total Assets | U15: =SUM(U4:U14) -> #REF!
B16: Liabilities | E16: Losses | Q16: =E15 -> Gain on Retirement of Debt | R16: =-F15 -> 0 | T16: Liabilities
B17: Accounts Payable | C17: =Setup!C21 -> 0 | E17: Loss on Sale of PP&E | F17: =SUMIF(Journal!$C$2:$C$201,E17,Journal!$E$2:$E$201)-SUMIF(Journal!$D$2:$D$201,E17,Journal!$F$2:$F$201) -> 0 | Q17: Equity-based Compensation | R17: ='IDM Worksheet'!K79 -> 0 | T17: Accounts Payable | U17: =C17-SUMIF(Journal!$C$2:$C$201,B17,Journal!$E$2:$E$201)+SUMIF(Journal!$D$2:$H$201,B17,Journal!$F$2:$F$201) -> 0
B18: Salaries & Wages Payable | C18: =Setup!C22 -> 0 | E18: Loss on Sale of Business Unit | F18: =SUMIF(Journal!$C$2:$C$201,E18,Journal!$E$2:$E$201)-SUMIF(Journal!$D$2:$D$201,E18,Journal!$F$2:$F$201) -> 0 | Q18: Changes due to Operations: | T18: Salaries & Wages Payable | U18: =C18-SUMIF(Journal!$C$2:$C$201,B18,Journal!$E$2:$E$201)+SUMIF(Journal!$D$2:$H$201,B18,Journal!$F$2:$F$201) -> 0
B19: Interest Payable | C19: =Setup!C24 -> 0 | E19: Holding Loss on MS | F19: =SUMIF(Journal!$C$2:$C$201,E19,Journal!$E$2:$E$201)-SUMIF(Journal!$D$2:$D$201,E19,Journal!$F$2:$F$201) -> 0 | Q19: Accounts Receivable | R19: ='IDM Worksheet'!E110-'IDM Worksheet'!F110 -> 0 | T19: Interest Payable | U19: =C19-SUMIF(Journal!$C$2:$C$201,B19,Journal!$E$2:$E$201)+SUMIF(Journal!$D$2:$H$201,B19,Journal!$F$2:$F$201) -> 0
B20: Dividends Payable | C20: =Setup!#REF! -> #REF! | E20: Loss on Retirement of Debt | F20: =SUMIF(Journal!$C$2:$C$201,E20,Journal!$E$2:$E$201)-SUMIF(Journal!$D$2:$D$201,E20,Journal!$F$2:$F$201) -> 0 | Q20: Allowance for Doubtful Accounts | R20: ='IDM Worksheet'!E111-'IDM Worksheet'!F111 -> #REF! | T20: Dividends Payable | U20: =C20-SUMIF(Journal!$C$2:$C$201,B20,Journal!$E$2:$E$201)+SUMIF(Journal!$D$2:$H$201,B20,Journal!$F$2:$F$201) -> #REF!
B21: Other Current Liabilities | C21: =Setup!#REF! -> #REF! | E21: Impairment Loss | F21: =SUMIF(Journal!$C$2:$C$201,E21,Journal!$E$2:$E$201)-SUMIF(Journal!$D$2:$D$201,E21,Journal!$F$2:$F$201) -> 0 | Q21: Inventories | R21: ='IDM Worksheet'!E112-'IDM Worksheet'!F112 -> 0 | T21: Other Current Liabilities | U21: =C21-SUMIF(Journal!$C$2:$C$201,B21,Journal!$E$2:$E$201)+SUMIF(Journal!$D$2:$H$201,B21,Journal!$F$2:$F$201) -> #REF!
B22: Bonds Payable | C22: =Setup!#REF! -> #REF! | E22: =IF(Journal!G222,"Net Income","Net in temporary accounts") -> Net in temporary accounts | F22: =F4-SUM(F6:F9)+SUM(F12:F15)-SUM(F17:F21) -> 96 | Q22: Other Current Assets | R22: ='IDM Worksheet'!E113-'IDM Worksheet'!F113 -> #REF! | T22: Bonds Payable | U22: =C22-SUMIF(Journal!$C$2:$C$201,B22,Journal!$E$2:$E$201)+SUMIF(Journal!$D$2:$H$201,B22,Journal!$F$2:$F$201) -> #REF!
B23: Notes Payable | C23: =Setup!#REF! -> #REF! | Q23: Accounts Payable | R23: ='IDM Worksheet'!E116-'IDM Worksheet'!F116 -> 0 | T23: Notes Payable | U23: =C23-SUMIF(Journal!$C$2:$C$201,B23,Journal!$E$2:$E$201)+SUMIF(Journal!$D$2:$H$201,B23,Journal!$F$2:$F$201) -> #REF!
B24: Other Noncurrent Liabilities | C24: =Setup!#REF! -> #REF! | Q24: Interest Payable | R24: ='IDM Worksheet'!E117-'IDM Worksheet'!F117 -> 0 | T24: Other Noncurrent Liabilities | U24: =C24-SUMIF(Journal!$C$2:$C$201,B24,Journal!$E$2:$E$201)+SUMIF(Journal!$D$2:$H$201,B24,Journal!$F$2:$F$201) -> #REF!
B25: Total Liabilities | C25: =SUM(C17:C24) -> #REF! | Q25: Salaries & Wages Payable | R25: ='IDM Worksheet'!E118-'IDM Worksheet'!F118 -> 0 | T25: Total Liabilities | U25: =SUM(U17:U24) -> #REF!
B26: Equities | Q26: Other Current Liabilities | R26: ='IDM Worksheet'!E119-'IDM Worksheet'!F119 -> #REF! | T26: Equities
B27: Preferred Stock | C27: =Setup!#REF! -> #REF! | Q27: Total CFO | R27: =SUM(R4:R26) -> #REF! | T27: Preferred Stock | U27: =C27-SUMIF(Journal!$C$2:$C$201,B27,Journal!$E$2:$E$201)+SUMIF(Journal!$D$2:$H$201,B27,Journal!$F$2:$F$201) -> #REF!
B28: Common Stock | C28: =Setup!C28 -> 100 | Q28: Cash Flow from Investing | T28: Common Stock | U28: =C28-SUMIF(Journal!$C$2:$C$201,B28,Journal!$E$2:$E$201)+SUMIF(Journal!$D$2:$H$201,B28,Journal!$F$2:$F$201) -> 100
B29: Additional Paid in Capital | C29: =Setup!#REF! -> #REF! | Q29: Sold PP&E | R29: =Journal!E53 -> 0 | T29: Additional Paid in Capital | U29: =C29-SUMIF(Journal!$C$2:$C$201,B29,Journal!$E$2:$E$201)+SUMIF(Journal!$D$2:$H$201,B29,Journal!$F$2:$F$201) -> #REF!
B30: AOCI | C30: =Setup!#REF! -> #REF! | Q30: Sold subsidiary | R30: =Journal!E59 -> 0 | T30: AOCI | U30: =C30-SUMIF(Journal!$C$2:$C$201,B30,Journal!$E$2:$E$201)+SUMIF(Journal!$D$2:$H$201,B30,Journal!$F$2:$F$201) -> #REF!
B31: Retained Earnings | C31: =Setup!C29 -> 0 | Q31: Bought PP&E | R31: =-Journal!F34 -> 0 | T31: Retained Earnings | U31: =C31-SUMIF(Journal!$C$2:$C$219,B31,Journal!$E$2:$E$219)+SUMIF(Journal!$D$2:$D$219,B31,Journal!$F$2:$F$219) -> 0
B32: Treasury Stock | C32: =Setup!#REF! -> #REF! | Q32: Bought intangibles | R32: =-Journal!F37 -> 0 | T32: Treasury Stock | U32: =C32-SUMIF(Journal!$C$2:$C$219,B32,Journal!$E$2:$E$219)+SUMIF(Journal!$D$2:$D$219,B32,Journal!$F$2:$F$219) -> #REF!
B33: Total Equities | C33: =SUM(C27:C32) -> #REF! | Q33: Bought subsidiary | R33: =-Journal!F51 -> 0 | T33: Total Equities | U33: =SUM(U27:U32) -> #REF!
B34: Total Liabilities + Equities | C34: =C25+C33 -> #REF! | Q34: Bought marketable securities | R34: =-Journal!F31 -> 0 | T34: Total Liabilities + Equities | U34: =U25+U33 -> #REF!
Q35: Bought other noncurrent assets | R35: =-Journal!F40 -> 0
Q36: Total CFI | R36: =SUM(R29:R35) -> 0
Q37: Cash Flow from Financing
Q38: Issued Common Stock | R38: =Journal!E2 -> 0
Q39: Issued Preferred Stock | R39: =Journal!E6 -> 0
Q40: Issued notes | R40: =Journal!E12 -> 0
...

Sheet 3 years of FSs
A1: OFF | B1: =Entity -> StartUp Co DefTx | E1: =Period&": "&BegDate1&" to "&EndDate1 -> Year: 12/31/x0 to 12/31/x1 | H1: =Entity -> StartUp Co DefTx | K1: =Period&": "&BegDate2&" to "&EndDate2 -> Year: 1/1/x2 to 12/31/x2 | N1: =Entity -> StartUp Co DefTx | Q1: =Period&": "&BegDate3&" to "&EndDate3 -> Year: 1/1/x3 to 12/31/x3 | T1: =Entity -> StartUp Co DefTx
B2: Balance Sheet | C2: =BegDate1 -> 12/31/x0 | E2: Net Income | H2: Balance Sheet | I2: =EndDate1 -> 12/31/x1 | K2: Net Income | N2: Balance Sheet | O2: =EndDate2 -> 12/31/x2 | Q2: =IF(Journal!G222,"Net Income","Temporary accounts") -> Temporary accounts | T2: Balance Sheet | U2: =EndDate3 -> 12/31/x3
B3: Assets | E3: Revenues | H3: Assets | K3: Revenues | N3: Assets | Q3: Revenues | T3: Assets
B4: Cash | C4: =Setup!C13 -> 100 | E4: Sales | F4: =SUMIFS(JournalTable[Cr Amt],JournalTable[ref],1,JournalTable[Cr Account],E4)-SUMIFS(JournalTable[Dr Amt],JournalTable[ref],1,JournalTable[Dr Account],E4) -> 130 | H4: =B4 -> Cash | I4: =C4+SUMIFS(JournalTable[Dr Amt],JournalTable[ref],1,JournalTable[Dr Account],B4)-SUMIFS(JournalTable[Cr Amt],JournalTable[ref],1,JournalTable[Cr Account],B4) -> 150 | K4: =E4 -> Sales | L4: =SUMIFS(JournalTable[Cr Amt],JournalTable[ref],2,JournalTable[Cr Account],E4)-SUMIFS(JournalTable[Dr Amt],JournalTable[ref],2,JournalTable[Dr Account],E4) -> 0 | N4: =B4 -> Cash | O4: =I4+SUMIFS(JournalTable[Dr Amt],JournalTable[ref],2,JournalTable[Dr Account],B4)-SUMIFS(JournalTable[Cr Amt],JournalTable[ref],2,JournalTable[Cr Account],B4) -> 170 | Q4: =E4 -> Sales | R4: =SUMIFS(JournalTable[Cr Amt],JournalTable[ref],3,JournalTable[Cr Account],E4)-SUMIFS(JournalTable[Dr Amt],JournalTable[ref],3,JournalTable[Dr Account],E4) -> 0 | T4: =B4 -> Cash | U4: =O4+SUMIFS(JournalTable[Dr Amt],JournalTable[ref],3,JournalTable[Dr Account],B4)-SUMIFS(JournalTable[Cr Amt],JournalTable[ref],3,JournalTable[Cr Account],B4) -> 180
B5: Accounts Receivable | C5: =Setup!C14 -> 0 | E5: Expenses | H5: =B5 -> Accounts Receivable | I5: =C5+SUMIFS(JournalTable[Dr Amt],JournalTable[ref],1,JournalTable[Dr Account],B5)-SUMIFS(JournalTable[Cr Amt],JournalTable[ref],1,JournalTable[Cr Account],B5) -> 30 | K5: Expenses | N5: =B5 -> Accounts Receivable | O5: =I5+SUMIFS(JournalTable[Dr Amt],JournalTable[ref],2,JournalTable[Dr Account],B5)-SUMIFS(JournalTable[Cr Amt],JournalTable[ref],2,JournalTable[Cr Account],B5) -> 10 | Q5: Expenses | T5: =B5 -> Accounts Receivable | U5: =O5+SUMIFS(JournalTable[Dr Amt],JournalTable[ref],3,JournalTable[Dr Account],B5)-SUMIFS(JournalTable[Cr Amt],JournalTable[ref],3,JournalTable[Cr Account],B5) -> 0
B6: Inventories | C6: =Setup!C15 -> 0 | E6: Cost of Goods Sold | F6: =-SUMIFS(JournalTable[Cr Amt],JournalTable[ref],1,JournalTable[Cr Account],E6)+SUMIFS(JournalTable[Dr Amt],JournalTable[ref],1,JournalTable[Dr Account],E6) -> 0 | H6: =B6 -> Inventories | I6: =C6+SUMIFS(JournalTable[Dr Amt],JournalTable[ref],1,JournalTable[Dr Account],B6)-SUMIFS(JournalTable[Cr Amt],JournalTable[ref],1,JournalTable[Cr Account],B6) -> 0 | K6: =E6 -> Cost of Goods Sold | L6: =-SUMIFS(JournalTable[Cr Amt],JournalTable[ref],2,JournalTable[Cr Account],E6)+SUMIFS(JournalTable[Dr Amt],JournalTable[ref],2,JournalTable[Dr Account],E6) -> 0 | N6: =B6 -> Inventories | O6: =I6+SUMIFS(JournalTable[Dr Amt],JournalTable[ref],2,JournalTable[Dr Account],B6)-SUMIFS(JournalTable[Cr Amt],JournalTable[ref],2,JournalTable[Cr Account],B6) -> 0 | Q6: =E6 -> Cost of Goods Sold | R6: =-SUMIFS(JournalTable[Cr Amt],JournalTable[ref],3,JournalTable[Cr Account],E6)+SUMIFS(JournalTable[Dr Amt],JournalTable[ref],3,JournalTable[Dr Account],E6) -> 0 | T6: =B6 -> Inventories | U6: =O6+SUMIFS(JournalTable[Dr Amt],JournalTable[ref],3,JournalTable[Dr Account],H6)-SUMIFS(JournalTable[Cr Amt],JournalTable[ref],3,JournalTable[Cr Account],H6) -> 0
B7: Property, Plant & Equipment | C7: =Setup!C16 -> 0 | E7: Selling, General & Admin Exps | F7: =-SUMIFS(JournalTable[Cr Amt],JournalTable[ref],1,JournalTable[Cr Account],E7)+SUMIFS(JournalTable[Dr Amt],JournalTable[ref],1,JournalTable[Dr Account],E7) -> 50 | H7: =B7 -> Property, Plant & Equipment | I7: =C7+SUMIFS(JournalTable[Dr Amt],JournalTable[ref],1,JournalTable[Dr Account],B7)-SUMIFS(JournalTable[Cr Amt],JournalTable[ref],1,JournalTable[Cr Account],B7) -> 0 | K7: =E7 -> Selling, General & Admin Exps | L7: =-SUMIFS(JournalTable[Cr Amt],JournalTable[ref],2,JournalTable[Cr Account],E7)+SUMIFS(JournalTable[Dr Amt],JournalTable[ref],2,JournalTable[Dr Account],E7) -> 0 | N7: =B7 -> Property, Plant & Equipment | O7: =I7+SUMIFS(JournalTable[Dr Amt],JournalTable[ref],2,JournalTable[Dr Account],B7)-SUMIFS(JournalTable[Cr Amt],JournalTable[ref],2,JournalTable[Cr Account],B7) -> 0 | Q7: =E7 -> Selling, General & Admin Exps | R7: =-SUMIFS(JournalTable[Cr Amt],JournalTable[ref],3,JournalTable[Cr Account],E7)+SUMIFS(JournalTable[Dr Amt],JournalTable[ref],3,JournalTable[Dr Account],E7) -> 0 | T7: =B7 -> Property, Plant & Equipment | U7: =O7+SUMIFS(JournalTable[Dr Amt],JournalTable[ref],3,JournalTable[Dr Account],H7)-SUMIFS(JournalTable[Cr Amt],JournalTable[ref],3,JournalTable[Cr Account],H7) -> 0
B8: Accumulated Depreciation | C8: =Setup!C17 -> 0 | E8: Tax Expense | F8: =-SUMIFS(JournalTable[Cr Amt],JournalTable[ref],1,JournalTable[Cr Account],E8)+SUMIFS(JournalTable[Dr Amt],JournalTable[ref],1,JournalTable[Dr Account],E8) -> 16 | H8: =B8 -> Accumulated Depreciation | I8: =C8+SUMIFS(JournalTable[Dr Amt],JournalTable[ref],1,JournalTable[Dr Account],B8)-SUMIFS(JournalTable[Cr Amt],JournalTable[ref],1,JournalTable[Cr Account],B8) -> 0 | K8: =E8 -> Tax Expense | L8: =-SUMIFS(JournalTable[Cr Amt],JournalTable[ref],2,JournalTable[Cr Account],E8)+SUMIFS(JournalTable[Dr Amt],JournalTable[ref],2,JournalTable[Dr Account],E8) -> 0 | N8: =B8 -> Accumulated Depreciation | O8: =I8+SUMIFS(JournalTable[Dr Amt],JournalTable[ref],2,JournalTable[Dr Account],B8)-SUMIFS(JournalTable[Cr Amt],JournalTable[ref],2,JournalTable[Cr Account],B8) -> 0 | Q8: =E8 -> Tax Expense | R8: =-SUMIFS(JournalTable[Cr Amt],JournalTable[ref],3,JournalTable[Cr Account],E8)+SUMIFS(JournalTable[Dr Amt],JournalTable[ref],3,JournalTable[Dr Account],E8) -> 0 | T8: =B8 -> Accumulated Depreciation | U8: =O8+SUMIFS(JournalTable[Dr Amt],JournalTable[ref],3,JournalTable[Dr Account],H8)-SUMIFS(JournalTable[Cr Amt],JournalTable[ref],3,JournalTable[Cr Account],H8) -> 0
B9: Deferred Tax Assets | C9: =Setup!C18 -> 0 | E9: Net Income | F9: =F4-SUM(F6:F8) -> 64 | H9: =B9 -> Deferred Tax Assets | I9: =C9+SUMIFS(JournalTable[Dr Amt],JournalTable[ref],1,JournalTable[Dr Account],B9)-SUMIFS(JournalTable[Cr Amt],JournalTable[ref],1,JournalTable[Cr Account],B9) -> 0 | K9: Net Income | L9: =L4-SUM(L6:L8) -> 0 | N9: =B9 -> Deferred Tax Assets | O9: =I9+SUMIFS(JournalTable[Dr Amt],JournalTable[ref],2,JournalTable[Dr Account],B9)-SUMIFS(JournalTable[Cr Amt],JournalTable[ref],2,JournalTable[Cr Account],B9) -> 0 | Q9: =IF(Journal!G222,"Net Income","Net in temporary accounts") -> Net in temporary accounts | R9: =R4-SUM(R6:R8) -> 0 | T9: =B9 -> Deferred Tax Assets | U9: =O9+SUMIFS(JournalTable[Dr Amt],JournalTable[ref],3,JournalTable[Dr Account],H9)-SUMIFS(JournalTable[Cr Amt],JournalTable[ref],3,JournalTable[Cr Account],H9) -> 0
B10: Total Assets | C10: =SUM(C4:C9) -> 100 | H10: Total Assets | I10: =SUM(I4:I9) -> 180 | N10: Total Assets | O10: =SUM(O4:O9) -> 180 | T10: Total Assets | U10: =SUM(U4:U9) -> 180
B11: Liabilities | H11: Liabilities | N11: Liabilities | T11: Liabilities
B12: Accounts Payable | C12: =Setup!C21 -> 0 | H12: =B12 -> Accounts Payable | I12: =C12-SUMIFS(JournalTable[Dr Amt],JournalTable[ref],1,JournalTable[Dr Account],B12)+SUMIFS(JournalTable[Cr Amt],JournalTable[ref],1,JournalTable[Cr Account],B12) -> 0 | N12: =B12 -> Accounts Payable | O12: =I12-SUMIFS(JournalTable[Dr Amt],JournalTable[ref],2,JournalTable[Dr Account],B12)+SUMIFS(JournalTable[Cr Amt],JournalTable[ref],2,JournalTable[Cr Account],B12) -> 0 | T12: =B12 -> Accounts Payable | U12: =O12-SUMIFS(JournalTable[Dr Amt],JournalTable[ref],3,JournalTable[Dr Account],B12)+SUMIFS(JournalTable[Cr Amt],JournalTable[ref],3,JournalTable[Cr Account],B12) -> 0
B13: Accrued Expenses | C13: =Setup!C22 -> 0 | H13: =B13 -> Accrued Expenses | I13: =C13-SUMIFS(JournalTable[Dr Amt],JournalTable[ref],1,JournalTable[Dr Account],B13)+SUMIFS(JournalTable[Cr Amt],JournalTable[ref],1,JournalTable[Cr Account],B13) -> 0 | N13: =B13 -> Accrued Expenses | O13: =I13-SUMIFS(JournalTable[Dr Amt],JournalTable[ref],2,JournalTable[Dr Account],B13)+SUMIFS(JournalTable[Cr Amt],JournalTable[ref],2,JournalTable[Cr Account],B13) -> 0 | T13: =B13 -> Accrued Expenses | U13: =O13-SUMIFS(JournalTable[Dr Amt],JournalTable[ref],3,JournalTable[Dr Account],B13)+SUMIFS(JournalTable[Cr Amt],JournalTable[ref],3,JournalTable[Cr Account],B13) -> 0
B14: Taxes Payable | C14: =Setup!C23 -> 0 | H14: =B14 -> Taxes Payable | I14: =C14-SUMIFS(JournalTable[Dr Amt],JournalTable[ref],1,JournalTable[Dr Account],B14)+SUMIFS(JournalTable[Cr Amt],JournalTable[ref],1,JournalTable[Cr Account],B14) -> 10 | N14: =B14 -> Taxes Payable | O14: =I14-SUMIFS(JournalTable[Dr Amt],JournalTable[ref],2,JournalTable[Dr Account],B14)+SUMIFS(JournalTable[Cr Amt],JournalTable[ref],2,JournalTable[Cr Account],B14) -> 10 | T14: =B14 -> Taxes Payable | U14: =O14-SUMIFS(JournalTable[Dr Amt],JournalTable[ref],3,JournalTable[Dr Account],B14)+SUMIFS(JournalTable[Cr Amt],JournalTable[ref],3,JournalTable[Cr Account],B14) -> 14
B15: Unearned Revenue | C15: =Setup!C24 -> 0 | H15: =B15 -> Unearned Revenue | I15: =C15-SUMIFS(JournalTable[Dr Amt],JournalTable[ref],1,JournalTable[Dr Account],B15)+SUMIFS(JournalTable[Cr Amt],JournalTable[ref],1,JournalTable[Cr Account],B15) -> 0 | N15: =B15 -> Unearned Revenue | O15: =I15-SUMIFS(JournalTable[Dr Amt],JournalTable[ref],2,JournalTable[Dr Account],B15)+SUMIFS(JournalTable[Cr Amt],JournalTable[ref],2,JournalTable[Cr Account],B15) -> 0 | T15: =B15 -> Unearned Revenue | U15: =O15-SUMIFS(JournalTable[Dr Amt],JournalTable[ref],3,JournalTable[Dr Account],B15)+SUMIFS(JournalTable[Cr Amt],JournalTable[ref],3,JournalTable[Cr Account],B15) -> 0
B16: Deferred Tax Liabilities | C16: =Setup!C25 -> 0 | H16: =B16 -> Deferred Tax Liabilities | I16: =C16-SUMIFS(JournalTable[Dr Amt],JournalTable[ref],1,JournalTable[Dr Account],B16)+SUMIFS(JournalTable[Cr Amt],JournalTable[ref],1,JournalTable[Cr Account],B16) -> 6 | N16: =B16 -> Deferred Tax Liabilities | O16: =I16-SUMIFS(JournalTable[Dr Amt],JournalTable[ref],2,JournalTable[Dr Account],B16)+SUMIFS(JournalTable[Cr Amt],JournalTable[ref],2,JournalTable[Cr Account],B16) -> 6 | T16: =B16 -> Deferred Tax Liabilities | U16: =O16-SUMIFS(JournalTable[Dr Amt],JournalTable[ref],3,JournalTable[Dr Account],B16)+SUMIFS(JournalTable[Cr Amt],JournalTable[ref],3,JournalTable[Cr Account],B16) -> 2
B17: Total Liabilities | C17: =SUM(C12:C15) -> 0 | H17: Total Liabilities | I17: =SUM(I12:I16) -> 16 | N17: Total Liabilities | O17: =SUM(O12:O16) -> 16 | T17: Total Liabilities | U17: =SUM(U12:U16) -> 16
B18: Equities | H18: Equities | N18: Equities | T18: Equities
B19: Common Stock | C19: =Setup!C28 -> 100 | H19: =B19 -> Common Stock | I19: =C19-SUMIFS(JournalTable[Dr Amt],JournalTable[ref],1,JournalTable[Dr Account],B19)+SUMIFS(JournalTable[Cr Amt],JournalTable[ref],1,JournalTable[Cr Account],B19) -> 100 | N19: =B19 -> Common Stock | O19: =I19-SUMIFS(JournalTable[Dr Amt],JournalTable[ref],2,JournalTable[Dr Account],B19)+SUMIFS(JournalTable[Cr Amt],JournalTable[ref],2,JournalTable[Cr Account],B19) -> 100 | T19: =B19 -> Common Stock | U19: =O19-SUMIFS(JournalTable[Dr Amt],JournalTable[ref],3,JournalTable[Dr Account],B19)+SUMIFS(JournalTable[Cr Amt],JournalTable[ref],3,JournalTable[Cr Account],B19) -> 100
B20: Retained Earnings | C20: =Setup!C29 -> 0 | H20: =B20 -> Retained Earnings | I20: =C20-SUMIFS(JournalTable[Dr Amt],JournalTable[ref],"=CL1",JournalTable[Dr Account],B20)+SUMIFS(JournalTable[Cr Amt],JournalTable[ref],"=CL1",JournalTable[Cr Account],B20) -> 0 | N20: =B20 -> Retained Earnings | O20: =I20-SUMIFS(JournalTable[Dr Amt],JournalTable[ref],"=CL2",JournalTable[Dr Account],B20)+SUMIFS(JournalTable[Cr Amt],JournalTable[ref],"=CL2",JournalTable[Cr Account],B20) -> 0 | T20: =B20 -> Retained Earnings | U20: =O20-SUMIFS(JournalTable[Dr Amt],JournalTable[ref],"=CL3",JournalTable[Dr Account],B20)+SUMIFS(JournalTable[Cr Amt],JournalTable[ref],"=CL3",JournalTable[Cr Account],B20) -> 0
B21: Total Equities | C21: =SUM(C19:C20) -> 100 | H21: Total Equities | I21: =SUM(I19:I20) -> 100 | N21: Total Equities | O21: =SUM(O19:O20) -> 100 | T21: Total Equities | U21: =SUM(U19:U20) -> 100
B22: Total Liabilities + Equities | C22: =C17+C21 -> 100 | H22: Total Liabilities + Equities | I22: =I17+I21 -> 116 | N22: Total Liabilities + Equities | O22: =O17+O21 -> 116 | T22: Total Liabilities + Equities | U22: =U17+U21 -> 116
E53: All Revenues zero | F53: =COUNTIF(F4,"<>0")=0 -> FALSE | K53: All Revenues zero | L53: =COUNTIF(L4,"<>0")=0 -> TRUE | Q53: All Revenues zero | R53: =COUNTIF(R4,"<>0")=0 -> TRUE
B54: All assets zero | C54: =COUNTIF(C4:C9,"<>0")=0 -> FALSE | E54: All Expenses zero | F54: =COUNTIF(F6:F8,"<>0")=0 -> FALSE | H54: All assets zero | I54: =COUNTIF(I4:I9,"<>0")=0 -> FALSE | K54: All Expenses zero | L54: =COUNTIF(L6:L8,"<>0")=0 -> TRUE | N54: All assets zero | O54: =COUNTIF(O4:O9,"<>0")=0 -> FALSE | Q54: All Expenses zero | R54: =COUNTIF(R6:R8,"<>0")=0 -> TRUE
B55: All liabilities zero | C55: =COUNTIF(C12:C15,"<>0")=0 -> TRUE | E55: All Gains zero | F55: =COUNTIF(#REF!,"<>0")=0 -> #REF! | H55: All liabilities zero | I55: =COUNTIF(I12:I15,"<>0")=0 -> FALSE | K55: All Gains zero | L55: =COUNTIF(#REF!,"<>0")=0 -> #REF! | N55: All liabilities zero | O55: =COUNTIF(O12:O15,"<>0")=0 -> FALSE | Q55: All Gains zero | R55: =COUNTIF(#REF!,"<>0")=0 -> #REF!
B56: All equities zero | C56: =COUNTIF(C19:C20,"<>0")=0 -> FALSE | E56: All Losses zero | F56: =COUNTIF(#REF!,"<>0")=0 -> #REF! | H56: All equities zero | I56: =COUNTIF(I19:I20,"<>0")=0 -> FALSE | K56: All Losses zero | L56: =COUNTIF(#REF!,"<>0")=0 -> #REF! | N56: All equities zero | O56: =COUNTIF(O19:O20,"<>0")=0 -> FALSE | Q56: All Losses zero | R56: =COUNTIF(#REF!,"<>0")=0 -> #REF!
B57: Beginning balance sheet all zero | C57: =AND(C54,C55,C56) -> FALSE | E57: All temp accounts zero | F57: =AND(F53,F54,F55,F56) -> #REF! | H57: Ending balance sheet all zero | I57: =AND(I54,I55,I56) -> FALSE | K57: All temp accounts zero | L57: =AND(L53,L54,L55,L56) -> #REF! | N57: Ending balance sheet all zero | O57: =AND(O54,O55,O56) -> FALSE | Q57: All temp accounts zero | R57: =AND(R53,R54,R55,R56) -> #REF!
B58: Both balance sheets all zero | C58: =AND(C57,I57) -> FALSE
H59: Total assets | I59: =SUM(I4:I9) -> 180 | N59: Total assets | O59: =SUM(O4:O9) -> 180
H60: Total liabilities | I60: =SUM(I12:I15) -> 10 | N60: Total liabilities | O60: =SUM(O12:O15) -> 10
H61: Total equities | I61: =SUM(I19:I20) -> 100 | N61: Total equities | O61: =SUM(O19:O20) -> 100
H62: Amount out of balance | I62: =I59-I60-I61 -> 70 | N62: Amount out of balance | O62: =O59-O60-O61 -> 70
I65: =ROUND(-SUMIF(Journal!$B$2:$B$219,"TempEq",Journal!$E$2:$E$219)+SUMIF(Journal!$B$2:$B$219,"TempEq",Journal!$F$2:$F$219),2)=0 -> FALSE | O65: =ROUND(-SUMIF(Journal!$B$2:$B$219,"TempEq",Journal!$E$2:$E$219)+SUMIF(Journal!$B$2:$B$219,"TempEq",Journal!$F$2:$F$219),2)=0 -> FALSE
I66: =ROUND(SUM(Journal!E202:E219)-SUM(Journal!F202:F219),2)=0 -> TRUE | O66: =ROUND(SUM(Journal!K202:K219)-SUM(Journal!L202:L219),2)=0 -> TRUE
B69: Total assets | C69: =SUM(C4:C9) -> 100
B70: Total liabilities | C70: =SUM(C12:C15) -> 0
B71: Total equities | C71: =SUM(C19:C20) -> 100
B72: Amount out of balance | C72: =C69-C70-C71 -> 0

Sheet 3 years of BSs
A1: OFF | B1: =Entity -> StartUp Co DefTx
B2: Balance Sheet | C2: =BegDate1 -> 12/31/x0 | D2: =EndDate1 -> 12/31/x1 | E2: =EndDate2 -> 12/31/x2 | F2: =EndDate3 -> 12/31/x3
B3: Assets
B4: Cash | C4: =Setup!C13 -> 100 | D4: =C4+SUMIFS(JournalTable[Dr Amt],JournalTable[ref],1,JournalTable[Dr Account],B4)-SUMIFS(JournalTable[Cr Amt],JournalTable[ref],1,JournalTable[Cr Account],B4) -> 150 | E4: =D4+SUMIFS(JournalTable[Dr Amt],JournalTable[ref],2,JournalTable[Dr Account],B4)-SUMIFS(JournalTable[Cr Amt],JournalTable[ref],2,JournalTable[Cr Account],B4) -> 170 | F4: =E4+SUMIFS(JournalTable[Dr Amt],JournalTable[ref],3,JournalTable[Dr Account],B4)-SUMIFS(JournalTable[Cr Amt],JournalTable[ref],3,JournalTable[Cr Account],B4) -> 180 | G4: =COUNTIF(C4:F4,"<>0") -> 4
B5: Accounts Receivable | C5: =Setup!C14 -> 0 | D5: =C5+SUMIFS(JournalTable[Dr Amt],JournalTable[ref],1,JournalTable[Dr Account],B5)-SUMIFS(JournalTable[Cr Amt],JournalTable[ref],1,JournalTable[Cr Account],B5) -> 30 | E5: =D5+SUMIFS(JournalTable[Dr Amt],JournalTable[ref],2,JournalTable[Dr Account],B5)-SUMIFS(JournalTable[Cr Amt],JournalTable[ref],2,JournalTable[Cr Account],B5) -> 10 | F5: =E5+SUMIFS(JournalTable[Dr Amt],JournalTable[ref],3,JournalTable[Dr Account],B5)-SUMIFS(JournalTable[Cr Amt],JournalTable[ref],3,JournalTable[Cr Account],B5) -> 0 | G5: =COUNTIF(C5:F5,"<>0") -> 2
B6: Inventories | C6: =Setup!C15 -> 0 | D6: =C6+SUMIFS(JournalTable[Dr Amt],JournalTable[ref],1,JournalTable[Dr Account],B6)-SUMIFS(JournalTable[Cr Amt],JournalTable[ref],1,JournalTable[Cr Account],B6) -> 0 | E6: =D6+SUMIFS(JournalTable[Dr Amt],JournalTable[ref],2,JournalTable[Dr Account],B6)-SUMIFS(JournalTable[Cr Amt],JournalTable[ref],2,JournalTable[Cr Account],B6) -> 0 | F6: =E6+SUMIFS(JournalTable[Dr Amt],JournalTable[ref],3,JournalTable[Dr Account],#REF!)-SUMIFS(JournalTable[Cr Amt],JournalTable[ref],3,JournalTable[Cr Account],#REF!) -> 0 | G6: =COUNTIF(C6:F6,"<>0") -> 0
B7: Property, Plant & Equipment | C7: =Setup!C16 -> 0 | D7: =C7+SUMIFS(JournalTable[Dr Amt],JournalTable[ref],1,JournalTable[Dr Account],B7)-SUMIFS(JournalTable[Cr Amt],JournalTable[ref],1,JournalTable[Cr Account],B7) -> 0 | E7: =D7+SUMIFS(JournalTable[Dr Amt],JournalTable[ref],2,JournalTable[Dr Account],B7)-SUMIFS(JournalTable[Cr Amt],JournalTable[ref],2,JournalTable[Cr Account],B7) -> 0 | F7: =E7+SUMIFS(JournalTable[Dr Amt],JournalTable[ref],3,JournalTable[Dr Account],#REF!)-SUMIFS(JournalTable[Cr Amt],JournalTable[ref],3,JournalTable[Cr Account],#REF!) -> 0 | G7: =COUNTIF(C7:F7,"<>0") -> 0
B8: Accumulated Depreciation | C8: =Setup!C17 -> 0 | D8: =C8+SUMIFS(JournalTable[Dr Amt],JournalTable[ref],1,JournalTable[Dr Account],B8)-SUMIFS(JournalTable[Cr Amt],JournalTable[ref],1,JournalTable[Cr Account],B8) -> 0 | E8: =D8+SUMIFS(JournalTable[Dr Amt],JournalTable[ref],2,JournalTable[Dr Account],B8)-SUMIFS(JournalTable[Cr Amt],JournalTable[ref],2,JournalTable[Cr Account],B8) -> 0 | F8: =E8+SUMIFS(JournalTable[Dr Amt],JournalTable[ref],3,JournalTable[Dr Account],#REF!)-SUMIFS(JournalTable[Cr Amt],JournalTable[ref],3,JournalTable[Cr Account],B8) -> 0 | G8: =COUNTIF(C8:F8,"<>0") -> 0
B9: Deferred Tax Assets | C9: =Setup!C18 -> 0 | D9: =C9+SUMIFS(JournalTable[Dr Amt],JournalTable[ref],1,JournalTable[Dr Account],B9)-SUMIFS(JournalTable[Cr Amt],JournalTable[ref],1,JournalTable[Cr Account],B9) -> 0 | E9: =D9+SUMIFS(JournalTable[Dr Amt],JournalTable[ref],2,JournalTable[Dr Account],B9)-SUMIFS(JournalTable[Cr Amt],JournalTable[ref],2,JournalTable[Cr Account],B9) -> 0 | F9: =E9+SUMIFS(JournalTable[Dr Amt],JournalTable[ref],3,JournalTable[Dr Account],#REF!)-SUMIFS(JournalTable[Cr Amt],JournalTable[ref],3,JournalTable[Cr Account],B9) -> 0 | G9: =COUNTIF(C9:F9,"<>0") -> 0
B10: Total Assets | C10: =SUM(C4:C9) -> 100 | D10: =SUM(D4:D9) -> 180 | E10: =SUM(E4:E9) -> 180 | F10: =SUM(F4:F9) -> 180
B11: Liabilities
B12: Accounts Payable | C12: =Setup!C21 -> 0 | D12: =C12-SUMIFS(JournalTable[Dr Amt],JournalTable[ref],1,JournalTable[Dr Account],B12)+SUMIFS(JournalTable[Cr Amt],JournalTable[ref],1,JournalTable[Cr Account],B12) -> 0 | E12: =D12-SUMIFS(JournalTable[Dr Amt],JournalTable[ref],2,JournalTable[Dr Account],B12)+SUMIFS(JournalTable[Cr Amt],JournalTable[ref],2,JournalTable[Cr Account],B12) -> 0 | F12: =E12-SUMIFS(JournalTable[Dr Amt],JournalTable[ref],3,JournalTable[Dr Account],B12)+SUMIFS(JournalTable[Cr Amt],JournalTable[ref],3,JournalTable[Cr Account],B12) -> 0 | G12: =COUNTIF(C12:F12,"<>0") -> 0
B13: Accrued Expenses | C13: =Setup!C22 -> 0 | D13: =C13-SUMIFS(JournalTable[Dr Amt],JournalTable[ref],1,JournalTable[Dr Account],B13)+SUMIFS(JournalTable[Cr Amt],JournalTable[ref],1,JournalTable[Cr Account],B13) -> 0 | E13: =D13-SUMIFS(JournalTable[Dr Amt],JournalTable[ref],2,JournalTable[Dr Account],B13)+SUMIFS(JournalTable[Cr Amt],JournalTable[ref],2,JournalTable[Cr Account],B13) -> 0 | F13: =E13-SUMIFS(JournalTable[Dr Amt],JournalTable[ref],3,JournalTable[Dr Account],B13)+SUMIFS(JournalTable[Cr Amt],JournalTable[ref],3,JournalTable[Cr Account],B13) -> 0 | G13: =COUNTIF(C13:F13,"<>0") -> 0
B14: Taxes Payable | C14: =Setup!C23 -> 0 | D14: =C14-SUMIFS(JournalTable[Dr Amt],JournalTable[ref],1,JournalTable[Dr Account],B14)+SUMIFS(JournalTable[Cr Amt],JournalTable[ref],1,JournalTable[Cr Account],B14) -> 10 | E14: =D14-SUMIFS(JournalTable[Dr Amt],JournalTable[ref],2,JournalTable[Dr Account],B14)+SUMIFS(JournalTable[Cr Amt],JournalTable[ref],2,JournalTable[Cr Account],B14) -> 10 | F14: =E14-SUMIFS(JournalTable[Dr Amt],JournalTable[ref],3,JournalTable[Dr Account],B14)+SUMIFS(JournalTable[Cr Amt],JournalTable[ref],3,JournalTable[Cr Account],B14) -> 14 | G14: =COUNTIF(C14:F14,"<>0") -> 3
B15: Unearned Revenue | C15: =Setup!C24 -> 0 | D15: =C15-SUMIFS(JournalTable[Dr Amt],JournalTable[ref],1,JournalTable[Dr Account],B15)+SUMIFS(JournalTable[Cr Amt],JournalTable[ref],1,JournalTable[Cr Account],B15) -> 0 | E15: =D15-SUMIFS(JournalTable[Dr Amt],JournalTable[ref],2,JournalTable[Dr Account],B15)+SUMIFS(JournalTable[Cr Amt],JournalTable[ref],2,JournalTable[Cr Account],B15) -> 0 | F15: =E15-SUMIFS(JournalTable[Dr Amt],JournalTable[ref],3,JournalTable[Dr Account],B15)+SUMIFS(JournalTable[Cr Amt],JournalTable[ref],3,JournalTable[Cr Account],B15) -> 0 | G15: =COUNTIF(C16:F16,"<>0") -> 3
B16: Deferred Tax Liabilities | C16: =Setup!C24 -> 0 | D16: =C16-SUMIFS(JournalTable[Dr Amt],JournalTable[ref],1,JournalTable[Dr Account],B16)+SUMIFS(JournalTable[Cr Amt],JournalTable[ref],1,JournalTable[Cr Account],B16) -> 6 | E16: =D16-SUMIFS(JournalTable[Dr Amt],JournalTable[ref],2,JournalTable[Dr Account],B16)+SUMIFS(JournalTable[Cr Amt],JournalTable[ref],2,JournalTable[Cr Account],B16) -> 6 | F16: =E16-SUMIFS(JournalTable[Dr Amt],JournalTable[ref],3,JournalTable[Dr Account],B16)+SUMIFS(JournalTable[Cr Amt],JournalTable[ref],3,JournalTable[Cr Account],B16) -> 2
B17: Total Liabilities | C17: =SUM(C12:C16) -> 0 | D17: =SUM(D12:D16) -> 16 | E17: =SUM(E12:E16) -> 16 | F17: =SUM(F12:F16) -> 16
B18: Equities | G18: =COUNTIF(C19:F19,"<>0") -> 4
B19: Common Stock | C19: =Setup!C28 -> 100 | D19: =C19-SUMIFS(JournalTable[Dr Amt],JournalTable[ref],1,JournalTable[Dr Account],B19)+SUMIFS(JournalTable[Cr Amt],JournalTable[ref],1,JournalTable[Cr Account],B19) -> 100 | E19: =D19-SUMIFS(JournalTable[Dr Amt],JournalTable[ref],2,JournalTable[Dr Account],B19)+SUMIFS(JournalTable[Cr Amt],JournalTable[ref],2,JournalTable[Cr Account],B19) -> 100 | F19: =E19-SUMIFS(JournalTable[Dr Amt],JournalTable[ref],3,JournalTable[Dr Account],B19)+SUMIFS(JournalTable[Cr Amt],JournalTable[ref],3,JournalTable[Cr Account],B19) -> 100 | G19: =COUNTIF(C20:F20,"<>0") -> 0
B20: Retained Earnings | C20: =Setup!C29 -> 0 | D20: =C20-SUMIFS(JournalTable[Dr Amt],JournalTable[ref],"=CL1",JournalTable[Dr Account],B20)+SUMIFS(JournalTable[Cr Amt],JournalTable[ref],"=CL1",JournalTable[Cr Account],B20) -> 0 | E20: =D20-SUMIFS(JournalTable[Dr Amt],JournalTable[ref],"=CL2",JournalTable[Dr Account],B20)+SUMIFS(JournalTable[Cr Amt],JournalTable[ref],"=CL2",JournalTable[Cr Account],B20) -> 0 | F20: =E20-SUMIFS(JournalTable[Dr Amt],JournalTable[ref],"=CL3",JournalTable[Dr Account],B20)+SUMIFS(JournalTable[Cr Amt],JournalTable[ref],"=CL3",JournalTable[Cr Account],B20) -> 0
B21: Total Equities | C21: =SUM(C19:C20) -> 100 | D21: =SUM(D19:D20) -> 100 | E21: =SUM(E19:E20) -> 100 | F21: =SUM(F19:F20) -> 100
B22: Total Liabilities + Equities | C22: =C17+C21 -> 100 | D22: =D17+D21 -> 116 | E22: =E17+E21 -> 116 | F22: =F17+F21 -> 116
B54: All assets zero | C54: =COUNTIF(C4:C9,"<>0")=0 -> FALSE | D54: =COUNTIF(D4:D9,"<>0")=0 -> FALSE | E54: =COUNTIF(E4:E9,"<>0")=0 -> FALSE
B55: All liabilities zero | C55: =COUNTIF(C12:C16,"<>0")=0 -> TRUE | D55: =COUNTIF(D12:D16,"<>0")=0 -> FALSE | E55: =COUNTIF(E12:E16,"<>0")=0 -> FALSE
B56: All equities zero | C56: =COUNTIF(C19:C20,"<>0")=0 -> FALSE | D56: =COUNTIF(D19:D20,"<>0")=0 -> FALSE | E56: =COUNTIF(E19:E20,"<>0")=0 -> FALSE
B57: Beginning balance sheet all zero | C57: =AND(C54,C55,C56) -> FALSE | D57: =AND(D54,D55,D56) -> FALSE | E57: =AND(E54,E55,E56) -> FALSE
B58: Both balance sheets all zero | C58: =AND(C57,D57) -> FALSE
D59: =SUM(D4:D9) -> 180 | E59: =SUM(E4:E9) -> 180
D60: =SUM(D12:D16) -> 16 | E60: =SUM(E12:E16) -> 16
D61: =SUM(D19:D20) -> 100 | E61: =SUM(E19:E20) -> 100
D62: =D59-D60-D61 -> 64 | E62: =E59-E60-E61 -> 64
D65: =ROUND(-SUMIF(Journal!$B$2:$B$219,"TempEq",Journal!$E$2:$E$219)+SUMIF(Journal!$B$2:$B$219,"TempEq",Journal!$F$2:$F$219),2)=0 -> FALSE | E65: =ROUND(-SUMIF(Journal!$B$2:$B$219,"TempEq",Journal!$E$2:$E$219)+SUMIF(Journal!$B$2:$B$219,"TempEq",Journal!$F$2:$F$219),2)=0 -> FALSE
D66: =ROUND(SUM(Journal!E202:E219)-SUM(Journal!F202:F219),2)=0 -> TRUE | E66: =ROUND(SUM(Journal!K202:K219)-SUM(Journal!L202:L219),2)=0 -> TRUE
B69: Total assets | C69: =SUM(C4:C9) -> 100
B70: Total liabilities | C70: =SUM(C12:C16) -> 0
B71: Total equities | C71: =SUM(C19:C20) -> 100
B72: Amount out of balance | C72: =C69-C70-C71 -> 0

Sheet 3 years of ISs
A1: OFF | B1: Net Income
C2: Year 1 | D2: Year 2 | E2: Year 3
B3: Revenues
B4: Sales | C4: =SUMIFS(JournalTable[Cr Amt],JournalTable[ref],1,JournalTable[Cr Account],B4)-SUMIFS(JournalTable[Dr Amt],JournalTable[ref],1,JournalTable[Dr Account],B4) -> 130 | D4: =SUMIFS(JournalTable[Cr Amt],JournalTable[ref],2,JournalTable[Cr Account],B4)-SUMIFS(JournalTable[Dr Amt],JournalTable[ref],2,JournalTable[Dr Account],B4) -> 0 | E4: =SUMIFS(JournalTable[Cr Amt],JournalTable[ref],3,JournalTable[Cr Account],B4)-SUMIFS(JournalTable[Dr Amt],JournalTable[ref],3,JournalTable[Dr Account],B4) -> 0
B5: Expenses
B6: Cost of Goods Sold | C6: =-SUMIFS(JournalTable[Cr Amt],JournalTable[ref],1,JournalTable[Cr Account],B6)+SUMIFS(JournalTable[Dr Amt],JournalTable[ref],1,JournalTable[Dr Account],B6) -> 0 | D6: =-SUMIFS(JournalTable[Cr Amt],JournalTable[ref],2,JournalTable[Cr Account],B6)+SUMIFS(JournalTable[Dr Amt],JournalTable[ref],2,JournalTable[Dr Account],B6) -> 0 | E6: =-SUMIFS(JournalTable[Cr Amt],JournalTable[ref],3,JournalTable[Cr Account],B6)+SUMIFS(JournalTable[Dr Amt],JournalTable[ref],3,JournalTable[Dr Account],B6) -> 0
B7: Selling, General & Admin Exps | C7: =-SUMIFS(JournalTable[Cr Amt],JournalTable[ref],1,JournalTable[Cr Account],B7)+SUMIFS(JournalTable[Dr Amt],JournalTable[ref],1,JournalTable[Dr Account],B7) -> 50 | D7: =-SUMIFS(JournalTable[Cr Amt],JournalTable[ref],2,JournalTable[Cr Account],B7)+SUMIFS(JournalTable[Dr Amt],JournalTable[ref],2,JournalTable[Dr Account],B7) -> 0 | E7: =-SUMIFS(JournalTable[Cr Amt],JournalTable[ref],3,JournalTable[Cr Account],B7)+SUMIFS(JournalTable[Dr Amt],JournalTable[ref],3,JournalTable[Dr Account],B7) -> 0
B8: Tax Expense | C8: =-SUMIFS(JournalTable[Cr Amt],JournalTable[ref],1,JournalTable[Cr Account],B8)+SUMIFS(JournalTable[Dr Amt],JournalTable[ref],1,JournalTable[Dr Account],B8) -> 16 | D8: =-SUMIFS(JournalTable[Cr Amt],JournalTable[ref],2,JournalTable[Cr Account],B8)+SUMIFS(JournalTable[Dr Amt],JournalTable[ref],2,JournalTable[Dr Account],B8) -> 0 | E8: =-SUMIFS(JournalTable[Cr Amt],JournalTable[ref],3,JournalTable[Cr Account],B8)+SUMIFS(JournalTable[Dr Amt],JournalTable[ref],3,JournalTable[Dr Account],B8) -> 0
B9: =IF(Journal!G222,"Net Income","Net in temporary accounts") -> Net in temporary accounts | C9: =C4-SUM(C6:C8) -> 64 | D9: =D4-SUM(D6:D8) -> 0 | E9: =E4-SUM(E6:E8) -> 0
B53: All Revenues zero | C53: =COUNTIF(C4,"<>0")=0 -> FALSE | D53: =COUNTIF(D4,"<>0")=0 -> TRUE | E53: =COUNTIF(E4,"<>0")=0 -> TRUE
B54: All Expenses zero | C54: =COUNTIF(C6:C8,"<>0")=0 -> FALSE | D54: =COUNTIF(D6:D8,"<>0")=0 -> TRUE | E54: =COUNTIF(E6:E8,"<>0")=0 -> TRUE
B55: All Gains zero | C55: =COUNTIF(#REF!,"<>0")=0 -> #REF! | D55: =COUNTIF(#REF!,"<>0")=0 -> #REF! | E55: =COUNTIF(#REF!,"<>0")=0 -> #REF!
B56: All Losses zero | C56: =COUNTIF(#REF!,"<>0")=0 -> #REF! | D56: =COUNTIF(#REF!,"<>0")=0 -> #REF! | E56: =COUNTIF(#REF!,"<>0")=0 -> #REF!
B57: All temp accounts zero | C57: =AND(C53,C54,C55,C56) -> #REF! | D57: =AND(D53,D54,D55,D56) -> #REF! | E57: =AND(E53,E54,E55,E56) -> #REF!

Sheet IDM Worksheet
B1: BegBal | E1: ΔNotDueToOps | H1: EndBal | J1: Δdue To Operations or Gain or Loss
B2: Dr | C2: Cr | E2: Dr | F2: Cr | H2: Dr | I2: Cr | J2: Dr | K2: Cr
A3: Marketable Securities | B3: ='Financial Statements'!C5 -> #REF! | D3: g | E3: =Journal!E30 -> 0 | H3: ='Financial Statements'!U5 -> #REF! | J3: =MAX(H3-B3-SUM(E3:E6)+SUM(F3:F6),0) -> #REF! | K3: =-MIN(H3-B3-SUM(E3:E6)+SUM(F3:F6),0) -> #REF!
D4: o | E4: =Journal!E42 -> 0
D5: al | E5: =Journal!E102 -> 0 | F5: =Journal!F104 -> 0 | G5: al
D6: an | E6: =Journal!E77 -> 0 | F6: =Journal!F81 -> 0 | G6: am
A7: Accounts Receivable | B7: ='Financial Statements'!C6 -> 0 | D7: o | E7: =Journal!E43 -> 0 | F7: =Journal!F66 -> 0 | G7: w | H7: ='Financial Statements'!U6 -> 0 | J7: =MAX(H7-B7-SUM(E7:E10)+SUM(F7:F10),0) -> 0 | K7: =-MIN(H7-B7-SUM(E7:E10)+SUM(F7:F10),0) -> 0
P8: =N106-O106 -> #REF!
A11: Allowance for Doubtful Accounts | C11: =-'Financial Statements'!C7 -> #REF! | I11: =-'Financial Statements'!U7 -> #REF! | J11: =-MIN(I11-C11-SUM(F11:F14)+SUM(E11:E14),0) -> #REF! | K11: =MAX(I11-C11-SUM(F11:F14)+SUM(E11:E14),0) -> #REF!
A15: Inventories | B15: ='Financial Statements'!C8 -> 0 | D15: o | E15: =Journal!E44 -> 0 | F15: =Journal!F84 -> 0 | G15: p | H15: ='Financial Statements'!U8 -> 0 | J15: =MAX(H15-B15-SUM(E15:E18)+SUM(F15:F18),0) -> 0 | K15: =-MIN(H15-B15-SUM(E15:E18)+SUM(F15:F18),0) -> 0
F16: =Journal!F67 -> 0 | G16: w
A19: Other Current Assets | B19: ='Financial Statements'!C9 -> #REF! | F19: =Journal!F68 -> 0 | G19: w | H19: ='Financial Statements'!U9 -> #REF! | J19: =MAX(H19-B19-SUM(E19:E22)+SUM(F19:F22),0) -> #REF! | K19: =-MIN(H19-B19-SUM(E19:E22)+SUM(F19:F22),0) -> #REF!
A23: Property, Plant & Equipment | B23: ='Financial Statements'!C10 -> 0 | D23: i | E23: =Journal!E33 -> 0 | F23: =Journal!F100 -> 0 | G23: ak | H23: ='Financial Statements'!U10 -> 0 | J23: =MAX(H23-B23-SUM(E23:E26)+SUM(F23:F26),0) -> 0 | K23: =-MIN(H23-B23-SUM(E23:E26)+SUM(F23:F26),0) -> 0
D24: o | E24: =Journal!E45 -> 0 | F24: =Journal!F56 -> 0 | G24: v
D25: p | E25: =Journal!E83 -> 0 | F25: =Journal!F69 -> 0 | G25: w
A27: Accumulated Depreciation | C27: =-'Financial Statements'!C11 -> 0 | D27: v | E27: =Journal!E54 -> 0 | I27: =-'Financial Statements'!U11 -> 0 | J27: =-MIN(I27-C27-SUM(F27:F30)+SUM(E27:E30),0) -> 0 | K27: =MAX(I27-C27-SUM(F27:F30)+SUM(E27:E30),0) -> 0
D28: w | E28: =Journal!E64 -> 0
A31: Intangibles | B31: ='Financial Statements'!C12 -> 0 | D31: j | E31: =Journal!E36 -> 0 | F31: =Journal!F70 -> 0 | G31: w | H31: ='Financial Statements'!U12 -> 0 | J31: =MAX(H31-B31-SUM(E31:E34)+SUM(F31:F34),0) -> 0 | K31: =-MIN(H31-B31-SUM(E31:E34)+SUM(F31:F34),0) -> 0
D32: o | E32: =Journal!E46 -> 0
A35: Goodwill | B35: ='Financial Statements'!C13 -> #REF! | D35: o | E35: =Journal!E47 -> 0 | F35: =Journal!F71 -> 0 | G35: w | H35: ='Financial Statements'!U13 -> #REF! | J35: =MAX(H35-B35-SUM(E35:E38)+SUM(F35:F38),0) -> #REF! | K35: =-MIN(H35-B35-SUM(E35:E38)+SUM(F35:F38),0) -> #REF!
A39: Other Noncurrent Assets | B39: ='Financial Statements'!C14 -> #REF! | D39: k | E39: =Journal!E39 -> 0 | H39: ='Financial Statements'!U14 -> #REF! | J39: =MAX(H39-B39-SUM(E39:E42)+SUM(F39:F42),0) -> #REF! | K39: =-MIN(H39-B39-SUM(E39:E42)+SUM(F39:F42),0) -> #REF!
A43: Accounts Payable | C43: ='Financial Statements'!C17 -> 0 | D43: w | E43: =Journal!E60 -> 0 | F43: =Journal!F48 -> 0 | G43: o | I43: ='Financial Statements'!U17 -> 0 | J43: =-MIN(I43-C43-SUM(F43:F46)+SUM(E43:E46),0) -> 0 | K43: =MAX(I43-C43-SUM(F43:F46)+SUM(E43:E46),0) -> 0
A47: Salaries & Wages Payable | C47: ='Financial Statements'!C18 -> 0 | D47: w | E47: =Journal!E61 -> 0 | F47: =Journal!F49 -> 0 | G47: o | I47: ='Financial Statements'!U18 -> 0 | J47: =-MIN(I47-C47-SUM(F47:F50)+SUM(E47:E50),0) -> 0 | K47: =MAX(I47-C47-SUM(F47:F50)+SUM(E47:E50),0) -> 0
A51: Interest Payable | C51: =Setup!C24 -> 0 | I51: ='Financial Statements'!U19 -> 0 | J51: =-MIN(I51-C51-SUM(F51:F54)+SUM(E51:E54),0) -> 0 | K51: =MAX(I51-C51-SUM(F51:F54)+SUM(E51:E54),0) -> 0
A55: Dividends Payable | C55: =Setup!#REF! -> #REF! | D55: PayDiv | E55: =F134 -> 0 | F55: =Journal!F75 -> 0 | G55: DeclDiv | I55: ='Financial Statements'!U20 -> #REF! | J55: =-MIN(I55-C55-SUM(F55:F58)+SUM(E55:E58),0) -> #REF! | K55: =MAX(I55-C55-SUM(F55:F58)+SUM(E55:E58),0) -> #REF!
A59: Other Current Liabilities | C59: ='Financial Statements'!C21 -> #REF! | D59: w | E59: =Journal!E62 -> 0 | F59: =Journal!F16 -> 0 | G59: e | I59: ='Financial Statements'!U21 -> #REF! | J59: =-MIN(I59-C59-SUM(F59:F62)+SUM(E59:E62),0) -> #REF! | K59: =MAX(I59-C59-SUM(F59:F62)+SUM(E59:E62),0) -> #REF!
F61: =Journal!F97 -> 0 | G61: t
A63: Bonds Payable | C63: ='Financial Statements'!C22 -> #REF! | D63: aq | E63: =Journal!E24 -> 0 | F63: =Journal!F10 -> 0 | G63: c | I63: ='Financial Statements'!U22 -> #REF! | J63: =-MIN(I63-C63-SUM(F63:F66)+SUM(E63:E66),0) -> #REF! | K63: =MAX(I63-C63-SUM(F63:F66)+SUM(E63:E66),0) -> #REF!
A67: Notes Payable | C67: ='Financial Statements'!C23 -> #REF! | D67: s | E67: =Journal!E93 -> 0 | F67: =Journal!F13 -> 0 | G67: d | I67: ='Financial Statements'!U23 -> #REF! | J67: =-MIN(I67-C67-SUM(F67:F70)+SUM(E67:E70),0) -> #REF! | K67: =MAX(I67-C67-SUM(F67:F70)+SUM(E67:E70),0) -> #REF!
D68: aq | E68: =Journal!E25 -> 0 | F68: =Journal!F50 -> 0 | G68: o
F69: =Journal!F87 -> 0 | G69: q
A71: Other Noncurrent Liabilities | C71: ='Financial Statements'!C25 -> #REF! | D71: w | E71: =Journal!E63 -> 0 | F71: =Journal!F19 -> 0 | G71: f | I71: ='Financial Statements'!U24 -> #REF! | J71: =-MIN(I71-C71-SUM(F71:F74)+SUM(E71:E74),0) -> #REF! | K71: =MAX(I71-C71-SUM(F71:F74)+SUM(E71:E74),0) -> #REF!
D72: q | E72: =Journal!F87 -> 0
D73: t | E73: =Journal!E96 -> 0
A75: Preferred Stock | C75: ='Financial Statements'!C27 -> #REF! | D75: r | E75: =Journal!E89 -> 0 | F75: =Journal!F7 -> 0 | G75: b | I75: ='Financial Statements'!U27 -> #REF! | J75: =-MIN(I75-C75-SUM(F75:F78)+SUM(E75:E78),0) -> #REF! | K75: =MAX(I75-C75-SUM(F75:F78)+SUM(E75:E78),0) -> #REF!
F76: =Journal!F94 -> 0 | G76: s
A79: Common Stock | C79: ='Financial Statements'!C28 -> 100 | F79: =Journal!F3 -> 0 | G79: a | I79: ='Financial Statements'!U28 -> 100 | J79: =-MIN(I79-C79-SUM(F79:F82)+SUM(E79:E82),0) -> 0 | K79: =MAX(I79-C79-SUM(F79:F82)+SUM(E79:E82),0) -> 0
F80: =Journal!F90 -> 0 | G80: r
A83: Additional Paid in Capital | C83: ='Financial Statements'!C29 -> #REF! | F83: =Journal!F4 -> 0 | G83: a | I83: ='Financial Statements'!U29 -> #REF! | J83: =-MIN(I83-C83-SUM(F83:F86)+SUM(E83:E86),0) -> #REF! | K83: =MAX(I83-C83-SUM(F83:F86)+SUM(E83:E86),0) -> #REF!
F84: =Journal!F91 -> 0 | G84: r
...

Sheet PairwiseIncrDecrAccnts
F1: Contributed | H1: Earned
B2: Asset | D2: Liability | F2: Equity | H2: Revenue | I2: Expense
B3: Incr | C3: Decr | D3: Incr | E3: Decr | F3: Incr | G3: Decr | H3: Incr | I3: Incr
A4: Asset | B4: x | C4: x
A5: Asset | B5: x | D5: x
A6: Asset | B6: x | F6: x
A7: Asset | B7: x | H7: x
A8: Asset | C8: x | E8: x
A9: Asset | C9: x | G9: x
A10: Asset | C10: x | I10: x
A11: Liability | D11: x | E11: x
A12: Liability | D12: x | G12: x
A13: Liability | D13: x | I13: x
A14: Liability | E14: x | F14: x
A15: Liability | E15: x | H15: x
A16: Liability
A17: Equity | F17: x | G17: x
A18: Equity | F18: x | I18: x | J18: Example: Equity-based compensaiton
A19: Equity | G19: x | H19: x | J19: Example: Supply services to a shareholder who gives up shares as compensation.
B22: Possible interactions among accounts in transactions that only involve 2 accounts
B23: Note: No reason to have an entry (except closing) that includes both a revenue and an expense.
F25: Contributed | H25: Earned
B26: Asset | D26: Liability | F26: Equity | H26: Revenue | I26: Expense
B27: Incr | C27: Decr | D27: Incr | E27: Decr | F27: Incr | G27: Decr | H27: Incr | I27: Incr
A28: Asset | B28: x | C28: x | D28: x | F28: x | H28: x
A29: Asset | B29: x | C29: x | E29: x | G29: x | I29: x
A30: Liability | C30: x | D30: x | E30: x | G30: x | I30: x
A31: Liability | C31: x | D31: x | E31: x | F31: x | H31: x
A32: Equity | B32: x | E32: x | F32: x | G32: x | I32: x
A33: Equity | C33: x | D33: x | F33: x | G33: x | H33: x
