Workbook
Name All_Type: 'Account Names'!$A$23:$A$27
Name Asset: 'Account Names'!$B$2:$B$17
Name BegDate: 'Basic Inputs'!$B$5
Name CA2_: 'Basic Inputs'!$B$13
Name CA2_BB: 'Basic Inputs'!$C$13
Name CA2_EB: 'T accnts'!$F$11
Name CA3_: 'Basic Inputs'!$B$14
Name CA3_BB: 'Basic Inputs'!$C$14
Name CA3_Contra: 'Basic Inputs'!$B$15
Name CA3_Contra_BB: 'Basic Inputs'!$D$15
Name CA3_Contra_EB: 'T accnts'!$K$19
Name CA3_EB: 'T accnts'!$J$11
Name CA4_: 'Basic Inputs'!$B$16
Name CA4_BB: 'Basic Inputs'!$C$16
Name CA4_Contra: 'Basic Inputs'!$B$17
Name CA4_Contra_BB: 'Basic Inputs'!$D$17
Name CA4_Contra_EB: 'T accnts'!$O$19
Name CA4_EB: 'T accnts'!$N$11
Name CA5_: 'Basic Inputs'!$B$18
Name CA5_BB: 'Basic Inputs'!$C$18
Name CA5_EB: 'T accnts'!$F$19
Name CA6_: 'Basic Inputs'!$B$19
Name CA6_BB: 'Basic Inputs'!$C$19
Name CA6_EB: 'T accnts'!$F$27
Name CA7_: 'Basic Inputs'!$B$20
Name CA7_BB: 'Basic Inputs'!$C$20
Name CA7_EB: 'T accnts'!$J$27
Name Cash_: 'Basic Inputs'!$B$12
Name Cash_BB: 'Basic Inputs'!$C$12
Name Cash_EB: 'T accnts'!$B$27
Name CL1_: 'Basic Inputs'!$B$27
Name CL1_BB: 'Basic Inputs'!$D$27
Name CL1_EB: 'T accnts'!$C$57
Name CL2_: 'Basic Inputs'!$B$28
Name CL2_BB: 'Basic Inputs'!$D$28
Name CL2_EB: 'T accnts'!$G$50
Name CL3_: 'Basic Inputs'!$B$29
Name CL3_BB: 'Basic Inputs'!$D$29
Name CL3_EB: 'T accnts'!$K$50
Name CL4_: 'Basic Inputs'!$B$30
Name CL4_BB: 'Basic Inputs'!$D$30
Name CL4_EB: 'T accnts'!$O$50
Name CL5_: 'Basic Inputs'!$B$31
Name CL5_BB: 'Basic Inputs'!$D$31
Name CL5_EB: 'T accnts'!$G$57
Name CL6_: 'Basic Inputs'!$B$32
Name CL6_BB: 'Basic Inputs'!$D$32
Name CL6_EB: 'T accnts'!$K$57
Name CL7_: 'Basic Inputs'!$B$33
Name CL7_BB: 'Basic Inputs'!$D$33
Name CL7_EB: 'T accnts'!$O$57
Name Contra_Equity_BB: 'Basic Inputs'!$C$46
Name Contra_Equity_EB: 'T accnts'!$N$88
Name Contra_Equity1: 'Basic Inputs'!$B$46
Name Contributed_Equity: 'Account Names'!$D$2:$D$4
Name Current_Asset: 'Account Names'!$B$2:$B$12
Name Current_Liability: 'Account Names'!$C$2:$C$9
Name EndDate: 'Basic Inputs'!$B$6
Name Entity: 'Basic Inputs'!$B$3
Name Equity: 'Account Names'!$D$2:$D$7

Sheet Instructions

Sheet Basic Inputs
A1: Entity & Period Information
A2: Item | B2: Value
A3: Entity | B3: ImmuCell Corp.
A4: Entity Type | B4: For-Profit | C4: For Beginning Balances Entered Below
A5: BegDate | B5: [BegDate] | C5: Total Assets Entered: | D5: =ROUND(SUM(C12:C26)-SUM(D12:D26),1) -> 0
A6: EndDate | B6: [EndDate] | C6: Total Liabilities Entered: | D6: =ROUND(SUM(D27:D40),1) -> 0
A7: Period | B7: [Period] | C7: Total Equities Entered: | D7: =ROUND(SUM(D41:D46)-SUM(C41:C46),1) -> 0
A8: Units | B8: [Units] | C8: Amount out of Balance: | D8: =D5-D6-D7 -> 0
A10: Permanent Accounts
A11: Account Type | B11: Account Name | C11: Beginning Balance Dr | D11: Beginning Balance Cr
A12: Asset | B12: Cash
A13: Asset | B13: Current Asset 2
A14: Asset | B14: Current Asset 3
A15: Asset | B15: Contra to Current Asset 3
A16: Asset | B16: Current Asset 4
A17: Asset | B17: Contra to Current Asset 4
A18: Asset | B18: Current Asset 5
A19: Asset | B19: Current Asset 6
A20: Asset | B20: Current Asset 7
A21: Asset | B21: Property, Plant & Equipment
A22: Asset | B22: Accumulated Depreciation
A23: Asset | B23: Property, Plant & Equipment
... A46: Equity | B46: Contra Equity 1
A48: Temporary Accounts
A50: Account Type | B50: Name
A51: TempEquity | B51: Revenue 1
A52: TempEquity | B52: Revenue 2
A53: TempEquity | B53: Expense 1
A54: TempEquity | B54: Expense 2
A55: TempEquity | B55: Expense 3
A56: TempEquity | B56: Expense 4
A57: TempEquity | B57: Expense 5
A58: TempEquity | B58: Expense 6
A59: TempEquity | B59: Expense 7
A60: TempEquity | B60: Expense 8
A61: TempEquity | B61: Gain 1
... A64: TempEquity | B64: Loss 2

Sheet Journal
A1: Transactions and Information | B1: Ref. | C1: Journal (click for instructions) | J1: OIF | K1: $
C2: AccntType | D2: Account to Debit | E2: Account to Credit | F2: Amount to Debit | G2: Amount to Credit | H2: Posted? | I2: Debits-Credits | K2: $
A3: On October 1, 2019, issued 5 thousand shares of common stock for $225 thousand. | B3: a | I3: =SUM(F3:F4)-SUM(G3:G4) -> 0
A5: Purchased merchandise inventory on account from various suppliers for $900 thousand. | B5: b | I5: =SUM(F5:F6)-SUM(G5:G6) -> 0
A7: Incurred Salary expenses of $863 thousand. | B7: c | I7: =SUM(F7:F8)-SUM(G7:G8) -> 0
A9: Paid cash for salaries to employees in the amount of $950 thousand. | B9: d | I9: =SUM(F9:F10)-SUM(G9:G10) -> 0
A11: Sales were $2,500 thousand, all on account. | B11: e | I11: =SUM(F11:F12)-SUM(G11:G12) -> 0
A13: Collected accounts receivable of $2,450 thousand. | B13: f | I13: =SUM(F13:F14)-SUM(G13:G14) -> 0
A15: Paid rent of $450 thousand for the months of October 2019 through March 2020. (Record rent expense and Prepaid Rent in this one Journal entry.) | B15: g | I15: =SUM(F15:F17)-SUM(G15:G17) -> 0
A18: Depreciation expense for October through December 2019 was $20 thousand. | B18: h | I18: =SUM(F18:F19)-SUM(G18:G19) -> 0
A20: Paid accounts payable of $860 thousand. | B20: i | I20: =SUM(F20:F21)-SUM(G20:G21) -> 0
A22: On October 7, paid dividends of $5 thousand. | B22: j | I22: =SUM(F22:F23)-SUM(G22:G23) -> 0
A24: The 180-day note payable was issued on September 30, 2019 and carries an interest rate of 1% per quarter, therefore interest expense on the note for the quarter ended December 31, 2019 is $2 thousand. All interest on the note will be paid when the note matures on April 30, 2020. | B24: k | I24: =SUM(F24:F25)-SUM(G24:G25) -> 0
A26: The bonds payable were issued on September 30, 2019, and interest is not payable until the bonds mature on October 31, 2024. For the quarter ended December 31, 2019, the accrued interest on the bonds was $1 thousand. | B26: l | I26: =SUM(F26:F27)-SUM(G26:G27) -> 0
A28: Received cash payments totaling $69 thousand for services to be performed in January 2020. | B28: m | I28: =SUM(F28:F29)-SUM(G28:G29) -> 0
A30: At the close of business on December 31, 2019, bought a building for $200 thousand cash. | B30: n | I30: =SUM(F30:F31)-SUM(G30:G31) -> 0
A32: Cost of Goods Sold for the quarter was $983 thousand. | B32: o | I32: =SUM(F32:F33)-SUM(G32:G33) -> 0
A34: On October 15, 2018, declared a dividend to shareholders as of the close of business on September 20, 2019 of $0.10 per share payable on January 15, 2020. There were 185 thousand shares outstanding as of Sept 20, 2019. | B34: p | I34: =SUM(F34:F35)-SUM(G34:G35) -> 0
A36: On December 31, 2019, paid $210 thousand in cash for GoldMine Inc.. GoldMine Inc. had only three identifiable assets, Accounts Receivable with a fair market value on December 31 of $55 thousand, Inventories with a fair market value on December 31 of $45 thousand and Property & Equipment with a fair market value on December 31 of $100 thousand. | B36: q | I36: =SUM(F36:F42)-SUM(G36:G42) -> 0
H41: =IF(AND(F41="",G41=""),,"No") -> 0
H42: =IF(AND(F42="",G42=""),,"No") -> 0
A43: Traded nine thousand shares of its common stock for a building valued at $405 thousand on December 31, 2019. | B43: r | I43: 0
A45: On December 31, 2019, sold an X-ray device (Property, Plant & Equipment) with a cost of $60 thousand and accumulated depreciation of $15 thousand (as of December 31) for $47 thousand cash. | B45: s | I45: =SUM(F45:F48)-SUM(G45:G48) -> 0
A49: On December 31, 2019, provided additional compensation to employees by granting them 1 thousand shares of Rusher Co. common stock. The fair market value of the stock on the date of the grant was $45 thousand. | B49: t | I49: =SUM(F49:F50)-SUM(G49:G50) -> 0
A51: Was notified that a customer owing $3 thousand that was due in 30 days had declared bankruptcy and the court had nullified the debt. This was the first bad debt in the history of Rusher Co. Further, there is no reason to expect any of Rusher Co.’s other customers to fail to pay the entire amounts owed. | B51: u | I51: =SUM(F51:F52)-SUM(G51:G52) -> 0
A53: On December 31, 2019, sold a business unit (Expendable Division) for $120 thousand cash. The business unit had the following assets and liabilities at December 31: Accounts Receivable $48, Inventories $10, Equipment which cost $80 and had Accumulated Depreciation of $21, Accounts Payable $15 | B53: v | I53: =SUM(F53:F59)-SUM(G53:G59) -> 0
B60: w | H60: =IF(AND(F60="",G60=""),,"No") -> 0 | I60: =SUM(F60:F61)-SUM(G60:G61) -> 0
H61: =IF(AND(F61="",G61=""),,"No") -> 0
B62: x | H62: =IF(AND(F62="",G62=""),,"No") -> 0 | I62: =SUM(F62:F63)-SUM(G62:G63) -> 0
H63: =IF(AND(F63="",G63=""),,"No") -> 0
A64: Remember to close the Temporary Equity accounts! | B64: y | I64: =SUM(F64:F76)-SUM(G64:G76) -> 0
H75: =IF(AND(F75="",G75=""),,"No") -> 0
H76: =IF(AND(F76="",G76=""),,"No") -> 0
H77: =IF(AND(F77="",G77=""),,"No") -> 0 | I77: =SUM(F77:F78)-SUM(G77:G78) -> 0
H78: =IF(AND(F78="",G78=""),,"No") -> 0

Sheet T accnts
A1: =Entity -> ImmuCell Corp. | Q1: Amount out of Balance | R1: Assets | S1: Liabilities | T1: Equities | U1: Temporary Eq's | V1: Liabilities+Equities
A2: General Ledger | Q2: =R2-V2 -> 0 | R2: =B27+F11+J11+N11+B34+F19-G42+J27+F34-K19+F27-C42+J34+N34-O19 -> 0 | S2: =C57+G50+K50+O50+C64+G64+K64+O64+C70+G70+K70+G57+K57+O57 -> 0 | T2: =C80+G80+K80+O80+C88-N80-N88-B88 -> 0 | U2: =C97-B106-F106-J106-F113-J113-B113-N106-N113+G97+K97+O97-B120-F120 -> 0 | V2: =S2+T2+U2 -> 0
A3: =BegDate&" to "&EndDate -> [BegDate] to [EndDate] | Q3: (Taccnts)-(Journal) | R3: Drs (Posted-Journal) | S3: Crs (Posted-Journal)
A4: =Units -> [Units] | Q4: =R4-S4 -> 0 | R4: =SUM(B8:B26)+SUM(J8:J10)+SUM(N8:N10)+SUM(F16:F18)+SUM(F24:F26)+SUM(J24:J26)+SUM(B31:B33)+SUM(B39:B41)+SUM(F31:F33)+SUM(F39:F41)+SUM(J16:J18)+SUM(J31:J33)+SUM(N31:N33)+SUM(N16:N18)+SUM(F47:F49)+SUM(F54:F56)+SUM(B76:B79)+SUM(J54:J56)+SUM(B47:B56)+SUM(N54:N56)+SUM(J47:J49)+SUM(F8:F10)+SUM(N62:N63)+SUM(J62:J63)+SUM(F62:F63)+SUM(B62:B63)+SUM(J68:J69)+SUM(F68:F69)+SUM(B68:B69)+SUM(F76:F79)+SUM(J76:J79)+SUM(N76:N79)+SUM(N47:N49)+SUM(N84:N87)+SUM(B93:B96)+SUM(F93:F96)+SUM(J93:J96)+SUM(N93:N96)+SUM(N101:N105)+SUM(J101:J105)+SUM(F101:F105)+SUM(B101:B105)+SUM(N109:N112)+SUM(J109:J112)+SUM(B109:B112)+SUM(B84:B87)+SUM(B116:B119)+SUM(F109:F112)+SUM(F116:F119)-SUM(Journal!F3:F78) -> 0 | S4: =SUM(C8:C26)+SUM(K8:K10)+SUM(O8:O10)+SUM(G16:G18)+SUM(G24:G26)+SUM(K24:K26)+SUM(C31:C33)+SUM(C39:C41)+SUM(G31:G33)+SUM(G39:G41)+SUM(K16:K18)+SUM(K31:K33)+SUM(O31:O33)+SUM(O16:O18)+SUM(G47:G49)+SUM(G54:G56)+SUM(C76:C79)+SUM(K54:K56)+SUM(C47:C56)+SUM(O54:O56)+SUM(K47:K49)+SUM(G8:G10)+SUM(O62:O63)+SUM(K62:K63)+SUM(G62:G63)+SUM(C62:C63)+SUM(K68:K69)+SUM(G68:G69)+SUM(C68:C69)+SUM(G76:G79)+SUM(K76:K79)+SUM(O76:O79)+SUM(O47:O49)+SUM(O85:O87)+SUM(C93:C96)+SUM(G93:G96)+SUM(K93:K96)+SUM(O93:O96)+SUM(O101:O105)+SUM(K101:K105)+SUM(G101:G105)+SUM(C101:C105)+SUM(O109:O112)+SUM(K109:K112)+SUM(C109:C112)+SUM(C84:C87)+SUM(C116:'T accnts'!C119)+SUM(G109:G112)+SUM(G116:G119)-SUM(Journal!G3:G78) -> 0
A5: CURRENT ASSETS
B6: =Cash_ -> Cash | F6: =IF(CA2_="","",CA2_) -> Current Asset 2 | J6: =IF(CA3_="","",CA3_) -> Current Asset 3 | N6: =IF(CA4_="","",CA4_) -> Current Asset 4
A7: =IF(B6="","","BB") -> BB | B7: =Cash_BB -> 0 | E7: =IF(F6="","","BB") -> BB | F7: =CA2_BB -> 0 | I7: =IF(J6="","","BB") -> BB | J7: =CA3_BB -> 0 | M7: =IF(N6="","","BB") -> BB | N7: =CA4_BB -> 0
F11: =SUM(F7:F10)-SUM(G7:G10) -> 0 | J11: =SUM(J7:J10)-SUM(K7:K10) -> 0 | N11: =SUM(N7:N10)-SUM(O7:O10) -> 0
J13: CURRENT CONTRA-ASSETS
F14: =IF(CA5_="","",CA5_) -> Current Asset 5 | J14: =IF(CA3_Contra="","",CA3_Contra) -> Contra to Current Asset 3 | N14: =IF(CA4_Contra="","",CA4_Contra) -> Contra to Current Asset 4 | AA14: =AND(CA3_Contra="",CA4_Contra="") -> FALSE
E15: =IF(F14="","","BB") -> BB | F15: =CA5_BB -> 0 | K15: =CA3_Contra_BB -> 0 | L15: =IF(J14="","","BB") -> BB | O15: =CA4_Contra_BB -> 0 | P15: =IF(N14="","","BB") -> BB | Z15: Cash_ | AA15: =IF(Cash_="","TRUE","FALSE") -> FALSE
Z16: ="CA2"&W14&"_" -> CA2_ | AA16: =IF(CA2_="","TRUE","FALSE") -> FALSE
Z17: ="CA3"&W15&"_" -> CA3_ | AA17: =IF(CA3_="","TRUE","FALSE") -> FALSE
Z18: CA4_ | AA18: =IF(CA4_="","TRUE","FALSE") -> FALSE
F19: =SUM(F15:F18)-SUM(G15:G18) -> 0 | K19: =SUM(K15:K18)-SUM(J15:J18) -> 0 | O19: =SUM(O15:O18)-SUM(N15:N18) -> 0 | Z19: CA5_ | AA19: =IF(CA5_="","TRUE","FALSE") -> FALSE
Z20: CA6_ | AA20: =IF(CA6_="","TRUE","FALSE") -> FALSE
Z21: CA7_ | AA21: =IF(CA7_="","TRUE","FALSE") -> FALSE
F22: =IF(CA6_="","",CA6_) -> Current Asset 6 | J22: =IF(CA7_="","",CA7_) -> Current Asset 7 | Z22: CA3_Contra | AA22: =IF(CA3_Contra="","TRUE","FALSE") -> FALSE
E23: =IF(F22="","","BB") -> BB | F23: =CA6_BB -> 0 | I23: =IF(J22="","","BB") -> BB | J23: =CA7_BB -> 0 | Z23: CA4_Contra | AA23: =IF(CA4_Contra="","TRUE","FALSE") -> FALSE
Z24: NCA1_ | AA24: =IF(NCA1_="","TRUE","FALSE") -> FALSE
Z25: NCA2_ | AA25: =IF(NCA2_="","TRUE","FALSE") -> FALSE
Z26: NCA3_ | AA26: =IF(NCA3_="","TRUE","FALSE") -> FALSE
B27: =SUM(B7:B26)-SUM(C7:C26) -> 0 | F27: =SUM(F23:F26)-SUM(G23:G26) -> 0 | J27: =SUM(J23:J26)-SUM(K23:K26) -> 0 | Z27: NCA4_ | AA27: =IF(NCA4_="","TRUE","FALSE") -> FALSE
A28: NONCURRENT ASSETS | AA28: =AND(NCA1_Contra="",NCA2_Contra="") -> FALSE
B29: =IF(NCA1_="","",NCA1_) -> Property, Plant & Equipment | F29: =IF(NCA2_="","",NCA2_) -> Property, Plant & Equipment | J29: =IF(NCA3_="","",NCA3_) -> Property, Plant & Equipment | N29: =IF(NCA4_="","",NCA4_) -> Property, Plant & Equipment | Z29: NCA1_Contra | AA29: =IF(NCA1_Contra="","TRUE","FALSE") -> FALSE
A30: =IF(B29="","","BB") -> BB | B30: =NCA1_BB -> 0 | E30: =IF(F29="","","BB") -> BB | F30: =NCA2_BB -> 0 | I30: =IF(J29="","","BB") -> BB | J30: =NCA3_BB -> 0 | M30: =IF(N29="","","BB") -> BB | N30: =NCA4_BB -> 0 | Z30: NCA2_Contra | AA30: =IF(NCA2_Contra="","TRUE","FALSE") -> FALSE
Z31: CL1_ | AA31: =IF(CL1_="","TRUE","FALSE") -> FALSE
Z32: CL2_ | AA32: =IF(CL2_="","TRUE","FALSE") -> FALSE
A33: r | Z33: CL3_ | AA33: =IF(CL3_="","TRUE","FALSE") -> FALSE
B34: =SUM(B30:B33)-SUM(C30:C33) -> 0 | F34: =SUM(F30:F33)-SUM(G30:G33) -> 0 | J34: =SUM(J30:J33)-SUM(K30:K33) -> 0 | N34: =SUM(N30:N33)-SUM(O30:O33) -> 0 | Z34: CL4_ | AA34: =IF(CL4_="","TRUE","FALSE") -> FALSE
Z35: CL5_ | AA35: =IF(CL5_="","TRUE","FALSE") -> FALSE
B36: NONCURRENT CONTRA-ASSETS | Z36: CL6_ | AA36: =IF(CL6_="","TRUE","FALSE") -> FALSE
B37: =IF(NCA1_Contra="","",NCA1_Contra) -> Accumulated Depreciation | F37: =IF(NCA2_Contra="","",NCA2_Contra) -> Accumulated Depreciation | Z37: CL7_ | AA37: =IF(CL7_="","TRUE","FALSE") -> FALSE
C38: =NCA1_Contra_BB -> 0 | D38: =IF(B37="","","BB") -> BB | G38: =NCA2_Contra_BB -> 0 | H38: =IF(F37="","","BB") -> BB | Z38: NCL1_ | AA38: =IF(NCL1_="","TRUE","FALSE") -> FALSE
Z39: NCL2_ | AA39: =IF(NCL2_="","TRUE","FALSE") -> FALSE
Z40: NCL3_ | AA40: =IF(NCL3_="","TRUE","FALSE") -> FALSE
Z41: NCL4_ | AA41: =IF(NCL4_="","TRUE","FALSE") -> FALSE
C42: =SUM(C38:C41)-SUM(B38:B41) -> 0 | G42: =SUM(G38:G41)-SUM(F38:F41) -> 0 | Z42: NCL5_ | AA42: =IF(NCL5_="","TRUE","FALSE") -> FALSE
Z43: NCL6_ | AA43: =IF(NCL6_="","TRUE","FALSE") -> FALSE
A44: CURRENT LIABILITIES | Z44: NCL7_ | AA44: =IF(NCL7_="","TRUE","FALSE") -> FALSE
...

Sheet Indirect Method Worksheet
A1: =Entity -> ImmuCell Corp.
A2: Cash Flow Worksheet
A3: =BegDate&" to "&EndDate -> [BegDate] to [EndDate]
B5: Beginning Balance | D5: Ref | E5: Explanations | G5: Ref | H5: Ending Balance
B6: dr | C6: cr | E6: dr | F6: cr | H6: dr | I6: cr | J6: Balance?
A7: =CA2_ -> Current Asset 2 | B7: =CA2_BB -> 0 | H7: =CA2_EB -> 0 | J7: =IF(ROUND(B7+SUM(E7:E8)-SUM(F7:F8)-H7,2)=0,"YES",B7+SUM(E7:E8)-SUM(F7:F8)-H7) -> YES
A9: =CA3_ -> Current Asset 3 | B9: =CA3_BB -> 0 | H9: =CA3_EB -> 0 | J9: =IF(ROUND(B9+SUM(E9:E10)-SUM(F9:F10)-H9,2)=0,"YES",B9+SUM(E9:E10)-SUM(F9:F10)-H9) -> YES
A11: =CA4_ -> Current Asset 4 | B11: =CA4_BB -> 0 | H11: =CA4_EB -> 0 | J11: =IF(ROUND(B11+SUM(E11:E11)-SUM(F11:F11)-H11,2)=0,"YES",B11+SUM(E11:E11)-SUM(F11:F11)-H11) -> YES
A12: =NCA1_ -> Property, Plant & Equipment | B12: =NCA1_BB -> 0 | H12: =NCA1_EB -> 0 | J12: =IF(ROUND(B12+SUM(E12:E14)-SUM(F12:F14)-H12,2)=0,"YES",B12+SUM(E12:E14)-SUM(F12:F14)-H12) -> YES
A15: =NCA1_Contra -> Accumulated Depreciation | C15: =NCA1_Contra_BB -> 0 | I15: =NCA1_Contra_EB -> 0 | J15: =IF(ROUND(C15-SUM(E15:E16)+SUM(F15:F16)-I15,2)=0,"YES",C15-SUM(E15:E16)+SUM(F15:F16)-I15) -> YES
A17: =NCA2_ -> Property, Plant & Equipment | B17: =NCA2_BB -> 0 | H17: =NCA2_EB -> 0 | J17: =IF(ROUND(B17+SUM(E17:E17)-SUM(F17:F17)-H17,2)=0,"YES",B17+SUM(E17:E17)-SUM(F17:F17)-H17) -> YES
A18: =CL1_ -> Current Liability 1 | C18: =CL1_BB -> 0 | I18: =CL1_EB -> 0 | J18: =IF(ROUND(C18-SUM(E18:E19)+SUM(F18:F19)-I18,2)=0,"YES",C18-SUM(E18:E19)+SUM(F18:F19)-I18) -> YES
A20: =CL2_ -> Current Liability 2 | C20: =CL2_BB -> 0 | I20: =CL2_EB -> 0 | J20: =IF(ROUND(C20-SUM(E20:E20)+SUM(F20:F20)-I20,2)=0,"YES",C20-SUM(E20:E20)+SUM(F20:F20)-I20) -> YES
A21: =CL3_ -> Current Liability 3 | C21: =CL3_BB -> 0 | I21: =CL3_EB -> 0 | J21: =IF(ROUND(C21-SUM(E21:E21)+SUM(F21:F21)-I21,2)=0,"YES",C21-SUM(E21:E21)+SUM(F21:F21)-I21) -> YES
A22: =CL4_ -> Current Liability 4 | C22: =CL4_BB -> 0 | I22: =CL4_EB -> 0 | J22: =IF(ROUND(C22-SUM(E22:E22)+SUM(F22:F22)-I22,2)=0,"YES",C22-SUM(E22:E22)+SUM(F22:F22)-I22) -> YES
A23: =CL5_ -> Current Liability 5 | C23: =CL5_BB -> 0 | I23: =CL5_EB -> 0 | J23: =IF(ROUND(C23-SUM(E23:E23)+SUM(F23:F23)-I23,2)=0,"YES",C23-SUM(E23:E23)+SUM(F23:F23)-I23) -> YES
A24: =CL6_ -> Current Liability 6 | C24: =CL6_BB -> 0 | I24: =CL6_EB -> 0 | J24: =IF(ROUND(C24-SUM(E24:E24)+SUM(F24:F24)-I24,2)=0,"YES",C24-SUM(E24:E24)+SUM(F24:F24)-I24) -> YES
A25: =NCL1_ -> Noncurrent Liability 1 | C25: =NCL1_BB -> 0 | I25: =NCL1_EB -> 0 | J25: =IF(ROUND(C25-SUM(E25:E25)+SUM(F25:F25)-I25,2)=0,"YES",C25-SUM(E25:E25)+SUM(F25:F25)-I25) -> YES
A26: =NCL2_ -> Noncurrent Liability 2 | C26: =NCL2_BB -> 0 | I26: =NCL2_EB -> 0 | J26: =IF(ROUND(C26-SUM(E26:E26)+SUM(F26:F26)-I26,2)=0,"YES",C26-SUM(E26:E26)+SUM(F26:F26)-I26) -> YES
C27: =NCL3_BB -> 0 | I27: =NCL3_EB -> 0 | J27: =IF(ROUND(C27-SUM(E27:E27)+SUM(F27:F27)-I27,2)=0,"YES",C27-SUM(E27:E27)+SUM(F27:F27)-I27) -> YES
A28: =IF(SE1_="","",SE1_) -> Contributed Equity 1 | C28: =SE1_BB -> 0 | I28: =SE1_EB -> 0 | J28: =IF(ROUND(C28-SUM(E28:E28)+SUM(F28:F28)-I28,2)=0,"YES",C28-SUM(E28:E28)+SUM(F28:F28)-I28) -> YES
A29: =IF(SE2_="","",SE2_) -> Contributed Equity 2 | C29: =SE2_BB -> 0 | I29: =SE2_EB -> 0 | J29: =IF(ROUND(C29-SUM(E29:E32)+SUM(F29:F32)-I29,2)=0,"YES",C29-SUM(E29:E32)+SUM(F29:F32)-I29) -> YES
A32: =IF(SE3_="","",SE3_) -> Contributed Equity 3 | C32: =SE3_BB -> 0 | I32: =SE3_EB -> 0 | J32: =IF(ROUND(C32-SUM(E32:E32)+SUM(F32:F32)-I32,2)=0,"YES",C32-SUM(E32:E32)+SUM(F32:F32)-I32) -> YES
A33: Retained Earnings | B33: =IF(SE4_BB_Dr>0,SE4_BB_Dr,0) -> 0 | C33: =IF(SE4_BB_Cr>0,SE4_BB_Cr,0) -> 0 | F33: =NI -> 0 | G33: NI | H33: =IF(SE4_EB_Dr>0,SE4_EB_Dr,0) -> 0 | I33: =IF(SE4_EB_Cr>0,SE4_EB_Cr,0) -> 0 | J33: =IF(ROUND(C33-SUM(E33:E33)+SUM(F33:F33)-I33,2)=0,"YES",C33-SUM(E33:E33)+SUM(F33:F33)-I33) -> YES
B36: =SUM(B7:B35) -> 0 | C36: =SUM(C7:C33) -> 0 | E36: Cash | H36: =SUM(H7:H35) -> 0 | I36: =SUM(I7:I35) -> 0
A37: Beg cash | B37: =Cash_BB -> 0 | D37: BB | E37: =Cash_BB -> 0 | H37: =Cash_EB -> 0 | I37: End Cash
B38: =SUM(B36:B37) -> 0 | E38: Operations | H38: =SUM(H36:H37) -> 0
D39: NI | E39: =NI -> 0
B40: Difference | C40: =B38-C36 -> 0 | H40: Difference | I40: =H38-I36 -> 0
D48: CFO | E48: =MAX(SUM(E39:E47)-SUM(F39:F47),0) -> 0 | F48: =MAX(SUM(F39:F47)-SUM(E39:E47),0) -> 0 | J48: Total drs | K48: Total crs
H49: Explanations Check | J49: =SUM(E7:E35)+SUM(E39:E47)+SUM(E51:E53)+SUM(E57:E58) -> 0 | K49: =SUM(F7:F35)+SUM(F39:F47)+SUM(F51:F53)+SUM(F57:F58) -> 0
E50: Investing
I51: Difference | J51: =J49-K49 -> 0
D54: CFI | E54: =MAX(SUM(E51:E53)-SUM(F51:F53),0) -> 0 | F54: =MAX(SUM(F51:F53)-SUM(E51:E53),0) -> 0 | H54: Ending Balance Check
J55: =ROUND(E60-Cash_EB,2) -> 0
E56: Financing
D59: CFF | E59: =MAX(SUM(E57:E58)-SUM(F57:F58),0) -> 0 | F59: =MAX(SUM(F57:F58)-SUM(E57:E58),0) -> 0
D60: EB | E60: =E37-F48+E48-F54+E54-F59+E59 -> 0

Sheet Financial Statements
A1: =Entity -> ImmuCell Corp. | G1: Checks
A2: Balance Sheets | G2: ="Balance Sheet as of "&BegDate -> Balance Sheet as of [BegDate]
A3: ="as of "&EndDate&" and "&BegDate -> as of [EndDate] and [BegDate] | G3: Total Assets | H3: =E26 -> 0
A4: =Units -> [Units] | G4: Total Liabilities | H4: =E49 -> 0
A5: Assets | G5: Total Shareholders' Equity | H5: =E58 -> 0
B6: =EndDate -> [EndDate] | D6: =BegDate -> [BegDate] | G6: A minus L plus E | H6: =ROUND(H3-H4-H5,2) -> 0
A7: Current Assets:
A8: =Cash_ -> Cash | B8: =IF(Cash_EB="","",Cash_EB) -> 0 | D8: =Cash_BB -> 0 | G8: ="Balance Sheet as of "&EndDate -> Balance Sheet as of [EndDate]
A9: =IF(CA2_="","",CA2_) -> Current Asset 2 | B9: =IF(CA2_EB="","",CA2_EB) -> 0 | D9: =CA2_BB -> 0 | G9: Total Assets | H9: =C26 -> 0
A10: =IF(AND(CA3_="",CA3_Contra=""),"",IF(CA3_Contra="",CA3_,CA3_&", net")) -> Current Asset 3, net | B10: =IF(A10=CA3_&", net",CA3_EB-CA3_Contra_EB,CA3_EB) -> 0 | D10: =IF(A10=CA3_&", net",CA3_BB-CA3_Contra_BB,CA3_BB) -> 0 | G10: Total Liabilities | H10: =C49 -> 0
A11: =IF(AND(CA4_="",CA4_Contra=""),"",IF(CA4_Contra="",CA4_,CA4_&", net")) -> Current Asset 4, net | B11: =IF(A11=CA4_&", net",CA4_EB-CA4_Contra_EB,CA4_EB) -> 0 | D11: =IF(A11=CA4_&", net",CA4_BB-CA4_Contra_BB,CA4_BB) -> 0 | G11: Total Shareholders' Equity | H11: =C58 -> 0
A12: =IF(CA5_="","",CA5_) -> Current Asset 5 | B12: =IF(CA5_EB="","",CA5_EB) -> 0 | D12: =CA5_BB -> 0 | G12: A minus L plus E | H12: =ROUND(H9-H10-H11,2) -> 0
A13: =IF(CA6_="","",CA6_) -> Current Asset 6 | B13: =IF(CA6_EB="","",CA6_EB) -> 0 | D13: =CA6_BB -> 0
A14: =IF(CA7_="","",CA7_) -> Current Asset 7 | B14: =IF(CA7_EB="","",CA7_EB) -> 0 | D14: =CA7_BB -> 0
A15: Total Current Assets: | C15: =SUM(B8:B14) -> 0 | E15: =SUM(D8:D14) -> 0
A17: Noncurrent Assets:
A18: =IF(NCA1_="","",NCA1_) -> Property, Plant & Equipment | B18: =NCA1_EB -> 0 | D18: =NCA1_BB -> 0
A19: =IF(NCA1_Contra="","",NCA1_Contra) -> Accumulated Depreciation | B19: =-NCA1_Contra_EB -> 0 | D19: =-NCA1_Contra_BB -> 0
A20: Property, Plant & Equipment, net | B20: =SUM(B18:B19) -> 0 | D20: =SUM(D18:D19) -> 0
A21: =IF(AND(NCA2_="",NCA2_Contra=""),"",IF(NCA2_Contra="",NCA2_,NCA2_&", net")) -> Property, Plant & Equipment, net | B21: =IF(A21=NCA2_&", net",NCA2_EB-NCA2_Contra_EB,NCA2_EB) -> 0 | D21: =IF(A21=NCA2_&", net",NCA2_BB-NCA2_Contra_BB,NCA2_BB) -> 0
A22: =IF(NCA3_="","",NCA3_) -> Property, Plant & Equipment | B22: =NCA3_EB -> 0 | D22: =NCA3_BB -> 0
A23: =IF(NCA4_="","",NCA4_) -> Property, Plant & Equipment | B23: =NCA4_EB -> 0 | D23: =NCA4_BB -> 0
A24: Total Non-current Assets: | C24: =SUM(B20:B23) -> 0 | E24: =SUM(D20:D23) -> 0
A26: Total Assets | C26: =C15+C24 -> 0 | E26: =E15+E24 -> 0
A28: Liabilities and Equities
B29: =EndDate -> [EndDate] | D29: =BegDate -> [BegDate]
A30: Current Liabilities:
A31: =IF(CL1_="","",CL1_) -> Current Liability 1 | B31: =CL1_EB -> 0 | D31: =CL1_BB -> 0
A32: =IF(CL2_="","",CL2_) -> Current Liability 2 | B32: =CL2_EB -> 0 | D32: =CL2_BB -> 0
A33: =IF(CL3_="","",CL3_) -> Current Liability 3 | B33: =CL3_EB -> 0 | D33: =CL3_BB -> 0
A34: =IF(CL4_="","",CL4_) -> Current Liability 4 | B34: =CL4_EB -> 0 | D34: =CL4_BB -> 0
A35: =IF(CL5_="","",CL5_) -> Current Liability 5 | B35: =CL5_EB -> 0 | D35: =CL5_BB -> 0
A36: =IF(CL6_="","",CL6_) -> Current Liability 6 | B36: =CL6_EB -> 0 | D36: =CL6_BB -> 0
A37: =IF(CL7_="","",CL7_) -> Current Liability 7 | B37: =CL7_EB -> 0 | D37: =CL7_BB -> 0
A38: Total Current Liabilities: | C38: =SUM(B31:B37) -> 0 | E38: =SUM(D31:D37) -> 0
A40: Noncurrent Liabilities:
A41: =IF(NCL1_="","",NCL1_) -> Noncurrent Liability 1 | B41: =NCL1_EB -> 0 | D41: =NCL1_BB -> 0
A42: =IF(NCL2_="","",NCL2_) -> Noncurrent Liability 2 | B42: =NCL2_EB -> 0 | D42: =NCL2_BB -> 0
A43: =IF(NCL3_="","",NCL3_) -> Noncurrent Liability 3 | B43: =NCL3_EB -> 0 | D43: =NCL3_BB -> 0
A44: =IF(NCL4_="","",NCL4_) -> Noncurrent Liability 4 | B44: =NCL4_EB -> 0 | D44: =NCL4_BB -> 0
...

Sheet Retained Earnings & OCI
A1: Account Set 1
A2: T-ACCOUNTS
B4: Retained Earnings | D4: BB | G4: Other Comprehensive Income | L4: Total
A5: BB | B5: 0 | C5: 638672 | D5: BB | F5: BB | H5: 0 | I5: BB | L5: =B5+G5 -> 0 | M5: =C5+H5 -> 638672 | N5: BB
L6: =B6+G6 -> 0 | M6: =C6+H6 -> 0
C7: 508448 | D7: NI | L7: =B7+G7 -> 0 | M7: =C7+H7 -> 508448
L8: =B8+G8 -> 0 | M8: =C8+H8 -> 0
L9: =B9+G9 -> 0 | M9: =C9+H9 -> 0
B10: =IF(B11>0,MAX(SUM(C5:C9)-SUM(B5:B9)+B11,0),MAX(-SUM(B5:B9)+SUM(C5:C9)-C11,0)) -> 0 | C10: =IF(C11>0,MAX(-SUM(C5:C9)+SUM(B5:B9)+C11,0),MAX(SUM(B5:B9)-SUM(C5:C9)-B11,0)) -> 0 | G10: =IF(G11>0,MAX(SUM(H5:H9)-SUM(G5:G9)+G11,0),MAX(-SUM(G5:G9)+SUM(H5:H9)-H11,0)) -> 0 | H10: =IF(H11>0,MAX(-SUM(H5:H9)+SUM(G5:G9)+H11,0),MAX(SUM(G5:G9)-SUM(H5:H9)-G11,0)) -> 0 | M10: =SUM(M5:M9)-SUM(L5:L9)-M11 -> 0
A11: EB | C11: 1147120 | D11: EB | F11: EB | I11: EB | L11: =MAX(B11-C11+G11-H11,0) -> 0 | M11: =MAX(C11+H11-B11-G11,0) -> 1147120 | N11: EB
C14: JOURNAL TOOL
C15: Accounts to Debit | F15: Accounts to Credit | H15: Amounts to Debit | J15: Amounts to Credit | L15: Debits - Credits
L16: =SUM(H16:I22)-SUM(J16:K22) -> 0
A25: Account Set 2
A26: T-ACCOUNTS
L28: =B28&" , Total" -> , Total
D29: BB | F29: BB | I29: BB | K29: BB | N29: BB
C34: =SUM(C29:C33)-SUM(B29:B33)-C35 -> 0 | G34: =MAX(G35-SUM(G29:G33)+SUM(H30:H33),0) -> 0 | H34: =MAX(0,SUM(G29:G34)-SUM(H30:H33)-G35) -> 0 | M34: =SUM(M29:M33)-SUM(L29:L33)-M35 -> 0
D35: EB | F35: EB | N35: EB
C38: JOURNAL TOOL
C39: Accounts to Debit | F39: Accounts to Credit | H39: Amounts to Debit | J39: Amounts to Credit | L39: Debits - Credits
L40: =SUM(H40:I46)-SUM(J40:K46) -> 0

Sheet Property, Plant & Equipment
A3: Account Set 1
A4: T-ACCOUNTS
B6: Property, Plant & Equipment | G6: Accumulated Depreciation | L6: =B6&", Net" -> Property, Plant & Equipment, Net
A7: BB | B7: 10469358 | H7: 4750544 | L7: =B7-H7 -> 5718814
A8: $ | B8: 3586349
A9: Day1 | B9: 132000 | C9: 140901 | D9: disposals | F9: Disposal | G9: 84577 | H9: 783275 | I9: DeprExp
A10: AP | B10: 1248352
B12: =MAX(B13-SUM(B7:B11)+SUM(C8:C11),0) -> 377 | C12: =MAX(0,SUM(B7:B12)-SUM(C8:C11)-B13) -> 0 | H12: =SUM(H7:H11)-SUM(G7:G11)-H13 -> 0 | L12: =MAX(L13-SUM(L7:L11)+SUM(M8:M11),0) -> 4127479 | M12: =MAX(0,SUM(L7:L11)-SUM(M8:M11)-L13) -> 0
A13: EB | B13: 15295535 | H13: 5449242 | I13: EB | K13: EB | L13: =B13-H13 -> 9846293
C16: JOURNAL TOOL
C17: Accounts to Debit | F17: Accounts to Credit | H17: Amounts to Debit | J17: Amounts to Credit | L17: Debits - Credits
C18: Accumulated Depreciation | H18: 84577 | L18: =SUM(H18:I24)-SUM(J18:K24) -> 0
C19: Cash | H19: 30939
C20: Loss on PPE sale | H20: 25385
F21: PPE | J21: 140901
A27: Account Set 2
A28: T-ACCOUNTS
L30: =B30&", Net" -> , Net
A31: BB | I31: BB | K31: BB | L31: =B31-H31 -> 0
B36: =MAX(B37-SUM(B31:B35)+SUM(C32:C35),0) -> 0 | C36: =MAX(0,SUM(B31:B36)-SUM(C32:C35)-B37) -> 0 | H36: =SUM(H31:H35)-SUM(G31:G35)-H37 -> 0 | L36: =MAX(L37-SUM(L31:L35)+SUM(M32:M35),0) -> 0 | M36: =MAX(0,SUM(L31:L35)-SUM(M32:M35)-L37) -> 0
A37: EB | I37: EB | K37: EB | L37: =B37-H37 -> 0
C40: JOURNAL TOOL
C41: Accounts to Debit | F41: Accounts to Credit | H41: Amounts to Debit | J41: Amounts to Credit | L41: Debits - Credits
L42: =SUM(H42:I48)-SUM(J42:K48) -> 0

Sheet Inventories
A1: Account Set 1
A2: T-ACCOUNTS
B4: Inventories | G4: Noncurrent | L4: Total
A5: BB | B5: 870207 | F5: BB | L5: =B5+G5 -> 870207
A6: Purch | B6: 5266958 | C6: 4123266 | D6: CoGS | L6: =B6+G6 -> 5266958 | M6: =C6+H6 -> 4123266
A7: Day1Acq | B7: 113000 | L7: =B7+G7 -> 113000 | M7: =C7+H7 -> 0
L8: =B8+G8 -> 0 | M8: =C8+H8 -> 0
L9: =B9+G9 -> 0 | M9: =C9+H9 -> 0
B10: =MAX(B11-SUM(B5:B9)+SUM(C6:C9),0) -> 0 | C10: =MAX(0,SUM(B5:B10)-SUM(C6:C9)-B11) -> 0 | G10: =MAX(G11-SUM(G5:G9)+SUM(H6:H9),0) -> 0 | H10: =MAX(0,SUM(G5:G10)-SUM(H6:H9)-G11) -> 0 | L10: =MAX(L11-SUM(L5:L9)+SUM(M6:M9),0) -> 0 | M10: =MAX(0,SUM(L5:L9)-SUM(M6:M9)-L11) -> 0
A11: EB | B11: 2126899 | F11: EB | K11: EB | L11: =B11-H11 -> 2126899
C14: JOURNAL TOOL
C15: Accounts to Debit | F15: Accounts to Credit | H15: Amounts to Debit | J15: Amounts to Credit | L15: Debits - Credits
L16: =SUM(H16:I22)-SUM(J16:K22) -> 0
A25: Account Set 2
A26: T-ACCOUNTS
B28: Current | G28: Noncurrent | L28: Total
A29: BB | F29: BB | L29: =B29+G29 -> 0
L30: =B30+G30 -> 0 | M30: =C30+H30 -> 0
L31: =B31+G31 -> 0 | M31: =C31+H31 -> 0
L32: =B32+G32 -> 0 | M32: =C32+H32 -> 0
L33: =B33+G33 -> 0 | M33: =C33+H33 -> 0
B34: =MAX(B35-SUM(B29:B33)+SUM(C30:C33),0) -> 0 | C34: =MAX(0,SUM(B29:B34)-SUM(C30:C33)-B35) -> 0 | G34: =MAX(G35-SUM(G29:G33)+SUM(H30:H33),0) -> 0 | H34: =MAX(0,SUM(G29:G34)-SUM(H30:H33)-G35) -> 0 | L34: =MAX(L35-SUM(L29:L33)+SUM(M30:M33),0) -> 0 | M34: =MAX(0,SUM(L29:L33)-SUM(M30:M33)-L35) -> 0
A35: EB | F35: EB | K35: EB | L35: =B35-H35 -> 0
C38: JOURNAL TOOL
C39: Accounts to Debit | F39: Accounts to Credit | H39: Amounts to Debit | J39: Amounts to Credit | L39: Debits - Credits
L40: =SUM(H40:I46)-SUM(J40:K46) -> 0

Sheet Marketable Securities
A1: Account Set 1
A2: T-ACCOUNTS
B4: Short-term Investments | G4: Long-term Investments | L4: Total
A5: BB | F5: BB | L5: =B5+G5 -> 0
L6: =B6+G6 -> 0 | M6: =C6+H6 -> 0
L7: =B7+G7 -> 0 | M7: =C7+H7 -> 0
L8: =B8+G8 -> 0 | M8: =C8+H8 -> 0
L9: =B9+G9 -> 0 | M9: =C9+H9 -> 0
B10: =MAX(B11-SUM(B5:B9)+SUM(C6:C9),0) -> 0 | C10: =MAX(0,SUM(B5:B10)-SUM(C6:C9)-B11) -> 0 | G10: =MAX(G11-SUM(G5:G9)+SUM(H6:H9),0) -> 0 | H10: =MAX(0,SUM(G5:G10)-SUM(H6:H9)-G11) -> 0 | L10: =MAX(L11-SUM(L5:L9)+SUM(M6:M9),0) -> 0 | M10: =MAX(0,SUM(L5:L9)-SUM(M6:M9)-L11) -> 0
A11: EB | F11: EB | K11: EB | L11: =B11-H11 -> 0
C14: JOURNAL TOOL
C15: Accounts to Debit | F15: Accounts to Credit | H15: Amounts to Debit | J15: Amounts to Credit | L15: Debits - Credits
L16: =SUM(H16:I22)-SUM(J16:K22) -> 0
A25: Account Set 2
A26: T-ACCOUNTS
B28: Current | G28: Noncurrent | L28: Total
A29: BB | F29: BB | L29: =B29+G29 -> 0
L30: =B30+G30 -> 0 | M30: =C30+H30 -> 0
L31: =B31+G31 -> 0 | M31: =C31+H31 -> 0
L32: =B32+G32 -> 0 | M32: =C32+H32 -> 0
L33: =B33+G33 -> 0 | M33: =C33+H33 -> 0
B34: =MAX(B35-SUM(B29:B33)+SUM(C30:C33),0) -> 0 | C34: =MAX(0,SUM(B29:B34)-SUM(C30:C33)-B35) -> 0 | G34: =MAX(G35-SUM(G29:G33)+SUM(H30:H33),0) -> 0 | H34: =MAX(0,SUM(G29:G34)-SUM(H30:H33)-G35) -> 0 | L34: =MAX(L35-SUM(L29:L33)+SUM(M30:M33),0) -> 0 | M34: =MAX(0,SUM(L29:L33)-SUM(M30:M33)-L35) -> 0
A35: EB | F35: EB | K35: EB | L35: =B35-H35 -> 0
C38: JOURNAL TOOL
C39: Accounts to Debit | F39: Accounts to Credit | H39: Amounts to Debit | J39: Amounts to Credit | L39: Debits - Credits
L40: =SUM(H40:I46)-SUM(J40:K46) -> 0

Sheet Interest Rate Swaps
A1: Account Set 1
A2: T-ACCOUNTS
B4: Interest Rate Swaps | L4: =B4&" ,net" -> Interest Rate Swaps ,net
C5: 78525 | D5: BB | F5: BB | I5: BB | K5: BB | N5: BB
A6: MtoM OCI | B6: 41179
C10: =SUM(C5:C9)-SUM(B5:B9)-C11 -> 0 | G10: =MAX(G11-SUM(G5:G9)+SUM(H6:H9),0) -> 0 | H10: =MAX(0,SUM(G5:G10)-SUM(H6:H9)-G11) -> 0 | M10: =SUM(M5:M9)-SUM(L5:L9)-M11 -> 0
C11: 37346 | D11: EB | F11: EB | N11: EB
C14: JOURNAL TOOL
C15: Accounts to Debit | F15: Accounts to Credit | H15: Amounts to Debit | J15: Amounts to Credit | L15: Debits - Credits
C16: Interest Rate Swaps | H16: 41179 | L16: =SUM(H16:I22)-SUM(J16:K22) -> 0
F17: HG on Int Rate Swaps | J17: 41179
A25: Account Set 2
A26: T-ACCOUNTS
L28: =B28&" ,net" -> ,net
D29: BB | F29: BB | I29: BB | K29: BB | N29: BB
C34: =SUM(C29:C33)-SUM(B29:B33)-C35 -> 0 | G34: =MAX(G35-SUM(G29:G33)+SUM(H30:H33),0) -> 0 | H34: =MAX(0,SUM(G29:G34)-SUM(H30:H33)-G35) -> 0 | M34: =SUM(M29:M33)-SUM(L29:L33)-M35 -> 0
D35: EB | F35: EB | N35: EB
C38: JOURNAL TOOL
C39: Accounts to Debit | F39: Accounts to Credit | H39: Amounts to Debit | J39: Amounts to Credit | L39: Debits - Credits
L40: =SUM(H40:I46)-SUM(J40:K46) -> 0

Sheet Liability Account Curr+Noncurr
A1: Account Set 1
A2: T-ACCOUNTS
L4: Total
D5: BB | I5: BB | L5: =B5+G5 -> 0 | M5: =C5+H5 -> 0 | N5: BB
L6: =B6+G6 -> 0 | M6: =C6+H6 -> 0
L7: =B7+G7 -> 0 | M7: =C7+H7 -> 0
L8: =B8+G8 -> 0 | M8: =C8+H8 -> 0
L9: =B9+G9 -> 0 | M9: =C9+H9 -> 0
C10: =SUM(C5:C9)-SUM(B5:B9)-C11 -> 0 | H10: =SUM(H5:H9)-SUM(G5:G9)-H11 -> 0 | M10: =SUM(M5:M9)-SUM(L5:L9)-M11 -> 0
D11: EB | I11: EB | M11: =C11+H11 -> 0 | N11: EB
C14: JOURNAL TOOL
C15: Accounts to Debit | F15: Accounts to Credit | H15: Amounts to Debit | J15: Amounts to Credit | L15: Debits - Credits
L16: =SUM(H16:I22)-SUM(J16:K22) -> 0
A25: Account Set 2
A26: T-ACCOUNTS
L28: =B28&" , Total" -> , Total
D29: BB | F29: BB | I29: BB | K29: BB | L29: =B29+G29 -> 0 | M29: =C29+H29 -> 0 | N29: BB
L30: =B30+G30 -> 0 | M30: =C30+H30 -> 0
L31: =B31+G31 -> 0 | M31: =C31+H31 -> 0
L32: =B32+G32 -> 0 | M32: =C32+H32 -> 0
L33: =B33+G33 -> 0 | M33: =C33+H33 -> 0
C34: =SUM(C29:C33)-SUM(B29:B33)-C35 -> 0 | G34: =MAX(G35-SUM(G29:G33)+SUM(H30:H33),0) -> 0 | H34: =MAX(0,SUM(G29:G34)-SUM(H30:H33)-G35) -> 0 | M34: =SUM(M29:M33)-SUM(L29:L33)-M35 -> 0
D35: EB | F35: EB | N35: EB
C38: JOURNAL TOOL
C39: Accounts to Debit | F39: Accounts to Credit | H39: Amounts to Debit | J39: Amounts to Credit | L39: Debits - Credits
L40: =SUM(H40:I46)-SUM(J40:K46) -> 0

Sheet Liability Curr+Noncurr+Contra
A1: Account Set 1
A2: T-ACCOUNTS
B4: CURRENT | G4: NONCURRENT | L4: CONTRA | P4: TOTAL, Net
D5: BB | I5: BB | K5: BB | Q5: =H5-L5+C5 -> 0 | R5: BB
P6: =G6+L6+B6 -> 0 | Q6: =H6+M6+C6 -> 0
P7: =G7+L7+B7 -> 0 | Q7: =H7+M7+C7 -> 0
P8: =G8+L8+B8 -> 0 | Q8: =H8+M8+C8 -> 0
P9: =G9+L9+B9 -> 0 | Q9: =H9+M9+C9 -> 0
C10: =SUM(C5:C9)-SUM(B5:B9)-C11 -> 0 | H10: =SUM(H5:H9)-SUM(G5:G9)-H11 -> 0 | L10: =MAX(L11-SUM(L5:L9)+SUM(M6:M9),0) -> 0 | M10: =MAX(0,SUM(L5:L10)-SUM(M6:M9)-L11) -> 0 | Q10: =SUM(Q5:Q9)-SUM(P5:P9)-Q11 -> 0
D11: EB | I11: EB | K11: EB | L11: =SUM(L5:L9)-SUM(M6:M9) -> 0 | Q11: =H11-L11+C11 -> 0 | R11: EB
C14: JOURNAL TOOL
C15: Accounts to Debit | F15: Accounts to Credit | H15: Amounts to Debit | J15: Amounts to Credit | L15: Debits - Credits
L16: =SUM(H16:I23)-SUM(J16:K23) -> 0
A26: Account Set 2
A27: T-ACCOUNTS
B29: CURRENT | G29: NONCURRENT | L29: CONTRA | P29: TOTAL, Net
D30: BB | I30: BB | K30: BB | Q30: =H30-L30+C30 -> 0 | R30: BB
P31: =G31+L31+B31 -> 0 | Q31: =H31+M31+C31 -> 0
P32: =G32+L32+B32 -> 0 | Q32: =H32+M32+C32 -> 0
P33: =G33+L33+B33 -> 0 | Q33: =H33+M33+C33 -> 0
P34: =G34+L34+B34 -> 0 | Q34: =H34+M34+C34 -> 0
C35: =SUM(C30:C34)-SUM(B30:B34)-C36 -> 0 | H35: =SUM(H30:H34)-SUM(G30:G34)-H36 -> 0 | L35: =MAX(L36-SUM(L30:L34)+SUM(M31:M34),0) -> 0 | M35: =MAX(0,SUM(L30:L35)-SUM(M31:M34)-L36) -> 0 | Q35: =SUM(Q30:Q34)-SUM(P30:P34)-Q36 -> 0
D36: EB | I36: EB | K36: EB | L36: =SUM(L30:L34)-SUM(M31:M34) -> 0 | Q36: =H36-L36+C36 -> 0 | R36: EB
C39: JOURNAL TOOL
C40: Accounts to Debit | F40: Accounts to Credit | H40: Amounts to Debit | J40: Amounts to Credit | L40: Debits - Credits
L41: =SUM(H41:I48)-SUM(J41:K48) -> 0

Sheet Equity Accounts with Contra
A1: Account Set 1
A2: T-ACCOUNTS
B4: Equity1 | G4: Equity2 | L4: CONTRA | P4: TOTAL, Net
D5: BB | I5: BB | K5: BB | Q5: =H5-L5+C5 -> 0 | R5: BB
P6: =G6+L6+B6 -> 0 | Q6: =H6+M6+C6 -> 0
P7: =G7+L7+B7 -> 0 | Q7: =H7+M7+C7 -> 0
P8: =G8+L8+B8 -> 0 | Q8: =H8+M8+C8 -> 0
P9: =G9+L9+B9 -> 0 | Q9: =H9+M9+C9 -> 0
C10: =SUM(C5:C9)-SUM(B5:B9)-C11 -> 0 | H10: =SUM(H5:H9)-SUM(G5:G9)-H11 -> 0 | L10: =MAX(L11-SUM(L5:L9)+SUM(M6:M9),0) -> 0 | M10: =MAX(0,SUM(L5:L10)-SUM(M6:M9)-L11) -> 0 | Q10: =SUM(Q5:Q9)-SUM(P5:P9)-Q11 -> 0
D11: EB | I11: EB | K11: EB | L11: =SUM(L5:L9)-SUM(M6:M9) -> 0 | Q11: =H11-L11+C11 -> 0 | R11: EB
C14: JOURNAL TOOL
C15: Accounts to Debit | F15: Accounts to Credit | H15: Amounts to Debit | J15: Amounts to Credit | L15: Debits - Credits
L16: =SUM(H16:I23)-SUM(J16:K23) -> 0
A26: Account Set 2
A27: T-ACCOUNTS
B29: Equity1 | G29: Equity2 | L29: CONTRA | P29: TOTAL, Net
D30: BB | I30: BB | K30: BB | Q30: =H30-L30+C30 -> 0 | R30: BB
P31: =G31+L31+B31 -> 0 | Q31: =H31+M31+C31 -> 0
P32: =G32+L32+B32 -> 0 | Q32: =H32+M32+C32 -> 0
P33: =G33+L33+B33 -> 0 | Q33: =H33+M33+C33 -> 0
P34: =G34+L34+B34 -> 0 | Q34: =H34+M34+C34 -> 0
C35: =SUM(C30:C34)-SUM(B30:B34)-C36 -> 0 | H35: =SUM(H30:H34)-SUM(G30:G34)-H36 -> 0 | L35: =MAX(L36-SUM(L30:L34)+SUM(M31:M34),0) -> 0 | M35: =MAX(0,SUM(L30:L35)-SUM(M31:M34)-L36) -> 0 | Q35: =SUM(Q30:Q34)-SUM(P30:P34)-Q36 -> 0
D36: EB | I36: EB | K36: EB | L36: =SUM(L30:L34)-SUM(M31:M34) -> 0 | Q36: =H36-L36+C36 -> 0 | R36: EB
C39: JOURNAL TOOL
C40: Accounts to Debit | F40: Accounts to Credit | H40: Amounts to Debit | J40: Amounts to Credit | L40: Debits - Credits
L41: =SUM(H41:I48)-SUM(J41:K48) -> 0

Sheet RE + AOCI
A1: Account Set 1
A2: T-ACCOUNTS
B4: Retained Earnings | G4: Other Comprehensive Income | L4: Total
A5: BB | B5: 0 | D5: BB | F5: BB | H5: 0 | I5: BB | L5: =B5+G5 -> 0 | M5: =C5+H5 -> 0 | N5: BB
L6: =B6+G6 -> 0 | M6: =C6+H6 -> 0
L7: =B7+G7 -> 0 | M7: =C7+H7 -> 0
L8: =B8+G8 -> 0 | M8: =C8+H8 -> 0
L9: =B9+G9 -> 0 | M9: =C9+H9 -> 0
B10: =IF(B11>0,MAX(SUM(C5:C9)-SUM(B5:B9)+B11,0),MAX(-SUM(B5:B9)+SUM(C5:C9)-C11,0)) -> 0 | C10: =IF(C11>0,MAX(-SUM(C5:C9)+SUM(B5:B9)+C11,0),MAX(SUM(B5:B9)-SUM(C5:C9)-B11,0)) -> 0 | G10: =IF(G11>0,MAX(SUM(H5:H9)-SUM(G5:G9)+G11,0),MAX(-SUM(G5:G9)+SUM(H5:H9)-H11,0)) -> 0 | H10: =IF(H11>0,MAX(-SUM(H5:H9)+SUM(G5:G9)+H11,0),MAX(SUM(G5:G9)-SUM(H5:H9)-G11,0)) -> 0 | M10: =SUM(M5:M9)-SUM(L5:L9)-M11 -> 0
A11: EB | D11: EB | F11: EB | I11: EB | L11: =MAX(B11-C11+G11-H11,0) -> 0 | M11: =MAX(C11+H11-B11-G11,0) -> 0 | N11: EB
C14: JOURNAL TOOL
C15: Accounts to Debit | F15: Accounts to Credit | H15: Amounts to Debit | J15: Amounts to Credit | L15: Debits - Credits
L16: =SUM(H16:I22)-SUM(J16:K22) -> 0
A25: Account Set 2
A26: T-ACCOUNTS
L28: =B28&" , Total" -> , Total
D29: BB | F29: BB | I29: BB | K29: BB | N29: BB
C34: =SUM(C29:C33)-SUM(B29:B33)-C35 -> 0 | G34: =MAX(G35-SUM(G29:G33)+SUM(H30:H33),0) -> 0 | H34: =MAX(0,SUM(G29:G34)-SUM(H30:H33)-G35) -> 0 | M34: =SUM(M29:M33)-SUM(L29:L33)-M35 -> 0
D35: EB | F35: EB | N35: EB
C38: JOURNAL TOOL
C39: Accounts to Debit | F39: Accounts to Credit | H39: Amounts to Debit | J39: Amounts to Credit | L39: Debits - Credits
L40: =SUM(H40:I46)-SUM(J40:K46) -> 0

Sheet Final Check
A1: Tab(s) | C1: =IF(AND(B2="-",B3="-",B4="-",B5="-",B6="-",B7="-",B8="-",B9="-",B10="-"),"","Error")
A2: Basic Inputs | B2: =IF(C2="","-","X") -> - | C2: =IF('Basic Inputs'!D8=0,"","Beginning balance sheet not entered correctly")
A3: Journal | B3: =IF(C3="","-","X") -> - | C3: =IF(SUM(Journal!F3:F78)-SUM(Journal!G3:G78)=0,"","Total Debits not equal to total Credits")
A4: Journal & T accnts | B4: =IF(C4="","-","X") -> - | C4: =IF('T accnts'!Q4=0,"","Some amounts not posted")
A5: Journal & T accnts | B5: =IF(C5="","-","X") -> - | C5: =IF('T accnts'!R4=0,"","Total Debits posted to T-accounts not equal to total Debits in Journal")
A6: Journal & T accnts | B6: =IF(C6="","-","X") -> - | C6: =IF('T accnts'!S4=0,"","Total Credits posted to T-accounts not equal to total Credits in Journal")
A7: T accnts | B7: =IF(C7="","-","X") -> - | C7: =IF('T accnts'!Q2=0,"","Accounts not in balance")
A8: T accnts | B8: =IF(C8="","-","X") -> - | C8: =IF('T accnts'!U2=0,"","All temporary accounts not closed")
A9: Financial Statements | B9: =IF(C9="","-","X") -> - | C9: =IF('Financial Statements'!H6=0,"","Beginning balance sheet not in balance")
A10: Financial Statements | B10: =IF(C10="","-","X") -> - | C10: =IF('Financial Statements'!H12=0,"","Ending balance sheet not in balance")
C12: =IF(AND(B2="-",B3="-",B4="-",B5="-",B6="-",B7="-",B8="-",B9="-",B10="-"),"CONGRATULATIONS! Your work is internally consistent","Keep working!") -> CONGRATULATIONS! Your work is internally consistent

Sheet Account Names
A1: Account_Type | B1: Asset | C1: Liability | D1: Equity | E1: TempEquity | F1: NetAssets
A2: Asset | B2: Cash | C2: Current Liability 1 | D2: Contributed Equity 1 | E2: Revenue 1 | F2: Unrestricted Net Assets
A3: Liability | B3: Current Asset 2 | C3: Current Liability 2 | D3: Contributed Equity 2 | E3: Revenue 2 | F3: Restricted Net Assets
A4: Equity | B4: Current Asset 3 | C4: Current Liability 3 | D4: Contributed Equity 3 | E4: Expense 1
A5: TempEquity | B5: Contra to Current Asset 3 | C5: Current Liability 4 | D5: Retained Earnings | E5: Expense 2
B6: Current Asset 4 | C6: Current Liability 5 | D6: Accumulated Other Comp. Inc. | E6: Expense 3
B7: Contra to Current Asset 4 | C7: Current Liability 6 | D7: Contra Equity 1 | E7: Expense 4
B8: Current Asset 4 | C8: Current Liability 7 | E8: Expense 5
B9: Current Asset 5 | C9: Noncurrent Liability 1 | E9: Expense 6
B10: Current Asset 6 | C10: Noncurrent Liability 2 | E10: Expense 7
B11: Current Asset 7 | C11: Noncurrent Liability 3 | E11: Gain 1
A12: Operating | B12: Noncurrent Asset 1 | C12: Noncurrent Liability 4 | E12: Gain 2
A13: Investing | B13: Contra to Noncurrent Asset 1 | C13: Noncurrent Liability 5 | E13: Loss 1
A14: Financing | B14: Noncurrent Asset 2 | C14: Noncurrent Liability 6 | E14: Loss 2
B15: Contra to Noncurrent Asset 2 | C15: Noncurrent Liability 7
B16: Noncurrent Asset 3
B17: Noncurrent Asset 4
B20: For-Profit
B21: Asset
B22: Liability
B23: Equity
B24: TempEquity

Sheet Notice
