Workbook
Name AccountTypesUsed: _xlfn.ANCHORARRAY(MasterData!$L$5)
Name AssetUsed: _xlfn.ANCHORARRAY(MasterData!$L$56)
Name BB_Inbalance: Financial_Statement_Builder!$E$559
Name BegDate: ProblemData!$E$64
Name Begin: MasterData!$F$669:$F$688
Name Begin: MasterData!$F$669:$F$688
Name CFO_NI_Recon_NI: FSConstruction!$BA$7:$BE$7
Name DeprMethod: ProblemData!$E$72
Name End: MasterData!$G$669:$G$688
Name End: MasterData!$G$669:$G$688
Name EndDate: ProblemData!$E$65
Name Entity: ProblemData!$E$61
Name EntityActivity: ProblemData!$E$63
Name EntityType: ProblemData!$E$62
Name EquityUsed: _xlfn.ANCHORARRAY(MasterData!$L$116)
Name ExpenseUsed: _xlfn.ANCHORARRAY(MasterData!$L$149)
Name FS_IssueDate: ProblemData!$E$66
Name GainUsed: _xlfn.ANCHORARRAY(MasterData!$L$171)
Name InventoryMethod: ProblemData!$E$73
Name Issue_Date: ProblemData!$E$66
Name LiabilityUsed: _xlfn.ANCHORARRAY(MasterData!$L$83)
Name LossUsed: _xlfn.ANCHORARRAY(MasterData!$L$185)
Name ParValue: ProblemData!$E$70
Name Period: ProblemData!$E$67
Name PurposesUsed: _xlfn.ANCHORARRAY(MasterData!$F$512)
Name RevenueUsed: _xlfn.ANCHORARRAY(MasterData!$L$135)
Name RevRec: ProblemData!$E$74
Name ShrsOut: ProblemData!$E$69
Name TreasShrs: ProblemData!$E$71
Name Units: ProblemData!$E$68
Name ZZZ: FSConstruction!$BA$7:$BE$7

Sheet Tables and Columns
A1: Table Name | B1: Column Names
A2: MD_Account_Type_Labels | B2: ACCOUNT TYPE LABELS, Used
A3: MD_CF_Labels | B3: CASH FLOW STATEMENT LABELS, Used
A4: MD_Assets | B4: Account Name, Abbreviation, BalType, C/NC, Num, Definition, Used
A5: MD_Liabilities | B5: Account Name, Abbr, BalType, C/NC, Num, Definition, Used
A6: MD_Equities | B6: Account Name, Abbr, BalType, C/NC, Num, Definition, Used
A7: MD_Revenues | B7: Account Name, Abbr, BalType, C/NC, Num, Definition, Used
A8: MD_Expenses | B8: Account Name, Abbr, BalType, C/NC, Num, Definition, Used
A9: MD_Gains | B9: Account Name, Abbr, BalType, C/NC, Num, Definition, Used
A10: MD_Losses | B10: Account Name, Abbr, BalType, C/NC, Num, Definition, Used
A11: CashFlow_Codes | B11: Cash Flow Code
A12: Investing | B12: Transaction Description, Involve Cash, Abbr
... A34: Journal | B34: Transaction #, Accnt Type, Debit Account, Credit Account, Dr Amt, Cr Amt, Cash Flow, Movement #, Cash, ref1, ref2

Sheet FSFormattingCodes
B2: 1 | C2: Financial Statement Title
B3: 2 | C3: Main Heading
B4: 3 | C4: Main Heading Total
B5: 4 | C5: Subheading
B6: 5 | C6: Subheading Total
B7: 6 | C7: First Account Title or Explanation after Heading or Subheading
B8: 7 | C8: Not the First Account Title or Explanation after Heading or Subheading
B9: 8 | C9: Blank Line not in the Statement
B10: 9 | C10: Blank Line in the Statement
B11: 10 | C11: Units
B12: 11 | C12: Line not in the Statement
C15: Main Headings
C16: Assets
C17: Liabilities
C18: Equities
C21: Subheadings
C22: Revenues
C23: Expenses
C24: Account Abbreviations
C25: Operating
C26: Investing
C27: Financing
C28: Net Income (Loss)

Sheet MasterData
B2: Labels
C4: ACCOUNT TYPE LABELS | D4: Used | F4: ="MD_Account_Type_Labels[ACCOUNT TYPE LABELS]" -> MD_Account_Type_Labels[ACCOUNT TYPE LABELS] | L4: Account Types Used
C5: Asset | D5: =IF(MD_Account_Type_Labels[[#This Row],[ACCOUNT TYPE LABELS]]="","",IFERROR(IF(SEARCH(MD_Account_Type_Labels[[#This Row],[ACCOUNT TYPE LABELS]],ProblemData!$E$241)>0,1,0),"")) -> 1 | L5: {=IFERROR(_xlfn._xlws.FILTER(MD_Account_Type_Labels[ACCOUNT TYPE LABELS],MD_Account_Type_Labels[Used]=1),"")} -> Asset
C6: Liability | D6: =IF(MD_Account_Type_Labels[[#This Row],[ACCOUNT TYPE LABELS]]="","",IFERROR(IF(SEARCH(MD_Account_Type_Labels[[#This Row],[ACCOUNT TYPE LABELS]],ProblemData!$E$241)>0,1,0),"")) -> 1 | L6: Liability
C7: Equity | D7: =IF(MD_Account_Type_Labels[[#This Row],[ACCOUNT TYPE LABELS]]="","",IFERROR(IF(SEARCH(MD_Account_Type_Labels[[#This Row],[ACCOUNT TYPE LABELS]],ProblemData!$E$241)>0,1,0),"")) -> 1 | L7: Equity
C8: Revenue | D8: =IF(MD_Account_Type_Labels[[#This Row],[ACCOUNT TYPE LABELS]]="","",IFERROR(IF(SEARCH(MD_Account_Type_Labels[[#This Row],[ACCOUNT TYPE LABELS]],ProblemData!$E$241)>0,1,0),"")) -> 1 | L8: Revenue
C9: Expense | D9: =IF(MD_Account_Type_Labels[[#This Row],[ACCOUNT TYPE LABELS]]="","",IFERROR(IF(SEARCH(MD_Account_Type_Labels[[#This Row],[ACCOUNT TYPE LABELS]],ProblemData!$E$241)>0,1,0),"")) -> 1 | L9: Expense
C10: Gain | D10: =IF(MD_Account_Type_Labels[[#This Row],[ACCOUNT TYPE LABELS]]="","",IFERROR(IF(SEARCH(MD_Account_Type_Labels[[#This Row],[ACCOUNT TYPE LABELS]],ProblemData!$E$241)>0,1,0),"")) | L10: Loss
C11: Loss | D11: =IF(MD_Account_Type_Labels[[#This Row],[ACCOUNT TYPE LABELS]]="","",IFERROR(IF(SEARCH(MD_Account_Type_Labels[[#This Row],[ACCOUNT TYPE LABELS]],ProblemData!$E$241)>0,1,0),"")) -> 1
C14: CASH FLOW STATEMENT LABELS | D14: Used | E14: Include on Student List if Used | K14: CFS Labels Used for Students | L14: All CFS Labels Used
C15: Operating | D15: =IF(MD_CF_Labels[[#This Row],[CASH FLOW STATEMENT LABELS]]="","",IFERROR(IF(SEARCH(MD_CF_Labels[[#This Row],[CASH FLOW STATEMENT LABELS]],ProblemData!$E$242)>0,1,0),"")) -> 1 | E15: 1 | K15: {=IFERROR(_xlfn._xlws.FILTER(MD_CF_Labels[CASH FLOW STATEMENT LABELS],(MD_CF_Labels[Used]=1)*MD_CF_Labels[Include on Student List if Used]=1),"")} -> Operating | L15: {=IFERROR(_xlfn._xlws.FILTER(MD_CF_Labels[CASH FLOW STATEMENT LABELS],MD_CF_Labels[Used]=1),"")} -> Operating
C16: Investing | D16: =IF(MD_CF_Labels[[#This Row],[CASH FLOW STATEMENT LABELS]]="","",IFERROR(IF(SEARCH(MD_CF_Labels[[#This Row],[CASH FLOW STATEMENT LABELS]],ProblemData!$E$242)>0,1,0),"")) -> 1 | E16: 1 | K16: Investing | L16: Investing
C17: Financing | D17: =IF(MD_CF_Labels[[#This Row],[CASH FLOW STATEMENT LABELS]]="","",IFERROR(IF(SEARCH(MD_CF_Labels[[#This Row],[CASH FLOW STATEMENT LABELS]],ProblemData!$E$242)>0,1,0),"")) -> 1 | E17: 1 | K17: Financing | L17: Financing
C18: Noncash_Investing | D18: =IF(MD_CF_Labels[[#This Row],[CASH FLOW STATEMENT LABELS]]="","",IFERROR(IF(SEARCH(MD_CF_Labels[[#This Row],[CASH FLOW STATEMENT LABELS]],ProblemData!$E$242)>0,1,0),"")) -> 1 | E18: 0 | L18: Noncash_Investing
C19: Noncash_Financing | D19: =IF(MD_CF_Labels[[#This Row],[CASH FLOW STATEMENT LABELS]]="","",IFERROR(IF(SEARCH(MD_CF_Labels[[#This Row],[CASH FLOW STATEMENT LABELS]],ProblemData!$E$242)>0,1,0),"")) -> 1 | E19: 0 | L19: Noncash_Financing
C20: Noncash_Investing/Financing | D20: =IF(MD_CF_Labels[[#This Row],[CASH FLOW STATEMENT LABELS]]="","",IFERROR(IF(SEARCH(MD_CF_Labels[[#This Row],[CASH FLOW STATEMENT LABELS]],ProblemData!$E$242)>0,1,0),"")) | E20: 0
B24: Automation
C26: LEVELS OF FINANCIAL STATEMENT AUTOMATION | D26: Selected | F26: ="MD_FS_Automation[LEVELS OF FINANCIAL STATEMENT AUTOMATION]" -> MD_FS_Automation[LEVELS OF FINANCIAL STATEMENT AUTOMATION]
C27: None | D27: =IF(ProblemData!$E$3=MD_FS_Automation[[#This Row],[LEVELS OF FINANCIAL STATEMENT AUTOMATION]],1,"")
C28: Balance Sheets | D28: =IF(ProblemData!$E$3=MD_FS_Automation[[#This Row],[LEVELS OF FINANCIAL STATEMENT AUTOMATION]],1,"")
C29: Balance Sheets and Income Statement | D29: =IF(ProblemData!$E$3=MD_FS_Automation[[#This Row],[LEVELS OF FINANCIAL STATEMENT AUTOMATION]],1,"")
C30: Balance Sheets, Income Statement and Statement of Shareholders' Equity | D30: =IF(ProblemData!$E$3=MD_FS_Automation[[#This Row],[LEVELS OF FINANCIAL STATEMENT AUTOMATION]],1,"")
C31: Balance Sheets, Income Statement, Statement of Shareholders' Equity and Cash Flow Statement | D31: =IF(ProblemData!$E$3=MD_FS_Automation[[#This Row],[LEVELS OF FINANCIAL STATEMENT AUTOMATION]],1,"")
C32: All | D32: =IF(ProblemData!$E$3=MD_FS_Automation[[#This Row],[LEVELS OF FINANCIAL STATEMENT AUTOMATION]],1,"")
B34: Feedback
C36: LEVELS OF FEEDBACK | D36: Selected | F36: ="MD_Feedback[LEVELS OF FEEDBACK]" -> MD_Feedback[LEVELS OF FEEDBACK]
C37: None | D37: =IF(ProblemData!$E$10=MD_Feedback[[#This Row],[LEVELS OF FEEDBACK]],1,"")
C38: Journal Entry Tool in Analysis Help Only | D38: =IF(ProblemData!$E$10=MD_Feedback[[#This Row],[LEVELS OF FEEDBACK]],1,"")
C39: Journal Entry Tool in Analysis Help and Journal Entry Checker | D39: =IF(ProblemData!$E$10=MD_Feedback[[#This Row],[LEVELS OF FEEDBACK]],1,"")
C40: Journal Entry Tool in Analysis Help, Journal Entry Checker and Journal | D40: =IF(ProblemData!$E$10=MD_Feedback[[#This Row],[LEVELS OF FEEDBACK]],1,"")
D41: =IF(ProblemData!$E$10=MD_Feedback[[#This Row],[LEVELS OF FEEDBACK]],1,"")
D42: =IF(ProblemData!$E$10=MD_Feedback[[#This Row],[LEVELS OF FEEDBACK]],1,"")
D43: =IF(ProblemData!$E$10=MD_Feedback[[#This Row],[LEVELS OF FEEDBACK]],1,"")
D44: =IF(ProblemData!$E$10=MD_Feedback[[#This Row],[LEVELS OF FEEDBACK]],1,"")
D45: =IF(ProblemData!$E$10=MD_Feedback[[#This Row],[LEVELS OF FEEDBACK]],1,"")
D46: =IF(ProblemData!$E$10=MD_Feedback[[#This Row],[LEVELS OF FEEDBACK]],1,"")
D47: =IF(ProblemData!$E$10=MD_Feedback[[#This Row],[LEVELS OF FEEDBACK]],1,"")
B50: Accounts Taxonomy
B52: Balance Sheet Accounts
C54: Assets | AD54: {=_xlfn._xlws.FILTER(INDIRECT(J54,FALSE),INDIRECT(J54,FALSE)<>"")} -> #REF!
...

Sheet ProblemData
B1: Problem Parameters, Requirements and Purposes
D3: Item | E3: Allow Automation?
D4: All Entity Information, Units, Dates, … | E4: TRUE
D5: Entity Name | E5: FALSE
D6: Units | E6: FALSE
D7: Beginning Balance Sheet Date | E7: FALSE
D8: Ending Balance Sheet Date | E8: FALSE
D9: Period | E9: FALSE
D10: Beginning Balance Sheet | E10: TRUE
D11: Income Statement | E11: TRUE
D12: Statement of Comprehensive Income | E12: TRUE
D13: Statement of Changes in Shareholders' Equity | E13: TRUE
D14: Cash Flow Statement | E14: TRUE
D15: Reconciliation of NI and CFO | E15: TRUE
... D17: Ending Balance Sheet | E17: TRUE
D19: Feedback | E19: Allow?
D26: Purposes of Problem
D27: 1 | E27: Expand your financial vocabulary. | H27: 1
D28: 2 | E28: Use the Accounting Identity to analyze transactions. | H28: 1
D29: 3 | E29: Learn how to use the Analysis_Help | H29: 1
D30: 4 | H30: 1
D31: 5 | H31: 1
D33: Requirements
D34: Item | E34: Tab | F34: Action
D35: Chart of Accounts | E35: Instructions | F35: Omit
D36: Notes to the Financial Statements | E36: Notes_to_FSs | F36: Omit
D37: Beginning Balance Sheet | E37: Financial Statements | F37: Omit
D38: Journal entries for transactions and events of the period | E38: Journal | F38: Omit
D39: Journal entry to close temporary accounts | E39: Journal | F39: Omit
D40: Income Statement | E40: Financial Statements | F40: Omit
D41: Statement of Comprehensive Income | E41: Financial Statements | F41: Omit
D42: Statement of Shareholders' Equity | E42: Financial Statements | F42: Omit
D43: Cash flow statement labels in Column I of Journal | E43: Journal | F43: Omit
D44: Statement of Cash Flows | E44: Financial Statements | F44: Omit
D45: Net Income - Cash Flow from Operations Reconciliation Worksheet | E45: Reconciliation Worksheet | F45: Omit
... D50: Accounting Identity | E50: Analysis_Help | F50: Enter
B58: Entity Information
D60: Entity Information
D61: Entity | E61: Accounting Identity LLC
D62: Entity Type | E62: For-profit corporation
...

Sheet JournalAnswer
C2: Transaction # | D2: 32
C3: Transaction Description | L3: X
C4: {=INDEX(ProblemData!D78:AN79,2,D2+1)} -> 0 | L4: X
L5: X
L6: X
L7: X
C9: Journal Entries | G9: Drs | H9: Crs | I9: Diff
G10: =SUM(JournalAnswer[Dr Amt]) -> 393 | H10: =SUM(JournalAnswer[Cr Amt]) -> 393 | I10: =ROUND(G10-H10,2) -> 0
C11: Transaction # | D11: Accnt Type | E11: Debit Account | F11: Credit Account | G11: Dr Amt | H11: Cr Amt | I11: Cash Flow | J11: Movement # | K11: Cash | L11: ref1 | M11: ref2 | N11: ref3
B12: {=_xlfn._xlws.FILTER(ProblemData!$G$284:$G$808,ProblemData!$G$284:$G$808<>0)} -> 1 | C12: =IF(B12="","",B12) -> 1 | D12: =IFERROR(_xlfn.IFNA(INDEX(ProblemData!$C$78:$AM$145,MATCH(J12+0.1,ProblemData!$C$78:$C$145,0),MATCH(C12,ProblemData!$C$78:$AM$78,0)),""),"") -> Asset | E12: =IFERROR(_xlfn.IFNA(IF(INDEX(ProblemData!$C$78:$AM$145,MATCH(J12+0.3,ProblemData!$C$78:$C$145,0),MATCH(C12,ProblemData!$C$78:$AM$78,0))="Debit",INDEX(ProblemData!$C$78:$AM$145,MATCH(J12+0.2,ProblemData!$C$78:$C$145,0),MATCH(C12,ProblemData!$C$78:$AM$78,0)),""),""),"") -> Cash | F12: =IFERROR(_xlfn.IFNA(IF(INDEX(ProblemData!$C$78:$AM$145,MATCH(J12+0.3,ProblemData!$C$78:$C$145,0),MATCH(C12,ProblemData!$C$78:$AM$78,0))="Credit",INDEX(ProblemData!$C$78:$AM$145,MATCH(J12+0.2,ProblemData!$C$78:$C$145,0),MATCH(C12,ProblemData!$C$78:$AM$78,0)),""),""),"") | G12: =_xlfn.IFNA(IF(JournalAnswer[[#This Row],[Debit Account]]<>"",INDEX(ProblemData!$C$78:$AM$145,MATCH(J12+0.4,ProblemData!$C$78:$C$145,0),MATCH(C12,ProblemData!$C$78:$AM$78,0)),""),"") -> 50 | H12: =_xlfn.IFNA(IF(JournalAnswer[[#This Row],[Credit Account]]<>"",INDEX(ProblemData!$C$78:$AM$145,MATCH(J12+0.4,ProblemData!$C$78:$C$145,0),MATCH(C12,ProblemData!$C$78:$AM$78,0)),""),"") | I12: {=IF(JournalAnswer[[#This Row],[Debit Account]]="Cash",INDEX(ProblemData!$E$238:$AM$238,1,JournalAnswer[[#This Row],[Transaction '#]]),IF(JournalAnswer[[#This Row],[Credit Account]]="Cash",INDEX(ProblemData!$E$238:$AM$238,1,JournalAnswer[[#This Row],[Transaction '#]]),""))} -> Financing | J12: =IF(JournalAnswer[[#This Row],[Transaction '#]]="","",IF(JournalAnswer[[#This Row],[Transaction '#]]=C11,J11+1,1)) -> 1 | K12: {=IFERROR(_xlfn.IFS(JournalAnswer[[#This Row],[Debit Account]]="Cash",JournalAnswer[[#This Row],[Dr Amt]],JournalAnswer[[#This Row],[Credit Account]]="Cash",-JournalAnswer[[#This Row],[Cr Amt]]),0)} -> 50 | L12: {=IFERROR(INDEX(ProblemData!$E$239:$AM$239,1,JournalAnswer[[#This Row],[Transaction '#]]),"")} -> ICS | M12: =IF(JournalAnswer[[#This Row],[ref1]]="","",IF(NOT(ISBLANK(JournalAnswer[[#This Row],[Transaction '#]])),JournalAnswer[[#This Row],[ref1]]&JournalAnswer[[#This Row],[Movement '#]],"")) -> ICS1 | N12: =OR(JournalAnswer[[#This Row],[ref1]]="",ISNUMBER(MATCH(JournalAnswer[[#This Row],[ref1]], Operating[Abbr], 0)), "Found", "Not Found"="Found") -> FALSE
B13: 1 | C13: =IF(B13="","",B13) -> 1 | D13: =IFERROR(_xlfn.IFNA(INDEX(ProblemData!$C$78:$AM$145,MATCH(J13+0.1,ProblemData!$C$78:$C$145,0),MATCH(C13,ProblemData!$C$78:$AM$78,0)),""),"") -> Equity | E13: =IFERROR(_xlfn.IFNA(IF(INDEX(ProblemData!$C$78:$AM$145,MATCH(J13+0.3,ProblemData!$C$78:$C$145,0),MATCH(C13,ProblemData!$C$78:$AM$78,0))="Debit",INDEX(ProblemData!$C$78:$AM$145,MATCH(J13+0.2,ProblemData!$C$78:$C$145,0),MATCH(C13,ProblemData!$C$78:$AM$78,0)),""),""),"") | F13: =IFERROR(_xlfn.IFNA(IF(INDEX(ProblemData!$C$78:$AM$145,MATCH(J13+0.3,ProblemData!$C$78:$C$145,0),MATCH(C13,ProblemData!$C$78:$AM$78,0))="Credit",INDEX(ProblemData!$C$78:$AM$145,MATCH(J13+0.2,ProblemData!$C$78:$C$145,0),MATCH(C13,ProblemData!$C$78:$AM$78,0)),""),""),"") -> Common Stock | G13: =_xlfn.IFNA(IF(JournalAnswer[[#This Row],[Debit Account]]<>"",INDEX(ProblemData!$C$78:$AM$145,MATCH(J13+0.4,ProblemData!$C$78:$C$145,0),MATCH(C13,ProblemData!$C$78:$AM$78,0)),""),"") | H13: =_xlfn.IFNA(IF(JournalAnswer[[#This Row],[Credit Account]]<>"",INDEX(ProblemData!$C$78:$AM$145,MATCH(J13+0.4,ProblemData!$C$78:$C$145,0),MATCH(C13,ProblemData!$C$78:$AM$78,0)),""),"") -> 50 | I13: {=IF(JournalAnswer[[#This Row],[Debit Account]]="Cash",INDEX(ProblemData!$E$238:$AM$238,1,JournalAnswer[[#This Row],[Transaction '#]]),IF(JournalAnswer[[#This Row],[Credit Account]]="Cash",INDEX(ProblemData!$E$238:$AM$238,1,JournalAnswer[[#This Row],[Transaction '#]]),""))} | J13: =IF(JournalAnswer[[#This Row],[Transaction '#]]="","",IF(JournalAnswer[[#This Row],[Transaction '#]]=C12,J12+1,1)) -> 2 | K13: {=IFERROR(_xlfn.IFS(JournalAnswer[[#This Row],[Debit Account]]="Cash",JournalAnswer[[#This Row],[Dr Amt]],JournalAnswer[[#This Row],[Credit Account]]="Cash",-JournalAnswer[[#This Row],[Cr Amt]]),0)} -> 0 | L13: {=IFERROR(INDEX(ProblemData!$E$239:$AM$239,1,JournalAnswer[[#This Row],[Transaction '#]]),"")} -> ICS | M13: =IF(JournalAnswer[[#This Row],[ref1]]="","",IF(NOT(ISBLANK(JournalAnswer[[#This Row],[Transaction '#]])),JournalAnswer[[#This Row],[ref1]]&JournalAnswer[[#This Row],[Movement '#]],"")) -> ICS2 | N13: =OR(JournalAnswer[[#This Row],[ref1]]="",ISNUMBER(MATCH(JournalAnswer[[#This Row],[ref1]], Operating[Abbr], 0)), "Found", "Not Found"="Found") -> FALSE
B14: 2 | C14: =IF(B14="","",B14) -> 2 | D14: =IFERROR(_xlfn.IFNA(INDEX(ProblemData!$C$78:$AM$145,MATCH(J14+0.1,ProblemData!$C$78:$C$145,0),MATCH(C14,ProblemData!$C$78:$AM$78,0)),""),"") -> Asset | E14: =IFERROR(_xlfn.IFNA(IF(INDEX(ProblemData!$C$78:$AM$145,MATCH(J14+0.3,ProblemData!$C$78:$C$145,0),MATCH(C14,ProblemData!$C$78:$AM$78,0))="Debit",INDEX(ProblemData!$C$78:$AM$145,MATCH(J14+0.2,ProblemData!$C$78:$C$145,0),MATCH(C14,ProblemData!$C$78:$AM$78,0)),""),""),"") -> Cash | F14: =IFERROR(_xlfn.IFNA(IF(INDEX(ProblemData!$C$78:$AM$145,MATCH(J14+0.3,ProblemData!$C$78:$C$145,0),MATCH(C14,ProblemData!$C$78:$AM$78,0))="Credit",INDEX(ProblemData!$C$78:$AM$145,MATCH(J14+0.2,ProblemData!$C$78:$C$145,0),MATCH(C14,ProblemData!$C$78:$AM$78,0)),""),""),"") | G14: =_xlfn.IFNA(IF(JournalAnswer[[#This Row],[Debit Account]]<>"",INDEX(ProblemData!$C$78:$AM$145,MATCH(J14+0.4,ProblemData!$C$78:$C$145,0),MATCH(C14,ProblemData!$C$78:$AM$78,0)),""),"") -> 50 | H14: =_xlfn.IFNA(IF(JournalAnswer[[#This Row],[Credit Account]]<>"",INDEX(ProblemData!$C$78:$AM$145,MATCH(J14+0.4,ProblemData!$C$78:$C$145,0),MATCH(C14,ProblemData!$C$78:$AM$78,0)),""),"") | I14: {=IF(JournalAnswer[[#This Row],[Debit Account]]="Cash",INDEX(ProblemData!$E$238:$AM$238,1,JournalAnswer[[#This Row],[Transaction '#]]),IF(JournalAnswer[[#This Row],[Credit Account]]="Cash",INDEX(ProblemData!$E$238:$AM$238,1,JournalAnswer[[#This Row],[Transaction '#]]),""))} -> Financing | J14: =IF(JournalAnswer[[#This Row],[Transaction '#]]="","",IF(JournalAnswer[[#This Row],[Transaction '#]]=C13,J13+1,1)) -> 1 | K14: {=IFERROR(_xlfn.IFS(JournalAnswer[[#This Row],[Debit Account]]="Cash",JournalAnswer[[#This Row],[Dr Amt]],JournalAnswer[[#This Row],[Credit Account]]="Cash",-JournalAnswer[[#This Row],[Cr Amt]]),0)} -> 50 | L14: {=IFERROR(INDEX(ProblemData!$E$239:$AM$239,1,JournalAnswer[[#This Row],[Transaction '#]]),"")} -> GL | M14: =IF(JournalAnswer[[#This Row],[ref1]]="","",IF(NOT(ISBLANK(JournalAnswer[[#This Row],[Transaction '#]])),JournalAnswer[[#This Row],[ref1]]&JournalAnswer[[#This Row],[Movement '#]],"")) -> GL1 | N14: =OR(JournalAnswer[[#This Row],[ref1]]="",ISNUMBER(MATCH(JournalAnswer[[#This Row],[ref1]], Operating[Abbr], 0)), "Found", "Not Found"="Found") -> FALSE
B15: 2 | C15: =IF(B15="","",B15) -> 2 | D15: =IFERROR(_xlfn.IFNA(INDEX(ProblemData!$C$78:$AM$145,MATCH(J15+0.1,ProblemData!$C$78:$C$145,0),MATCH(C15,ProblemData!$C$78:$AM$78,0)),""),"") -> Liability | E15: =IFERROR(_xlfn.IFNA(IF(INDEX(ProblemData!$C$78:$AM$145,MATCH(J15+0.3,ProblemData!$C$78:$C$145,0),MATCH(C15,ProblemData!$C$78:$AM$78,0))="Debit",INDEX(ProblemData!$C$78:$AM$145,MATCH(J15+0.2,ProblemData!$C$78:$C$145,0),MATCH(C15,ProblemData!$C$78:$AM$78,0)),""),""),"") | F15: =IFERROR(_xlfn.IFNA(IF(INDEX(ProblemData!$C$78:$AM$145,MATCH(J15+0.3,ProblemData!$C$78:$C$145,0),MATCH(C15,ProblemData!$C$78:$AM$78,0))="Credit",INDEX(ProblemData!$C$78:$AM$145,MATCH(J15+0.2,ProblemData!$C$78:$C$145,0),MATCH(C15,ProblemData!$C$78:$AM$78,0)),""),""),"") -> Loans Payable | G15: =_xlfn.IFNA(IF(JournalAnswer[[#This Row],[Debit Account]]<>"",INDEX(ProblemData!$C$78:$AM$145,MATCH(J15+0.4,ProblemData!$C$78:$C$145,0),MATCH(C15,ProblemData!$C$78:$AM$78,0)),""),"") | H15: =_xlfn.IFNA(IF(JournalAnswer[[#This Row],[Credit Account]]<>"",INDEX(ProblemData!$C$78:$AM$145,MATCH(J15+0.4,ProblemData!$C$78:$C$145,0),MATCH(C15,ProblemData!$C$78:$AM$78,0)),""),"") -> 50 | I15: {=IF(JournalAnswer[[#This Row],[Debit Account]]="Cash",INDEX(ProblemData!$E$238:$AM$238,1,JournalAnswer[[#This Row],[Transaction '#]]),IF(JournalAnswer[[#This Row],[Credit Account]]="Cash",INDEX(ProblemData!$E$238:$AM$238,1,JournalAnswer[[#This Row],[Transaction '#]]),""))} | J15: =IF(JournalAnswer[[#This Row],[Transaction '#]]="","",IF(JournalAnswer[[#This Row],[Transaction '#]]=C14,J14+1,1)) -> 2 | K15: {=IFERROR(_xlfn.IFS(JournalAnswer[[#This Row],[Debit Account]]="Cash",JournalAnswer[[#This Row],[Dr Amt]],JournalAnswer[[#This Row],[Credit Account]]="Cash",-JournalAnswer[[#This Row],[Cr Amt]]),0)} -> 0 | L15: {=IFERROR(INDEX(ProblemData!$E$239:$AM$239,1,JournalAnswer[[#This Row],[Transaction '#]]),"")} -> GL | M15: =IF(JournalAnswer[[#This Row],[ref1]]="","",IF(NOT(ISBLANK(JournalAnswer[[#This Row],[Transaction '#]])),JournalAnswer[[#This Row],[ref1]]&JournalAnswer[[#This Row],[Movement '#]],"")) -> GL2 | N15: =OR(JournalAnswer[[#This Row],[ref1]]="",ISNUMBER(MATCH(JournalAnswer[[#This Row],[ref1]], Operating[Abbr], 0)), "Found", "Not Found"="Found") -> FALSE
B16: 3 | C16: =IF(B16="","",B16) -> 3 | D16: =IFERROR(_xlfn.IFNA(INDEX(ProblemData!$C$78:$AM$145,MATCH(J16+0.1,ProblemData!$C$78:$C$145,0),MATCH(C16,ProblemData!$C$78:$AM$78,0)),""),"") -> Asset | E16: =IFERROR(_xlfn.IFNA(IF(INDEX(ProblemData!$C$78:$AM$145,MATCH(J16+0.3,ProblemData!$C$78:$C$145,0),MATCH(C16,ProblemData!$C$78:$AM$78,0))="Debit",INDEX(ProblemData!$C$78:$AM$145,MATCH(J16+0.2,ProblemData!$C$78:$C$145,0),MATCH(C16,ProblemData!$C$78:$AM$78,0)),""),""),"") -> Cash | F16: =IFERROR(_xlfn.IFNA(IF(INDEX(ProblemData!$C$78:$AM$145,MATCH(J16+0.3,ProblemData!$C$78:$C$145,0),MATCH(C16,ProblemData!$C$78:$AM$78,0))="Credit",INDEX(ProblemData!$C$78:$AM$145,MATCH(J16+0.2,ProblemData!$C$78:$C$145,0),MATCH(C16,ProblemData!$C$78:$AM$78,0)),""),""),"") | G16: =_xlfn.IFNA(IF(JournalAnswer[[#This Row],[Debit Account]]<>"",INDEX(ProblemData!$C$78:$AM$145,MATCH(J16+0.4,ProblemData!$C$78:$C$145,0),MATCH(C16,ProblemData!$C$78:$AM$78,0)),""),"") -> 50 | H16: =_xlfn.IFNA(IF(JournalAnswer[[#This Row],[Credit Account]]<>"",INDEX(ProblemData!$C$78:$AM$145,MATCH(J16+0.4,ProblemData!$C$78:$C$145,0),MATCH(C16,ProblemData!$C$78:$AM$78,0)),""),"") | I16: {=IF(JournalAnswer[[#This Row],[Debit Account]]="Cash",INDEX(ProblemData!$E$238:$AM$238,1,JournalAnswer[[#This Row],[Transaction '#]]),IF(JournalAnswer[[#This Row],[Credit Account]]="Cash",INDEX(ProblemData!$E$238:$AM$238,1,JournalAnswer[[#This Row],[Transaction '#]]),""))} -> Operating | J16: =IF(JournalAnswer[[#This Row],[Transaction '#]]="","",IF(JournalAnswer[[#This Row],[Transaction '#]]=C15,J15+1,1)) -> 1 | K16: {=IFERROR(_xlfn.IFS(JournalAnswer[[#This Row],[Debit Account]]="Cash",JournalAnswer[[#This Row],[Dr Amt]],JournalAnswer[[#This Row],[Credit Account]]="Cash",-JournalAnswer[[#This Row],[Cr Amt]]),0)} -> 50 | L16: {=IFERROR(INDEX(ProblemData!$E$239:$AM$239,1,JournalAnswer[[#This Row],[Transaction '#]]),"")} -> ColC | M16: =IF(JournalAnswer[[#This Row],[ref1]]="","",IF(NOT(ISBLANK(JournalAnswer[[#This Row],[Transaction '#]])),JournalAnswer[[#This Row],[ref1]]&JournalAnswer[[#This Row],[Movement '#]],"")) -> ColC1 | N16: =OR(JournalAnswer[[#This Row],[ref1]]="",ISNUMBER(MATCH(JournalAnswer[[#This Row],[ref1]], Operating[Abbr], 0)), "Found", "Not Found"="Found") -> TRUE
B17: 3 | C17: =IF(B17="","",B17) -> 3 | D17: =IFERROR(_xlfn.IFNA(INDEX(ProblemData!$C$78:$AM$145,MATCH(J17+0.1,ProblemData!$C$78:$C$145,0),MATCH(C17,ProblemData!$C$78:$AM$78,0)),""),"") -> Revenue | E17: =IFERROR(_xlfn.IFNA(IF(INDEX(ProblemData!$C$78:$AM$145,MATCH(J17+0.3,ProblemData!$C$78:$C$145,0),MATCH(C17,ProblemData!$C$78:$AM$78,0))="Debit",INDEX(ProblemData!$C$78:$AM$145,MATCH(J17+0.2,ProblemData!$C$78:$C$145,0),MATCH(C17,ProblemData!$C$78:$AM$78,0)),""),""),"") | F17: =IFERROR(_xlfn.IFNA(IF(INDEX(ProblemData!$C$78:$AM$145,MATCH(J17+0.3,ProblemData!$C$78:$C$145,0),MATCH(C17,ProblemData!$C$78:$AM$78,0))="Credit",INDEX(ProblemData!$C$78:$AM$145,MATCH(J17+0.2,ProblemData!$C$78:$C$145,0),MATCH(C17,ProblemData!$C$78:$AM$78,0)),""),""),"") -> Revenue from Services | G17: =_xlfn.IFNA(IF(JournalAnswer[[#This Row],[Debit Account]]<>"",INDEX(ProblemData!$C$78:$AM$145,MATCH(J17+0.4,ProblemData!$C$78:$C$145,0),MATCH(C17,ProblemData!$C$78:$AM$78,0)),""),"") | H17: =_xlfn.IFNA(IF(JournalAnswer[[#This Row],[Credit Account]]<>"",INDEX(ProblemData!$C$78:$AM$145,MATCH(J17+0.4,ProblemData!$C$78:$C$145,0),MATCH(C17,ProblemData!$C$78:$AM$78,0)),""),"") -> 50 | I17: {=IF(JournalAnswer[[#This Row],[Debit Account]]="Cash",INDEX(ProblemData!$E$238:$AM$238,1,JournalAnswer[[#This Row],[Transaction '#]]),IF(JournalAnswer[[#This Row],[Credit Account]]="Cash",INDEX(ProblemData!$E$238:$AM$238,1,JournalAnswer[[#This Row],[Transaction '#]]),""))} | J17: =IF(JournalAnswer[[#This Row],[Transaction '#]]="","",IF(JournalAnswer[[#This Row],[Transaction '#]]=C16,J16+1,1)) -> 2 | K17: {=IFERROR(_xlfn.IFS(JournalAnswer[[#This Row],[Debit Account]]="Cash",JournalAnswer[[#This Row],[Dr Amt]],JournalAnswer[[#This Row],[Credit Account]]="Cash",-JournalAnswer[[#This Row],[Cr Amt]]),0)} -> 0 | L17: {=IFERROR(INDEX(ProblemData!$E$239:$AM$239,1,JournalAnswer[[#This Row],[Transaction '#]]),"")} -> ColC | M17: =IF(JournalAnswer[[#This Row],[ref1]]="","",IF(NOT(ISBLANK(JournalAnswer[[#This Row],[Transaction '#]])),JournalAnswer[[#This Row],[ref1]]&JournalAnswer[[#This Row],[Movement '#]],"")) -> ColC2 | N17: =OR(JournalAnswer[[#This Row],[ref1]]="",ISNUMBER(MATCH(JournalAnswer[[#This Row],[ref1]], Operating[Abbr], 0)), "Found", "Not Found"="Found") -> TRUE
B18: 4 | C18: =IF(B18="","",B18) -> 4 | D18: =IFERROR(_xlfn.IFNA(INDEX(ProblemData!$C$78:$AM$145,MATCH(J18+0.1,ProblemData!$C$78:$C$145,0),MATCH(C18,ProblemData!$C$78:$AM$78,0)),""),"") -> Asset | E18: =IFERROR(_xlfn.IFNA(IF(INDEX(ProblemData!$C$78:$AM$145,MATCH(J18+0.3,ProblemData!$C$78:$C$145,0),MATCH(C18,ProblemData!$C$78:$AM$78,0))="Debit",INDEX(ProblemData!$C$78:$AM$145,MATCH(J18+0.2,ProblemData!$C$78:$C$145,0),MATCH(C18,ProblemData!$C$78:$AM$78,0)),""),""),"") -> Property, Plant & Equipment | F18: =IFERROR(_xlfn.IFNA(IF(INDEX(ProblemData!$C$78:$AM$145,MATCH(J18+0.3,ProblemData!$C$78:$C$145,0),MATCH(C18,ProblemData!$C$78:$AM$78,0))="Credit",INDEX(ProblemData!$C$78:$AM$145,MATCH(J18+0.2,ProblemData!$C$78:$C$145,0),MATCH(C18,ProblemData!$C$78:$AM$78,0)),""),""),"") | G18: =_xlfn.IFNA(IF(JournalAnswer[[#This Row],[Debit Account]]<>"",INDEX(ProblemData!$C$78:$AM$145,MATCH(J18+0.4,ProblemData!$C$78:$C$145,0),MATCH(C18,ProblemData!$C$78:$AM$78,0)),""),"") -> 50 | H18: =_xlfn.IFNA(IF(JournalAnswer[[#This Row],[Credit Account]]<>"",INDEX(ProblemData!$C$78:$AM$145,MATCH(J18+0.4,ProblemData!$C$78:$C$145,0),MATCH(C18,ProblemData!$C$78:$AM$78,0)),""),"") | I18: {=IF(JournalAnswer[[#This Row],[Debit Account]]="Cash",INDEX(ProblemData!$E$238:$AM$238,1,JournalAnswer[[#This Row],[Transaction '#]]),IF(JournalAnswer[[#This Row],[Credit Account]]="Cash",INDEX(ProblemData!$E$238:$AM$238,1,JournalAnswer[[#This Row],[Transaction '#]]),""))} | J18: =IF(JournalAnswer[[#This Row],[Transaction '#]]="","",IF(JournalAnswer[[#This Row],[Transaction '#]]=C17,J17+1,1)) -> 1 | K18: {=IFERROR(_xlfn.IFS(JournalAnswer[[#This Row],[Debit Account]]="Cash",JournalAnswer[[#This Row],[Dr Amt]],JournalAnswer[[#This Row],[Credit Account]]="Cash",-JournalAnswer[[#This Row],[Cr Amt]]),0)} -> 0 | L18: {=IFERROR(INDEX(ProblemData!$E$239:$AM$239,1,JournalAnswer[[#This Row],[Transaction '#]]),"")} -> PPEfCS | M18: =IF(JournalAnswer[[#This Row],[ref1]]="","",IF(NOT(ISBLANK(JournalAnswer[[#This Row],[Transaction '#]])),JournalAnswer[[#This Row],[ref1]]&JournalAnswer[[#This Row],[Movement '#]],"")) -> PPEfCS1 | N18: =OR(JournalAnswer[[#This Row],[ref1]]="",ISNUMBER(MATCH(JournalAnswer[[#This Row],[ref1]], Operating[Abbr], 0)), "Found", "Not Found"="Found") -> FALSE
B19: 4 | C19: =IF(B19="","",B19) -> 4 | D19: =IFERROR(_xlfn.IFNA(INDEX(ProblemData!$C$78:$AM$145,MATCH(J19+0.1,ProblemData!$C$78:$C$145,0),MATCH(C19,ProblemData!$C$78:$AM$78,0)),""),"") -> Equity | E19: =IFERROR(_xlfn.IFNA(IF(INDEX(ProblemData!$C$78:$AM$145,MATCH(J19+0.3,ProblemData!$C$78:$C$145,0),MATCH(C19,ProblemData!$C$78:$AM$78,0))="Debit",INDEX(ProblemData!$C$78:$AM$145,MATCH(J19+0.2,ProblemData!$C$78:$C$145,0),MATCH(C19,ProblemData!$C$78:$AM$78,0)),""),""),"") | F19: =IFERROR(_xlfn.IFNA(IF(INDEX(ProblemData!$C$78:$AM$145,MATCH(J19+0.3,ProblemData!$C$78:$C$145,0),MATCH(C19,ProblemData!$C$78:$AM$78,0))="Credit",INDEX(ProblemData!$C$78:$AM$145,MATCH(J19+0.2,ProblemData!$C$78:$C$145,0),MATCH(C19,ProblemData!$C$78:$AM$78,0)),""),""),"") -> Common Stock | G19: =_xlfn.IFNA(IF(JournalAnswer[[#This Row],[Debit Account]]<>"",INDEX(ProblemData!$C$78:$AM$145,MATCH(J19+0.4,ProblemData!$C$78:$C$145,0),MATCH(C19,ProblemData!$C$78:$AM$78,0)),""),"") | H19: =_xlfn.IFNA(IF(JournalAnswer[[#This Row],[Credit Account]]<>"",INDEX(ProblemData!$C$78:$AM$145,MATCH(J19+0.4,ProblemData!$C$78:$C$145,0),MATCH(C19,ProblemData!$C$78:$AM$78,0)),""),"") -> 50 | I19: {=IF(JournalAnswer[[#This Row],[Debit Account]]="Cash",INDEX(ProblemData!$E$238:$AM$238,1,JournalAnswer[[#This Row],[Transaction '#]]),IF(JournalAnswer[[#This Row],[Credit Account]]="Cash",INDEX(ProblemData!$E$238:$AM$238,1,JournalAnswer[[#This Row],[Transaction '#]]),""))} | J19: =IF(JournalAnswer[[#This Row],[Transaction '#]]="","",IF(JournalAnswer[[#This Row],[Transaction '#]]=C18,J18+1,1)) -> 2 | K19: {=IFERROR(_xlfn.IFS(JournalAnswer[[#This Row],[Debit Account]]="Cash",JournalAnswer[[#This Row],[Dr Amt]],JournalAnswer[[#This Row],[Credit Account]]="Cash",-JournalAnswer[[#This Row],[Cr Amt]]),0)} -> 0 | L19: {=IFERROR(INDEX(ProblemData!$E$239:$AM$239,1,JournalAnswer[[#This Row],[Transaction '#]]),"")} -> PPEfCS | M19: =IF(JournalAnswer[[#This Row],[ref1]]="","",IF(NOT(ISBLANK(JournalAnswer[[#This Row],[Transaction '#]])),JournalAnswer[[#This Row],[ref1]]&JournalAnswer[[#This Row],[Movement '#]],"")) -> PPEfCS2 | N19: =OR(JournalAnswer[[#This Row],[ref1]]="",ISNUMBER(MATCH(JournalAnswer[[#This Row],[ref1]], Operating[Abbr], 0)), "Found", "Not Found"="Found") -> FALSE
B20: 5 | C20: =IF(B20="","",B20) -> 5 | D20: =IFERROR(_xlfn.IFNA(INDEX(ProblemData!$C$78:$AM$145,MATCH(J20+0.1,ProblemData!$C$78:$C$145,0),MATCH(C20,ProblemData!$C$78:$AM$78,0)),""),"") -> Asset | E20: =IFERROR(_xlfn.IFNA(IF(INDEX(ProblemData!$C$78:$AM$145,MATCH(J20+0.3,ProblemData!$C$78:$C$145,0),MATCH(C20,ProblemData!$C$78:$AM$78,0))="Debit",INDEX(ProblemData!$C$78:$AM$145,MATCH(J20+0.2,ProblemData!$C$78:$C$145,0),MATCH(C20,ProblemData!$C$78:$AM$78,0)),""),""),"") -> Property, Plant & Equipment | F20: =IFERROR(_xlfn.IFNA(IF(INDEX(ProblemData!$C$78:$AM$145,MATCH(J20+0.3,ProblemData!$C$78:$C$145,0),MATCH(C20,ProblemData!$C$78:$AM$78,0))="Credit",INDEX(ProblemData!$C$78:$AM$145,MATCH(J20+0.2,ProblemData!$C$78:$C$145,0),MATCH(C20,ProblemData!$C$78:$AM$78,0)),""),""),"") | G20: =_xlfn.IFNA(IF(JournalAnswer[[#This Row],[Debit Account]]<>"",INDEX(ProblemData!$C$78:$AM$145,MATCH(J20+0.4,ProblemData!$C$78:$C$145,0),MATCH(C20,ProblemData!$C$78:$AM$78,0)),""),"") -> 50 | H20: =_xlfn.IFNA(IF(JournalAnswer[[#This Row],[Credit Account]]<>"",INDEX(ProblemData!$C$78:$AM$145,MATCH(J20+0.4,ProblemData!$C$78:$C$145,0),MATCH(C20,ProblemData!$C$78:$AM$78,0)),""),"") | I20: {=IF(JournalAnswer[[#This Row],[Debit Account]]="Cash",INDEX(ProblemData!$E$238:$AM$238,1,JournalAnswer[[#This Row],[Transaction '#]]),IF(JournalAnswer[[#This Row],[Credit Account]]="Cash",INDEX(ProblemData!$E$238:$AM$238,1,JournalAnswer[[#This Row],[Transaction '#]]),""))} | J20: =IF(JournalAnswer[[#This Row],[Transaction '#]]="","",IF(JournalAnswer[[#This Row],[Transaction '#]]=C19,J19+1,1)) -> 1 | K20: {=IFERROR(_xlfn.IFS(JournalAnswer[[#This Row],[Debit Account]]="Cash",JournalAnswer[[#This Row],[Dr Amt]],JournalAnswer[[#This Row],[Credit Account]]="Cash",-JournalAnswer[[#This Row],[Cr Amt]]),0)} -> 0 | L20: {=IFERROR(INDEX(ProblemData!$E$239:$AM$239,1,JournalAnswer[[#This Row],[Transaction '#]]),"")} -> PPEfL | M20: =IF(JournalAnswer[[#This Row],[ref1]]="","",IF(NOT(ISBLANK(JournalAnswer[[#This Row],[Transaction '#]])),JournalAnswer[[#This Row],[ref1]]&JournalAnswer[[#This Row],[Movement '#]],"")) -> PPEfL1 | N20: =OR(JournalAnswer[[#This Row],[ref1]]="",ISNUMBER(MATCH(JournalAnswer[[#This Row],[ref1]], Operating[Abbr], 0)), "Found", "Not Found"="Found") -> FALSE
B21: 5 | C21: =IF(B21="","",B21) -> 5 | D21: =IFERROR(_xlfn.IFNA(INDEX(ProblemData!$C$78:$AM$145,MATCH(J21+0.1,ProblemData!$C$78:$C$145,0),MATCH(C21,ProblemData!$C$78:$AM$78,0)),""),"") -> Liability | E21: =IFERROR(_xlfn.IFNA(IF(INDEX(ProblemData!$C$78:$AM$145,MATCH(J21+0.3,ProblemData!$C$78:$C$145,0),MATCH(C21,ProblemData!$C$78:$AM$78,0))="Debit",INDEX(ProblemData!$C$78:$AM$145,MATCH(J21+0.2,ProblemData!$C$78:$C$145,0),MATCH(C21,ProblemData!$C$78:$AM$78,0)),""),""),"") | F21: =IFERROR(_xlfn.IFNA(IF(INDEX(ProblemData!$C$78:$AM$145,MATCH(J21+0.3,ProblemData!$C$78:$C$145,0),MATCH(C21,ProblemData!$C$78:$AM$78,0))="Credit",INDEX(ProblemData!$C$78:$AM$145,MATCH(J21+0.2,ProblemData!$C$78:$C$145,0),MATCH(C21,ProblemData!$C$78:$AM$78,0)),""),""),"") -> Loans Payable | G21: =_xlfn.IFNA(IF(JournalAnswer[[#This Row],[Debit Account]]<>"",INDEX(ProblemData!$C$78:$AM$145,MATCH(J21+0.4,ProblemData!$C$78:$C$145,0),MATCH(C21,ProblemData!$C$78:$AM$78,0)),""),"") | H21: =_xlfn.IFNA(IF(JournalAnswer[[#This Row],[Credit Account]]<>"",INDEX(ProblemData!$C$78:$AM$145,MATCH(J21+0.4,ProblemData!$C$78:$C$145,0),MATCH(C21,ProblemData!$C$78:$AM$78,0)),""),"") -> 50 | I21: {=IF(JournalAnswer[[#This Row],[Debit Account]]="Cash",INDEX(ProblemData!$E$238:$AM$238,1,JournalAnswer[[#This Row],[Transaction '#]]),IF(JournalAnswer[[#This Row],[Credit Account]]="Cash",INDEX(ProblemData!$E$238:$AM$238,1,JournalAnswer[[#This Row],[Transaction '#]]),""))} | J21: =IF(JournalAnswer[[#This Row],[Transaction '#]]="","",IF(JournalAnswer[[#This Row],[Transaction '#]]=C20,J20+1,1)) -> 2 | K21: {=IFERROR(_xlfn.IFS(JournalAnswer[[#This Row],[Debit Account]]="Cash",JournalAnswer[[#This Row],[Dr Amt]],JournalAnswer[[#This Row],[Credit Account]]="Cash",-JournalAnswer[[#This Row],[Cr Amt]]),0)} -> 0 | L21: {=IFERROR(INDEX(ProblemData!$E$239:$AM$239,1,JournalAnswer[[#This Row],[Transaction '#]]),"")} -> PPEfL | M21: =IF(JournalAnswer[[#This Row],[ref1]]="","",IF(NOT(ISBLANK(JournalAnswer[[#This Row],[Transaction '#]])),JournalAnswer[[#This Row],[ref1]]&JournalAnswer[[#This Row],[Movement '#]],"")) -> PPEfL2 | N21: =OR(JournalAnswer[[#This Row],[ref1]]="",ISNUMBER(MATCH(JournalAnswer[[#This Row],[ref1]], Operating[Abbr], 0)), "Found", "Not Found"="Found") -> FALSE
B22: 6 | C22: =IF(B22="","",B22) -> 6 | D22: =IFERROR(_xlfn.IFNA(INDEX(ProblemData!$C$78:$AM$145,MATCH(J22+0.1,ProblemData!$C$78:$C$145,0),MATCH(C22,ProblemData!$C$78:$AM$78,0)),""),"") -> Asset | E22: =IFERROR(_xlfn.IFNA(IF(INDEX(ProblemData!$C$78:$AM$145,MATCH(J22+0.3,ProblemData!$C$78:$C$145,0),MATCH(C22,ProblemData!$C$78:$AM$78,0))="Debit",INDEX(ProblemData!$C$78:$AM$145,MATCH(J22+0.2,ProblemData!$C$78:$C$145,0),MATCH(C22,ProblemData!$C$78:$AM$78,0)),""),""),"") -> Inventories | F22: =IFERROR(_xlfn.IFNA(IF(INDEX(ProblemData!$C$78:$AM$145,MATCH(J22+0.3,ProblemData!$C$78:$C$145,0),MATCH(C22,ProblemData!$C$78:$AM$78,0))="Credit",INDEX(ProblemData!$C$78:$AM$145,MATCH(J22+0.2,ProblemData!$C$78:$C$145,0),MATCH(C22,ProblemData!$C$78:$AM$78,0)),""),""),"") | G22: =_xlfn.IFNA(IF(JournalAnswer[[#This Row],[Debit Account]]<>"",INDEX(ProblemData!$C$78:$AM$145,MATCH(J22+0.4,ProblemData!$C$78:$C$145,0),MATCH(C22,ProblemData!$C$78:$AM$78,0)),""),"") -> 18 | H22: =_xlfn.IFNA(IF(JournalAnswer[[#This Row],[Credit Account]]<>"",INDEX(ProblemData!$C$78:$AM$145,MATCH(J22+0.4,ProblemData!$C$78:$C$145,0),MATCH(C22,ProblemData!$C$78:$AM$78,0)),""),"") | I22: {=IF(JournalAnswer[[#This Row],[Debit Account]]="Cash",INDEX(ProblemData!$E$238:$AM$238,1,JournalAnswer[[#This Row],[Transaction '#]]),IF(JournalAnswer[[#This Row],[Credit Account]]="Cash",INDEX(ProblemData!$E$238:$AM$238,1,JournalAnswer[[#This Row],[Transaction '#]]),""))} | J22: =IF(JournalAnswer[[#This Row],[Transaction '#]]="","",IF(JournalAnswer[[#This Row],[Transaction '#]]=C21,J21+1,1)) -> 1 | K22: {=IFERROR(_xlfn.IFS(JournalAnswer[[#This Row],[Debit Account]]="Cash",JournalAnswer[[#This Row],[Dr Amt]],JournalAnswer[[#This Row],[Credit Account]]="Cash",-JournalAnswer[[#This Row],[Cr Amt]]),0)} -> 0 | L22: {=IFERROR(INDEX(ProblemData!$E$239:$AM$239,1,JournalAnswer[[#This Row],[Transaction '#]]),"")} -> PdS | M22: =IF(JournalAnswer[[#This Row],[ref1]]="","",IF(NOT(ISBLANK(JournalAnswer[[#This Row],[Transaction '#]])),JournalAnswer[[#This Row],[ref1]]&JournalAnswer[[#This Row],[Movement '#]],"")) -> PdS1 | N22: =OR(JournalAnswer[[#This Row],[ref1]]="",ISNUMBER(MATCH(JournalAnswer[[#This Row],[ref1]], Operating[Abbr], 0)), "Found", "Not Found"="Found") -> TRUE
B23: 6 | C23: =IF(B23="","",B23) -> 6 | D23: =IFERROR(_xlfn.IFNA(INDEX(ProblemData!$C$78:$AM$145,MATCH(J23+0.1,ProblemData!$C$78:$C$145,0),MATCH(C23,ProblemData!$C$78:$AM$78,0)),""),"") -> Asset | E23: =IFERROR(_xlfn.IFNA(IF(INDEX(ProblemData!$C$78:$AM$145,MATCH(J23+0.3,ProblemData!$C$78:$C$145,0),MATCH(C23,ProblemData!$C$78:$AM$78,0))="Debit",INDEX(ProblemData!$C$78:$AM$145,MATCH(J23+0.2,ProblemData!$C$78:$C$145,0),MATCH(C23,ProblemData!$C$78:$AM$78,0)),""),""),"") | F23: =IFERROR(_xlfn.IFNA(IF(INDEX(ProblemData!$C$78:$AM$145,MATCH(J23+0.3,ProblemData!$C$78:$C$145,0),MATCH(C23,ProblemData!$C$78:$AM$78,0))="Credit",INDEX(ProblemData!$C$78:$AM$145,MATCH(J23+0.2,ProblemData!$C$78:$C$145,0),MATCH(C23,ProblemData!$C$78:$AM$78,0)),""),""),"") -> Cash | G23: =_xlfn.IFNA(IF(JournalAnswer[[#This Row],[Debit Account]]<>"",INDEX(ProblemData!$C$78:$AM$145,MATCH(J23+0.4,ProblemData!$C$78:$C$145,0),MATCH(C23,ProblemData!$C$78:$AM$78,0)),""),"") | H23: =_xlfn.IFNA(IF(JournalAnswer[[#This Row],[Credit Account]]<>"",INDEX(ProblemData!$C$78:$AM$145,MATCH(J23+0.4,ProblemData!$C$78:$C$145,0),MATCH(C23,ProblemData!$C$78:$AM$78,0)),""),"") -> 18 | I23: {=IF(JournalAnswer[[#This Row],[Debit Account]]="Cash",INDEX(ProblemData!$E$238:$AM$238,1,JournalAnswer[[#This Row],[Transaction '#]]),IF(JournalAnswer[[#This Row],[Credit Account]]="Cash",INDEX(ProblemData!$E$238:$AM$238,1,JournalAnswer[[#This Row],[Transaction '#]]),""))} -> Operating | J23: =IF(JournalAnswer[[#This Row],[Transaction '#]]="","",IF(JournalAnswer[[#This Row],[Transaction '#]]=C22,J22+1,1)) -> 2 | K23: {=IFERROR(_xlfn.IFS(JournalAnswer[[#This Row],[Debit Account]]="Cash",JournalAnswer[[#This Row],[Dr Amt]],JournalAnswer[[#This Row],[Credit Account]]="Cash",-JournalAnswer[[#This Row],[Cr Amt]]),0)} -> -18 | L23: {=IFERROR(INDEX(ProblemData!$E$239:$AM$239,1,JournalAnswer[[#This Row],[Transaction '#]]),"")} -> PdS | M23: =IF(JournalAnswer[[#This Row],[ref1]]="","",IF(NOT(ISBLANK(JournalAnswer[[#This Row],[Transaction '#]])),JournalAnswer[[#This Row],[ref1]]&JournalAnswer[[#This Row],[Movement '#]],"")) -> PdS2 | N23: =OR(JournalAnswer[[#This Row],[ref1]]="",ISNUMBER(MATCH(JournalAnswer[[#This Row],[ref1]], Operating[Abbr], 0)), "Found", "Not Found"="Found") -> TRUE
B24: 7 | C24: =IF(B24="","",B24) -> 7 | D24: =IFERROR(_xlfn.IFNA(INDEX(ProblemData!$C$78:$AM$145,MATCH(J24+0.1,ProblemData!$C$78:$C$145,0),MATCH(C24,ProblemData!$C$78:$AM$78,0)),""),"") -> Asset | E24: =IFERROR(_xlfn.IFNA(IF(INDEX(ProblemData!$C$78:$AM$145,MATCH(J24+0.3,ProblemData!$C$78:$C$145,0),MATCH(C24,ProblemData!$C$78:$AM$78,0))="Debit",INDEX(ProblemData!$C$78:$AM$145,MATCH(J24+0.2,ProblemData!$C$78:$C$145,0),MATCH(C24,ProblemData!$C$78:$AM$78,0)),""),""),"") -> Inventories | F24: =IFERROR(_xlfn.IFNA(IF(INDEX(ProblemData!$C$78:$AM$145,MATCH(J24+0.3,ProblemData!$C$78:$C$145,0),MATCH(C24,ProblemData!$C$78:$AM$78,0))="Credit",INDEX(ProblemData!$C$78:$AM$145,MATCH(J24+0.2,ProblemData!$C$78:$C$145,0),MATCH(C24,ProblemData!$C$78:$AM$78,0)),""),""),"") | G24: =_xlfn.IFNA(IF(JournalAnswer[[#This Row],[Debit Account]]<>"",INDEX(ProblemData!$C$78:$AM$145,MATCH(J24+0.4,ProblemData!$C$78:$C$145,0),MATCH(C24,ProblemData!$C$78:$AM$78,0)),""),"") -> 18 | H24: =_xlfn.IFNA(IF(JournalAnswer[[#This Row],[Credit Account]]<>"",INDEX(ProblemData!$C$78:$AM$145,MATCH(J24+0.4,ProblemData!$C$78:$C$145,0),MATCH(C24,ProblemData!$C$78:$AM$78,0)),""),"") | I24: {=IF(JournalAnswer[[#This Row],[Debit Account]]="Cash",INDEX(ProblemData!$E$238:$AM$238,1,JournalAnswer[[#This Row],[Transaction '#]]),IF(JournalAnswer[[#This Row],[Credit Account]]="Cash",INDEX(ProblemData!$E$238:$AM$238,1,JournalAnswer[[#This Row],[Transaction '#]]),""))} | J24: =IF(JournalAnswer[[#This Row],[Transaction '#]]="","",IF(JournalAnswer[[#This Row],[Transaction '#]]=C23,J23+1,1)) -> 1 | K24: {=IFERROR(_xlfn.IFS(JournalAnswer[[#This Row],[Debit Account]]="Cash",JournalAnswer[[#This Row],[Dr Amt]],JournalAnswer[[#This Row],[Credit Account]]="Cash",-JournalAnswer[[#This Row],[Cr Amt]]),0)} -> 0 | L24: {=IFERROR(INDEX(ProblemData!$E$239:$AM$239,1,JournalAnswer[[#This Row],[Transaction '#]]),"")} | M24: =IF(JournalAnswer[[#This Row],[ref1]]="","",IF(NOT(ISBLANK(JournalAnswer[[#This Row],[Transaction '#]])),JournalAnswer[[#This Row],[ref1]]&JournalAnswer[[#This Row],[Movement '#]],"")) | N24: =OR(JournalAnswer[[#This Row],[ref1]]="",ISNUMBER(MATCH(JournalAnswer[[#This Row],[ref1]], Operating[Abbr], 0)), "Found", "Not Found"="Found") -> TRUE
... B46: 23 | C46: =IF(B46="","",B46) -> 23 | D46: =IFERROR(_xlfn.IFNA(INDEX(ProblemData!$C$78:$AM$145,MATCH(J46+0.1,ProblemData!$C$78:$C$145,0),MATCH(C46,ProblemData!$C$78:$AM$78,0)),""),"") -> Asset | E46: =IFERROR(_xlfn.IFNA(IF(INDEX(ProblemData!$C$78:$AM$145,MATCH(J46+0.3,ProblemData!$C$78:$C$145,0),MATCH(C46,ProblemData!$C$78:$AM$78,0))="Debit",INDEX(ProblemData!$C$78:$AM$145,MATCH(J46+0.2,ProblemData!$C$78:$C$145,0),MATCH(C46,ProblemData!$C$78:$AM$78,0)),""),""),"") | F46: =IFERROR(_xlfn.IFNA(IF(INDEX(ProblemData!$C$78:$AM$145,MATCH(J46+0.3,ProblemData!$C$78:$C$145,0),MATCH(C46,ProblemData!$C$78:$AM$78,0))="Credit",INDEX(ProblemData!$C$78:$AM$145,MATCH(J46+0.2,ProblemData!$C$78:$C$145,0),MATCH(C46,ProblemData!$C$78:$AM$78,0)),""),""),"") -> Cash | G46: =_xlfn.IFNA(IF(JournalAnswer[[#This Row],[Debit Account]]<>"",INDEX(ProblemData!$C$78:$AM$145,MATCH(J46+0.4,ProblemData!$C$78:$C$145,0),MATCH(C46,ProblemData!$C$78:$AM$78,0)),""),"") | H46: =_xlfn.IFNA(IF(JournalAnswer[[#This Row],[Credit Account]]<>"",INDEX(ProblemData!$C$78:$AM$145,MATCH(J46+0.4,ProblemData!$C$78:$C$145,0),MATCH(C46,ProblemData!$C$78:$AM$78,0)),""),"") -> 2 | I46: {=IF(JournalAnswer[[#This Row],[Debit Account]]="Cash",INDEX(ProblemData!$E$238:$AM$238,1,JournalAnswer[[#This Row],[Transaction '#]]),IF(JournalAnswer[[#This Row],[Credit Account]]="Cash",INDEX(ProblemData!$E$238:$AM$238,1,JournalAnswer[[#This Row],[Transaction '#]]),""))} -> Financing | J46: =IF(JournalAnswer[[#This Row],[Transaction '#]]="","",IF(JournalAnswer[[#This Row],[Transaction '#]]=C45,J45+1,1)) -> 2 | K46: {=IFERROR(_xlfn.IFS(JournalAnswer[[#This Row],[Debit Account]]="Cash",JournalAnswer[[#This Row],[Dr Amt]],JournalAnswer[[#This Row],[Credit Account]]="Cash",-JournalAnswer[[#This Row],[Cr Amt]]),0)} -> -2 | L46: {=IFERROR(INDEX(ProblemData!$E$239:$AM$239,1,JournalAnswer[[#This Row],[Transaction '#]]),"")} | M46: =IF(JournalAnswer[[#This Row],[ref1]]="","",IF(NOT(ISBLANK(JournalAnswer[[#This Row],[Transaction '#]])),JournalAnswer[[#This Row],[ref1]]&JournalAnswer[[#This Row],[Movement '#]],"")) | N46: =OR(JournalAnswer[[#This Row],[ref1]]="",ISNUMBER(MATCH(JournalAnswer[[#This Row],[ref1]], Operating[Abbr], 0)), "Found", "Not Found"="Found") -> TRUE
C47: =IF(B47="","",B47) | D47: =IFERROR(_xlfn.IFNA(INDEX(ProblemData!$C$78:$AM$145,MATCH(J47+0.1,ProblemData!$C$78:$C$145,0),MATCH(C47,ProblemData!$C$78:$AM$78,0)),""),"") | E47: =IFERROR(_xlfn.IFNA(IF(INDEX(ProblemData!$C$78:$AM$145,MATCH(J47+0.3,ProblemData!$C$78:$C$145,0),MATCH(C47,ProblemData!$C$78:$AM$78,0))="Debit",INDEX(ProblemData!$C$78:$AM$145,MATCH(J47+0.2,ProblemData!$C$78:$C$145,0),MATCH(C47,ProblemData!$C$78:$AM$78,0)),""),""),"") | F47: =IFERROR(_xlfn.IFNA(IF(INDEX(ProblemData!$C$78:$AM$145,MATCH(J47+0.3,ProblemData!$C$78:$C$145,0),MATCH(C47,ProblemData!$C$78:$AM$78,0))="Credit",INDEX(ProblemData!$C$78:$AM$145,MATCH(J47+0.2,ProblemData!$C$78:$C$145,0),MATCH(C47,ProblemData!$C$78:$AM$78,0)),""),""),"") | G47: =_xlfn.IFNA(IF(JournalAnswer[[#This Row],[Debit Account]]<>"",INDEX(ProblemData!$C$78:$AM$145,MATCH(J47+0.4,ProblemData!$C$78:$C$145,0),MATCH(C47,ProblemData!$C$78:$AM$78,0)),""),"") | H47: =_xlfn.IFNA(IF(JournalAnswer[[#This Row],[Credit Account]]<>"",INDEX(ProblemData!$C$78:$AM$145,MATCH(J47+0.4,ProblemData!$C$78:$C$145,0),MATCH(C47,ProblemData!$C$78:$AM$78,0)),""),"") | I47: {=IF(JournalAnswer[[#This Row],[Debit Account]]="Cash",INDEX(ProblemData!$E$238:$AM$238,1,JournalAnswer[[#This Row],[Transaction '#]]),IF(JournalAnswer[[#This Row],[Credit Account]]="Cash",INDEX(ProblemData!$E$238:$AM$238,1,JournalAnswer[[#This Row],[Transaction '#]]),""))} | J47: =IF(JournalAnswer[[#This Row],[Transaction '#]]="","",IF(JournalAnswer[[#This Row],[Transaction '#]]=C46,J46+1,1)) | K47: {=IFERROR(_xlfn.IFS(JournalAnswer[[#This Row],[Debit Account]]="Cash",JournalAnswer[[#This Row],[Dr Amt]],JournalAnswer[[#This Row],[Credit Account]]="Cash",-JournalAnswer[[#This Row],[Cr Amt]]),0)} -> 0 | L47: {=IFERROR(INDEX(ProblemData!$E$239:$AM$239,1,JournalAnswer[[#This Row],[Transaction '#]]),"")} | M47: =IF(JournalAnswer[[#This Row],[ref1]]="","",IF(NOT(ISBLANK(JournalAnswer[[#This Row],[Transaction '#]])),JournalAnswer[[#This Row],[ref1]]&JournalAnswer[[#This Row],[Movement '#]],"")) | N47: =OR(JournalAnswer[[#This Row],[ref1]]="",ISNUMBER(MATCH(JournalAnswer[[#This Row],[ref1]], Operating[Abbr], 0)), "Found", "Not Found"="Found") -> TRUE
C48: =IF(B48="","",B48) | D48: =IFERROR(_xlfn.IFNA(INDEX(ProblemData!$C$78:$AM$145,MATCH(J48+0.1,ProblemData!$C$78:$C$145,0),MATCH(C48,ProblemData!$C$78:$AM$78,0)),""),"") | E48: =IFERROR(_xlfn.IFNA(IF(INDEX(ProblemData!$C$78:$AM$145,MATCH(J48+0.3,ProblemData!$C$78:$C$145,0),MATCH(C48,ProblemData!$C$78:$AM$78,0))="Debit",INDEX(ProblemData!$C$78:$AM$145,MATCH(J48+0.2,ProblemData!$C$78:$C$145,0),MATCH(C48,ProblemData!$C$78:$AM$78,0)),""),""),"") | F48: =IFERROR(_xlfn.IFNA(IF(INDEX(ProblemData!$C$78:$AM$145,MATCH(J48+0.3,ProblemData!$C$78:$C$145,0),MATCH(C48,ProblemData!$C$78:$AM$78,0))="Credit",INDEX(ProblemData!$C$78:$AM$145,MATCH(J48+0.2,ProblemData!$C$78:$C$145,0),MATCH(C48,ProblemData!$C$78:$AM$78,0)),""),""),"") | G48: =_xlfn.IFNA(IF(JournalAnswer[[#This Row],[Debit Account]]<>"",INDEX(ProblemData!$C$78:$AM$145,MATCH(J48+0.4,ProblemData!$C$78:$C$145,0),MATCH(C48,ProblemData!$C$78:$AM$78,0)),""),"") | H48: =_xlfn.IFNA(IF(JournalAnswer[[#This Row],[Credit Account]]<>"",INDEX(ProblemData!$C$78:$AM$145,MATCH(J48+0.4,ProblemData!$C$78:$C$145,0),MATCH(C48,ProblemData!$C$78:$AM$78,0)),""),"") | I48: {=IF(JournalAnswer[[#This Row],[Debit Account]]="Cash",INDEX(ProblemData!$E$238:$AM$238,1,JournalAnswer[[#This Row],[Transaction '#]]),IF(JournalAnswer[[#This Row],[Credit Account]]="Cash",INDEX(ProblemData!$E$238:$AM$238,1,JournalAnswer[[#This Row],[Transaction '#]]),""))} | J48: =IF(JournalAnswer[[#This Row],[Transaction '#]]="","",IF(JournalAnswer[[#This Row],[Transaction '#]]=C47,J47+1,1)) | K48: {=IFERROR(_xlfn.IFS(JournalAnswer[[#This Row],[Debit Account]]="Cash",JournalAnswer[[#This Row],[Dr Amt]],JournalAnswer[[#This Row],[Credit Account]]="Cash",-JournalAnswer[[#This Row],[Cr Amt]]),0)} -> 0 | L48: {=IFERROR(INDEX(ProblemData!$E$239:$AM$239,1,JournalAnswer[[#This Row],[Transaction '#]]),"")} | M48: =IF(JournalAnswer[[#This Row],[ref1]]="","",IF(NOT(ISBLANK(JournalAnswer[[#This Row],[Transaction '#]])),JournalAnswer[[#This Row],[ref1]]&JournalAnswer[[#This Row],[Movement '#]],"")) | N48: =OR(JournalAnswer[[#This Row],[ref1]]="",ISNUMBER(MATCH(JournalAnswer[[#This Row],[ref1]], Operating[Abbr], 0)), "Found", "Not Found"="Found") -> TRUE
C49: =IF(B49="","",B49) | D49: =IFERROR(_xlfn.IFNA(INDEX(ProblemData!$C$78:$AM$145,MATCH(J49+0.1,ProblemData!$C$78:$C$145,0),MATCH(C49,ProblemData!$C$78:$AM$78,0)),""),"") | E49: =IFERROR(_xlfn.IFNA(IF(INDEX(ProblemData!$C$78:$AM$145,MATCH(J49+0.3,ProblemData!$C$78:$C$145,0),MATCH(C49,ProblemData!$C$78:$AM$78,0))="Debit",INDEX(ProblemData!$C$78:$AM$145,MATCH(J49+0.2,ProblemData!$C$78:$C$145,0),MATCH(C49,ProblemData!$C$78:$AM$78,0)),""),""),"") | F49: =IFERROR(_xlfn.IFNA(IF(INDEX(ProblemData!$C$78:$AM$145,MATCH(J49+0.3,ProblemData!$C$78:$C$145,0),MATCH(C49,ProblemData!$C$78:$AM$78,0))="Credit",INDEX(ProblemData!$C$78:$AM$145,MATCH(J49+0.2,ProblemData!$C$78:$C$145,0),MATCH(C49,ProblemData!$C$78:$AM$78,0)),""),""),"") | G49: =_xlfn.IFNA(IF(JournalAnswer[[#This Row],[Debit Account]]<>"",INDEX(ProblemData!$C$78:$AM$145,MATCH(J49+0.4,ProblemData!$C$78:$C$145,0),MATCH(C49,ProblemData!$C$78:$AM$78,0)),""),"") | H49: =_xlfn.IFNA(IF(JournalAnswer[[#This Row],[Credit Account]]<>"",INDEX(ProblemData!$C$78:$AM$145,MATCH(J49+0.4,ProblemData!$C$78:$C$145,0),MATCH(C49,ProblemData!$C$78:$AM$78,0)),""),"") | I49: {=IF(JournalAnswer[[#This Row],[Debit Account]]="Cash",INDEX(ProblemData!$E$238:$AM$238,1,JournalAnswer[[#This Row],[Transaction '#]]),IF(JournalAnswer[[#This Row],[Credit Account]]="Cash",INDEX(ProblemData!$E$238:$AM$238,1,JournalAnswer[[#This Row],[Transaction '#]]),""))} | J49: =IF(JournalAnswer[[#This Row],[Transaction '#]]="","",IF(JournalAnswer[[#This Row],[Transaction '#]]=C48,J48+1,1)) | K49: {=IFERROR(_xlfn.IFS(JournalAnswer[[#This Row],[Debit Account]]="Cash",JournalAnswer[[#This Row],[Dr Amt]],JournalAnswer[[#This Row],[Credit Account]]="Cash",-JournalAnswer[[#This Row],[Cr Amt]]),0)} -> 0 | L49: {=IFERROR(INDEX(ProblemData!$E$239:$AM$239,1,JournalAnswer[[#This Row],[Transaction '#]]),"")} | M49: =IF(JournalAnswer[[#This Row],[ref1]]="","",IF(NOT(ISBLANK(JournalAnswer[[#This Row],[Transaction '#]])),JournalAnswer[[#This Row],[ref1]]&JournalAnswer[[#This Row],[Movement '#]],"")) | N49: =OR(JournalAnswer[[#This Row],[ref1]]="",ISNUMBER(MATCH(JournalAnswer[[#This Row],[ref1]], Operating[Abbr], 0)), "Found", "Not Found"="Found") -> TRUE
C50: =IF(B50="","",B50) | D50: =IFERROR(_xlfn.IFNA(INDEX(ProblemData!$C$78:$AM$145,MATCH(J50+0.1,ProblemData!$C$78:$C$145,0),MATCH(C50,ProblemData!$C$78:$AM$78,0)),""),"") | E50: =IFERROR(_xlfn.IFNA(IF(INDEX(ProblemData!$C$78:$AM$145,MATCH(J50+0.3,ProblemData!$C$78:$C$145,0),MATCH(C50,ProblemData!$C$78:$AM$78,0))="Debit",INDEX(ProblemData!$C$78:$AM$145,MATCH(J50+0.2,ProblemData!$C$78:$C$145,0),MATCH(C50,ProblemData!$C$78:$AM$78,0)),""),""),"") | F50: =IFERROR(_xlfn.IFNA(IF(INDEX(ProblemData!$C$78:$AM$145,MATCH(J50+0.3,ProblemData!$C$78:$C$145,0),MATCH(C50,ProblemData!$C$78:$AM$78,0))="Credit",INDEX(ProblemData!$C$78:$AM$145,MATCH(J50+0.2,ProblemData!$C$78:$C$145,0),MATCH(C50,ProblemData!$C$78:$AM$78,0)),""),""),"") | G50: =_xlfn.IFNA(IF(JournalAnswer[[#This Row],[Debit Account]]<>"",INDEX(ProblemData!$C$78:$AM$145,MATCH(J50+0.4,ProblemData!$C$78:$C$145,0),MATCH(C50,ProblemData!$C$78:$AM$78,0)),""),"") | H50: =_xlfn.IFNA(IF(JournalAnswer[[#This Row],[Credit Account]]<>"",INDEX(ProblemData!$C$78:$AM$145,MATCH(J50+0.4,ProblemData!$C$78:$C$145,0),MATCH(C50,ProblemData!$C$78:$AM$78,0)),""),"") | I50: {=IF(JournalAnswer[[#This Row],[Debit Account]]="Cash",INDEX(ProblemData!$E$238:$AM$238,1,JournalAnswer[[#This Row],[Transaction '#]]),IF(JournalAnswer[[#This Row],[Credit Account]]="Cash",INDEX(ProblemData!$E$238:$AM$238,1,JournalAnswer[[#This Row],[Transaction '#]]),""))} | J50: =IF(JournalAnswer[[#This Row],[Transaction '#]]="","",IF(JournalAnswer[[#This Row],[Transaction '#]]=C49,J49+1,1)) | K50: {=IFERROR(_xlfn.IFS(JournalAnswer[[#This Row],[Debit Account]]="Cash",JournalAnswer[[#This Row],[Dr Amt]],JournalAnswer[[#This Row],[Credit Account]]="Cash",-JournalAnswer[[#This Row],[Cr Amt]]),0)} -> 0 | L50: {=IFERROR(INDEX(ProblemData!$E$239:$AM$239,1,JournalAnswer[[#This Row],[Transaction '#]]),"")} | M50: =IF(JournalAnswer[[#This Row],[ref1]]="","",IF(NOT(ISBLANK(JournalAnswer[[#This Row],[Transaction '#]])),JournalAnswer[[#This Row],[ref1]]&JournalAnswer[[#This Row],[Movement '#]],"")) | N50: =OR(JournalAnswer[[#This Row],[ref1]]="",ISNUMBER(MATCH(JournalAnswer[[#This Row],[ref1]], Operating[Abbr], 0)), "Found", "Not Found"="Found") -> TRUE
C51: =IF(B51="","",B51) | D51: =IFERROR(_xlfn.IFNA(INDEX(ProblemData!$C$78:$AM$145,MATCH(J51+0.1,ProblemData!$C$78:$C$145,0),MATCH(C51,ProblemData!$C$78:$AM$78,0)),""),"") | E51: =IFERROR(_xlfn.IFNA(IF(INDEX(ProblemData!$C$78:$AM$145,MATCH(J51+0.3,ProblemData!$C$78:$C$145,0),MATCH(C51,ProblemData!$C$78:$AM$78,0))="Debit",INDEX(ProblemData!$C$78:$AM$145,MATCH(J51+0.2,ProblemData!$C$78:$C$145,0),MATCH(C51,ProblemData!$C$78:$AM$78,0)),""),""),"") | F51: =IFERROR(_xlfn.IFNA(IF(INDEX(ProblemData!$C$78:$AM$145,MATCH(J51+0.3,ProblemData!$C$78:$C$145,0),MATCH(C51,ProblemData!$C$78:$AM$78,0))="Credit",INDEX(ProblemData!$C$78:$AM$145,MATCH(J51+0.2,ProblemData!$C$78:$C$145,0),MATCH(C51,ProblemData!$C$78:$AM$78,0)),""),""),"") | G51: =_xlfn.IFNA(IF(JournalAnswer[[#This Row],[Debit Account]]<>"",INDEX(ProblemData!$C$78:$AM$145,MATCH(J51+0.4,ProblemData!$C$78:$C$145,0),MATCH(C51,ProblemData!$C$78:$AM$78,0)),""),"") | H51: =_xlfn.IFNA(IF(JournalAnswer[[#This Row],[Credit Account]]<>"",INDEX(ProblemData!$C$78:$AM$145,MATCH(J51+0.4,ProblemData!$C$78:$C$145,0),MATCH(C51,ProblemData!$C$78:$AM$78,0)),""),"") | I51: {=IF(JournalAnswer[[#This Row],[Debit Account]]="Cash",INDEX(ProblemData!$E$238:$AM$238,1,JournalAnswer[[#This Row],[Transaction '#]]),IF(JournalAnswer[[#This Row],[Credit Account]]="Cash",INDEX(ProblemData!$E$238:$AM$238,1,JournalAnswer[[#This Row],[Transaction '#]]),""))} | J51: =IF(JournalAnswer[[#This Row],[Transaction '#]]="","",IF(JournalAnswer[[#This Row],[Transaction '#]]=C50,J50+1,1)) | K51: {=IFERROR(_xlfn.IFS(JournalAnswer[[#This Row],[Debit Account]]="Cash",JournalAnswer[[#This Row],[Dr Amt]],JournalAnswer[[#This Row],[Credit Account]]="Cash",-JournalAnswer[[#This Row],[Cr Amt]]),0)} -> 0 | L51: {=IFERROR(INDEX(ProblemData!$E$239:$AM$239,1,JournalAnswer[[#This Row],[Transaction '#]]),"")} | M51: =IF(JournalAnswer[[#This Row],[ref1]]="","",IF(NOT(ISBLANK(JournalAnswer[[#This Row],[Transaction '#]])),JournalAnswer[[#This Row],[ref1]]&JournalAnswer[[#This Row],[Movement '#]],"")) | N51: =OR(JournalAnswer[[#This Row],[ref1]]="",ISNUMBER(MATCH(JournalAnswer[[#This Row],[ref1]], Operating[Abbr], 0)), "Found", "Not Found"="Found") -> TRUE
C52: =IF(B52="","",B52) | D52: =IFERROR(_xlfn.IFNA(INDEX(ProblemData!$C$78:$AM$145,MATCH(J52+0.1,ProblemData!$C$78:$C$145,0),MATCH(C52,ProblemData!$C$78:$AM$78,0)),""),"") | E52: =IFERROR(_xlfn.IFNA(IF(INDEX(ProblemData!$C$78:$AM$145,MATCH(J52+0.3,ProblemData!$C$78:$C$145,0),MATCH(C52,ProblemData!$C$78:$AM$78,0))="Debit",INDEX(ProblemData!$C$78:$AM$145,MATCH(J52+0.2,ProblemData!$C$78:$C$145,0),MATCH(C52,ProblemData!$C$78:$AM$78,0)),""),""),"") | F52: =IFERROR(_xlfn.IFNA(IF(INDEX(ProblemData!$C$78:$AM$145,MATCH(J52+0.3,ProblemData!$C$78:$C$145,0),MATCH(C52,ProblemData!$C$78:$AM$78,0))="Credit",INDEX(ProblemData!$C$78:$AM$145,MATCH(J52+0.2,ProblemData!$C$78:$C$145,0),MATCH(C52,ProblemData!$C$78:$AM$78,0)),""),""),"") | G52: =_xlfn.IFNA(IF(JournalAnswer[[#This Row],[Debit Account]]<>"",INDEX(ProblemData!$C$78:$AM$145,MATCH(J52+0.4,ProblemData!$C$78:$C$145,0),MATCH(C52,ProblemData!$C$78:$AM$78,0)),""),"") | H52: =_xlfn.IFNA(IF(JournalAnswer[[#This Row],[Credit Account]]<>"",INDEX(ProblemData!$C$78:$AM$145,MATCH(J52+0.4,ProblemData!$C$78:$C$145,0),MATCH(C52,ProblemData!$C$78:$AM$78,0)),""),"") | I52: {=IF(JournalAnswer[[#This Row],[Debit Account]]="Cash",INDEX(ProblemData!$E$238:$AM$238,1,JournalAnswer[[#This Row],[Transaction '#]]),IF(JournalAnswer[[#This Row],[Credit Account]]="Cash",INDEX(ProblemData!$E$238:$AM$238,1,JournalAnswer[[#This Row],[Transaction '#]]),""))} | J52: =IF(JournalAnswer[[#This Row],[Transaction '#]]="","",IF(JournalAnswer[[#This Row],[Transaction '#]]=C51,J51+1,1)) | K52: {=IFERROR(_xlfn.IFS(JournalAnswer[[#This Row],[Debit Account]]="Cash",JournalAnswer[[#This Row],[Dr Amt]],JournalAnswer[[#This Row],[Credit Account]]="Cash",-JournalAnswer[[#This Row],[Cr Amt]]),0)} -> 0 | L52: {=IFERROR(INDEX(ProblemData!$E$239:$AM$239,1,JournalAnswer[[#This Row],[Transaction '#]]),"")} | M52: =IF(JournalAnswer[[#This Row],[ref1]]="","",IF(NOT(ISBLANK(JournalAnswer[[#This Row],[Transaction '#]])),JournalAnswer[[#This Row],[ref1]]&JournalAnswer[[#This Row],[Movement '#]],"")) | N52: =OR(JournalAnswer[[#This Row],[ref1]]="",ISNUMBER(MATCH(JournalAnswer[[#This Row],[ref1]], Operating[Abbr], 0)), "Found", "Not Found"="Found") -> TRUE
C53: =IF(B53="","",B53) | D53: =IFERROR(_xlfn.IFNA(INDEX(ProblemData!$C$78:$AM$145,MATCH(J53+0.1,ProblemData!$C$78:$C$145,0),MATCH(C53,ProblemData!$C$78:$AM$78,0)),""),"") | E53: =IFERROR(_xlfn.IFNA(IF(INDEX(ProblemData!$C$78:$AM$145,MATCH(J53+0.3,ProblemData!$C$78:$C$145,0),MATCH(C53,ProblemData!$C$78:$AM$78,0))="Debit",INDEX(ProblemData!$C$78:$AM$145,MATCH(J53+0.2,ProblemData!$C$78:$C$145,0),MATCH(C53,ProblemData!$C$78:$AM$78,0)),""),""),"") | F53: =IFERROR(_xlfn.IFNA(IF(INDEX(ProblemData!$C$78:$AM$145,MATCH(J53+0.3,ProblemData!$C$78:$C$145,0),MATCH(C53,ProblemData!$C$78:$AM$78,0))="Credit",INDEX(ProblemData!$C$78:$AM$145,MATCH(J53+0.2,ProblemData!$C$78:$C$145,0),MATCH(C53,ProblemData!$C$78:$AM$78,0)),""),""),"") | G53: =_xlfn.IFNA(IF(JournalAnswer[[#This Row],[Debit Account]]<>"",INDEX(ProblemData!$C$78:$AM$145,MATCH(J53+0.4,ProblemData!$C$78:$C$145,0),MATCH(C53,ProblemData!$C$78:$AM$78,0)),""),"") | H53: =_xlfn.IFNA(IF(JournalAnswer[[#This Row],[Credit Account]]<>"",INDEX(ProblemData!$C$78:$AM$145,MATCH(J53+0.4,ProblemData!$C$78:$C$145,0),MATCH(C53,ProblemData!$C$78:$AM$78,0)),""),"") | I53: {=IF(JournalAnswer[[#This Row],[Debit Account]]="Cash",INDEX(ProblemData!$E$238:$AM$238,1,JournalAnswer[[#This Row],[Transaction '#]]),IF(JournalAnswer[[#This Row],[Credit Account]]="Cash",INDEX(ProblemData!$E$238:$AM$238,1,JournalAnswer[[#This Row],[Transaction '#]]),""))} | J53: =IF(JournalAnswer[[#This Row],[Transaction '#]]="","",IF(JournalAnswer[[#This Row],[Transaction '#]]=C52,J52+1,1)) | K53: {=IFERROR(_xlfn.IFS(JournalAnswer[[#This Row],[Debit Account]]="Cash",JournalAnswer[[#This Row],[Dr Amt]],JournalAnswer[[#This Row],[Credit Account]]="Cash",-JournalAnswer[[#This Row],[Cr Amt]]),0)} -> 0 | L53: {=IFERROR(INDEX(ProblemData!$E$239:$AM$239,1,JournalAnswer[[#This Row],[Transaction '#]]),"")} | M53: =IF(JournalAnswer[[#This Row],[ref1]]="","",IF(NOT(ISBLANK(JournalAnswer[[#This Row],[Transaction '#]])),JournalAnswer[[#This Row],[ref1]]&JournalAnswer[[#This Row],[Movement '#]],"")) | N53: =OR(JournalAnswer[[#This Row],[ref1]]="",ISNUMBER(MATCH(JournalAnswer[[#This Row],[ref1]], Operating[Abbr], 0)), "Found", "Not Found"="Found") -> TRUE
