Workbook

Sheet Instructions

Sheet Cash Flow Maps
A1: Coupon Bond | B1: TRUE | C1: check your answer
A3: Face Value | B3: 5000
A4: Coupon Rate | B4: 0.07 | C4: per period
A5: Life | B5: 6 | C5: periods
B6: End of Period
B7: 0 | C7: 1 | D7: 2 | E7: 3 | F7: 4 | G7: 5 | H7: 6 | I7: 7 | J7: 8 | K7: 9 | L7: 10
A8: Coupon Payments | C8: =$B$4*$B$3 -> 350 | D8: =$B$4*$B$3 -> 350 | E8: =$B$4*$B$3 -> 350 | F8: =$B$4*$B$3 -> 350 | G8: =$B$4*$B$3 -> 350 | H8: =$B$4*$B$3 -> 350
A9: Face Payment | H9: 5000
A10: Total | B10: =SUM(B8:B9) -> 0 | C10: =SUM(C8:C9) -> 350 | D10: =SUM(D8:D9) -> 350 | E10: =SUM(E8:E9) -> 350 | F10: =SUM(F8:F9) -> 350 | G10: =SUM(G8:G9) -> 350 | H10: =SUM(H8:H9) -> 5350 | I10: =SUM(I8:I9) -> 0 | ... L10: =SUM(L8:L9) -> 0
A12: Zero Coupon Bond | B12: FALSE | C12: check your answer
A14: Face Value | B14: 10000
A15: Coupon Rate | B15: 0 | C15: per period
A16: Life | B16: 9 | C16: periods
B18: End of Period
B19: 0 | C19: 1 | D19: 2 | E19: 3 | F19: 4 | G19: 5 | H19: 6 | I19: 7 | J19: 8 | K19: 9 | L19: 10
A20: Coupon Payments | K20: 0
A21: Face Payment | K21: 10000
A22: Total | B22: =SUM(B20:B21) -> 0 | C22: =SUM(C20:C21) -> 0 | D22: =SUM(D20:D21) -> 0 | E22: =SUM(E20:E21) -> 0 | F22: =SUM(F20:F21) -> 0 | G22: =SUM(G20:G21) -> 0 | H22: =SUM(H20:H21) -> 0 | I22: =SUM(I20:I21) -> 0 | ... L22: =SUM(L20:L21) -> 0
A24: Annuity in Arrears | B24: FALSE | C24: check your answer
A26: Amount | B26: 500 | C26: per period
A27: Life | B27: 7
B29: End of Period
B30: 0 | C30: 1 | D30: 2 | E30: 3 | F30: 4 | G30: 5 | H30: 6 | I30: 7 | J30: 8 | K30: 9 | L30: 10
A31: Total | C31: 500 | D31: 500 | E31: 500 | F31: 500 | G31: 500 | H31: 500 | I31: 500
A34: Annuity in Advance | B34: FALSE | C34: check your answer
A36: Amount | B36: 600 | C36: per period
A37: Life | B37: 5 | C37: periods
B39: End of Period
B40: 0 | C40: 1 | D40: 2 | E40: 3 | F40: 4 | G40: 5 | H40: 6 | I40: 7 | J40: 8 | K40: 9 | L40: 10

Sheet CFMA
A1: Coupon Bond
A3: Face Value | B3: 5000
A4: Coupon Rate | B4: 0.07 | C4: per period
A5: Life | B5: 6 | C5: periods
B6: End of Period
B7: 0 | C7: 1 | D7: 2 | E7: 3 | F7: 4 | G7: 5 | H7: 6 | I7: 7 | J7: 8 | K7: 9 | L7: 10
A8: Coupon Payments | C8: =$B$3*$B$4 -> 350 | D8: =$B$3*$B$4 -> 350 | E8: =$B$3*$B$4 -> 350 | F8: =$B$3*$B$4 -> 350 | G8: =$B$3*$B$4 -> 350 | H8: =$B$3*$B$4 -> 350
A9: Face Payment | H9: =$B$3 -> 5000
A10: Total | B10: =SUM(B8:B9) -> 0 | C10: =SUM(C8:C9) -> 350 | D10: =SUM(D8:D9) -> 350 | E10: =SUM(E8:E9) -> 350 | F10: =SUM(F8:F9) -> 350 | G10: =SUM(G8:G9) -> 350 | H10: =SUM(H8:H9) -> 5350 | I10: =SUM(I8:I9) -> 0 | ... L10: =SUM(L8:L9) -> 0
A12: Zero Coupon Bond
A14: Face Value | B14: 10000
A15: Coupon Rate | B15: 0 | C15: per period
A16: Life | B16: 9 | C16: periods
B18: End of Period
B19: 0 | C19: 1 | D19: 2 | E19: 3 | F19: 4 | G19: 5 | H19: 6 | I19: 7 | J19: 8 | K19: 9 | L19: 10
A20: Coupon Payments | C20: =$B$14*$B$15 -> 0 | D20: =$B$14*$B$15 -> 0 | E20: =$B$14*$B$15 -> 0 | F20: =$B$14*$B$15 -> 0 | G20: =$B$14*$B$15 -> 0 | H20: =$B$14*$B$15 -> 0 | I20: =$B$14*$B$15 -> 0 | J20: =$B$14*$B$15 -> 0 | K20: =$B$14*$B$15 -> 0
A21: Face Payment | K21: =$B$14 -> 10000
A22: Total | B22: =SUM(B20:B21) -> 0 | C22: =SUM(C20:C21) -> 0 | D22: =SUM(D20:D21) -> 0 | E22: =SUM(E20:E21) -> 0 | F22: =SUM(F20:F21) -> 0 | G22: =SUM(G20:G21) -> 0 | H22: =SUM(H20:H21) -> 0 | I22: =SUM(I20:I21) -> 0 | ... L22: =SUM(L20:L21) -> 0
A24: Annuity in Arrears
A26: Amount | B26: 500 | C26: per period
A27: Life | B27: 7
B29: End of Period
B30: 0 | C30: 1 | D30: 2 | E30: 3 | F30: 4 | G30: 5 | H30: 6 | I30: 7 | J30: 8 | K30: 9 | L30: 10
A31: Total | C31: =$B$26 -> 500 | D31: =$B$26 -> 500 | E31: =$B$26 -> 500 | F31: =$B$26 -> 500 | G31: =$B$26 -> 500 | H31: =$B$26 -> 500 | I31: =$B$26 -> 500 | J31: 0 | K31: 0 | L31: 0
A34: Annuity in Advance
A36: Amount | B36: 600 | C36: per period
A37: Life | B37: 5 | C37: periods
B39: End of Period
B40: 0 | C40: 1 | D40: 2 | E40: 3 | F40: 4 | G40: 5 | H40: 6 | I40: 7 | J40: 8 | K40: 9 | L40: 10
B41: =$B$36 -> 600 | C41: =$B$36 -> 600 | D41: =$B$36 -> 600 | E41: =$B$36 -> 600 | F41: =$B$36 -> 600 | G41: 0 | H41: 0 | I41: 0 | J41: 0 | K41: 0 | L41: 0

Sheet Discounting
A1: Coupon Bond | B1: TRUE | C1: check your answer
A3: Face Value | B3: =CFMA!B3 -> 5000
A4: Coupon Rate | B4: =CFMA!B4 -> 0.07 | C4: per period
A5: Life | B5: =CFMA!B5 -> 6 | C5: periods
B6: End of Period
B7: 0 | C7: 1 | D7: 2 | E7: 3 | F7: 4 | G7: 5 | H7: 6 | I7: 7 | J7: 8 | K7: 9 | L7: 10
A8: Total | B8: ='Cash Flow Maps'!B10 -> 0 | C8: ='Cash Flow Maps'!C10 -> 350 | D8: ='Cash Flow Maps'!D10 -> 350 | E8: ='Cash Flow Maps'!E10 -> 350 | F8: ='Cash Flow Maps'!F10 -> 350 | G8: ='Cash Flow Maps'!G10 -> 350 | H8: ='Cash Flow Maps'!H10 -> 5350 | I8: ='Cash Flow Maps'!I10 -> 0 | ... L8: ='Cash Flow Maps'!L10 -> 0
A10: Interest Rate | B10: 0.07
B12: Value at Time 0 of Cash Flow at End of Period
B13: 0 | C13: 1 | D13: 2 | E13: 3 | F13: 4 | G13: 5 | H13: 6 | I13: 7 | J13: 8 | K13: 9 | L13: 10
C14: =C8/(1+$B$10)^C13 -> 327.1028 | D14: =D8/(1+$B$10)^D13 -> 305.70355 | E14: =E8/(1+$B$10)^E13 -> 285.70426 | F14: =F8/(1+$B$10)^F13 -> 267.01332 | G14: =G8/(1+$B$10)^G13 -> 249.54516 | H14: =H8/(1+$B$10)^H13 -> 3564.9309
A15: Total Present Value | B15: =SUM(B14:L14) -> 5000
A17: Zero Coupon Bond | B17: TRUE | C17: check your answer
A19: Face Value | B19: =CFMA!B14 -> 10000
A20: Coupon Rate | B20: =CFMA!B15 -> 0 | C20: per period
A21: Life | B21: =CFMA!B16 -> 9 | C21: periods
B23: End of Period
B24: 0 | C24: 1 | D24: 2 | E24: 3 | F24: 4 | G24: 5 | H24: 6 | I24: 7 | J24: 8 | K24: 9 | L24: 10
A25: Total | B25: ='Cash Flow Maps'!B22 -> 0 | C25: ='Cash Flow Maps'!C22 -> 0 | D25: ='Cash Flow Maps'!D22 -> 0 | E25: ='Cash Flow Maps'!E22 -> 0 | F25: ='Cash Flow Maps'!F22 -> 0 | G25: ='Cash Flow Maps'!G22 -> 0 | H25: ='Cash Flow Maps'!H22 -> 0 | I25: ='Cash Flow Maps'!I22 -> 0 | ... L25: ='Cash Flow Maps'!L22 -> 0
A27: Interest Rate | B27: 0.04
B29: Value at Time 0 of Cash Flow at End of Period
B30: 0 | C30: 1 | D30: 2 | E30: 3 | F30: 4 | G30: 5 | H30: 6 | I30: 7 | J30: 8 | K30: 9 | L30: 10
K31: =K25/(1+$B$27)^K30 -> 7025.8674
A32: Total Present Value | B32: =SUM(B31:L31) -> 7025.8674
A34: Annuity in Arrears | B34: FALSE | C34: check your answer
A36: Amount | B36: =CFMA!B26 -> 500 | C36: per period
A37: Life | B37: =CFMA!B27 -> 7 | C37: periods
B39: End of Period
B40: 0 | C40: 1 | D40: 2 | E40: 3 | F40: 4 | G40: 5 | H40: 6 | I40: 7 | J40: 8 | K40: 9 | L40: 10
A41: Total | B41: ='Cash Flow Maps'!B31 -> 0 | C41: ='Cash Flow Maps'!C31 -> 500 | D41: ='Cash Flow Maps'!D31 -> 500 | E41: ='Cash Flow Maps'!E31 -> 500 | F41: ='Cash Flow Maps'!F31 -> 500 | G41: ='Cash Flow Maps'!G31 -> 500 | H41: ='Cash Flow Maps'!H31 -> 500 | I41: ='Cash Flow Maps'!I31 -> 500 | ... L41: ='Cash Flow Maps'!L31 -> 0
A43: Interest Rate | B43: 0.06
B45: Value at Time 0 of Cash Flow at End of Period
B46: 0 | C46: 1 | D46: 2 | E46: 3 | F46: 4 | G46: 5 | H46: 6 | I46: 7 | J46: 8 | K46: 9 | L46: 10
A48: Total Present Value | B48: =SUM(B47:L47) -> 0
A50: Annuity in Advance | B50: FALSE | C50: check your answer
A52: Amount | B52: =CFMA!B36 -> 600 | C52: per period
A53: Life | B53: =CFMA!B37 -> 5 | C53: periods
B55: End of Period
B56: 0 | C56: 1 | D56: 2 | E56: 3 | F56: 4 | G56: 5 | H56: 6 | I56: 7 | J56: 8 | K56: 9 | L56: 10
B57: ='Cash Flow Maps'!B41 -> 0 | C57: ='Cash Flow Maps'!C41 -> 0 | D57: ='Cash Flow Maps'!D41 -> 0 | E57: ='Cash Flow Maps'!E41 -> 0 | F57: ='Cash Flow Maps'!F41 -> 0 | G57: ='Cash Flow Maps'!G41 -> 0 | H57: ='Cash Flow Maps'!H41 -> 0 | I57: ='Cash Flow Maps'!I41 -> 0 | ... L57: ='Cash Flow Maps'!L41 -> 0
...

Sheet DA
A1: Coupon Bond
A3: Face Value | B3: =CFMA!B3 -> 5000
A4: Coupon Rate | B4: =CFMA!B4 -> 0.07 | C4: per period
A5: Life | B5: =CFMA!B5 -> 6 | C5: periods
B6: End of Period
B7: 0 | C7: 1 | D7: 2 | E7: 3 | F7: 4 | G7: 5 | H7: 6 | I7: 7 | J7: 8 | K7: 9 | L7: 10
A8: Total | B8: =CFMA!B10 -> 0 | C8: =CFMA!C10 -> 350 | D8: =CFMA!D10 -> 350 | E8: =CFMA!E10 -> 350 | F8: =CFMA!F10 -> 350 | G8: =CFMA!G10 -> 350 | H8: =CFMA!H10 -> 5350 | I8: =CFMA!I10 -> 0 | ... L8: =CFMA!L10 -> 0
A10: Interest Rate | B10: 0.08
B12: Value at Time 0 of Cash Flow at End of Period
B13: 0 | C13: 1 | D13: 2 | E13: 3 | F13: 4 | G13: 5 | H13: 6 | I13: 7 | J13: 8 | K13: 9 | L13: 10
C14: =C8/(1+$B$10)^C13 -> 324.07407 | D14: =D8/(1+$B$10)^D13 -> 300.06859 | E14: =E8/(1+$B$10)^E13 -> 277.84128 | F14: =F8/(1+$B$10)^F13 -> 257.26045 | G14: =G8/(1+$B$10)^G13 -> 238.20412 | H14: =H8/(1+$B$10)^H13 -> 3371.4075
A15: Total Present Value | B15: =SUM(B14:L14) -> 4768.856
A17: Zero Coupon Bond
A19: Face Value | B19: =CFMA!B14 -> 10000
A20: Coupon Rate | B20: =CFMA!B15 -> 0 | C20: per period
A21: Life | B21: =CFMA!B16 -> 9 | C21: periods
B23: End of Period
B24: 0 | C24: 1 | D24: 2 | E24: 3 | F24: 4 | G24: 5 | H24: 6 | I24: 7 | J24: 8 | K24: 9 | L24: 10
A25: Total | B25: =CFMA!B22 -> 0 | C25: =CFMA!C22 -> 0 | D25: =CFMA!D22 -> 0 | E25: =CFMA!E22 -> 0 | F25: =CFMA!F22 -> 0 | G25: =CFMA!G22 -> 0 | H25: =CFMA!H22 -> 0 | I25: =CFMA!I22 -> 0 | ... L25: =CFMA!L22 -> 0
A27: Interest Rate | B27: 0.04
B29: Value at Time 0 of Cash Flow at End of Period
B30: 0 | C30: 1 | D30: 2 | E30: 3 | F30: 4 | G30: 5 | H30: 6 | I30: 7 | J30: 8 | K30: 9 | L30: 10
K31: =K25/(1+$B$27)^K30 -> 7025.8674
A32: Total Present Value | B32: =SUM(B31:L31) -> 7025.8674
A34: Annuity in Arrears
A36: Amount | B36: =CFMA!B26 -> 500 | C36: per period
A37: Life | B37: =CFMA!B27 -> 7 | C37: periods
B39: End of Period
B40: 0 | C40: 1 | D40: 2 | E40: 3 | F40: 4 | G40: 5 | H40: 6 | I40: 7 | J40: 8 | K40: 9 | L40: 10
A41: Total | B41: =CFMA!B31 -> 0 | C41: =CFMA!C31 -> 500 | D41: =CFMA!D31 -> 500 | E41: =CFMA!E31 -> 500 | F41: =CFMA!F31 -> 500 | G41: =CFMA!G31 -> 500 | H41: =CFMA!H31 -> 500 | I41: =CFMA!I31 -> 500 | ... L41: =CFMA!L31 -> 0
A43: Interest Rate | B43: 0.06
B45: Value at Time 0 of Cash Flow at End of Period
B46: 0 | C46: 1 | D46: 2 | E46: 3 | F46: 4 | G46: 5 | H46: 6 | I46: 7 | J46: 8 | K46: 9 | L46: 10
C47: =C41/(1+$B$43)^C46 -> 471.69811 | D47: =D41/(1+$B$43)^D46 -> 444.99822 | E47: =E41/(1+$B$43)^E46 -> 419.80964 | F47: =F41/(1+$B$43)^F46 -> 396.04683 | G47: =G41/(1+$B$43)^G46 -> 373.62909 | H47: =H41/(1+$B$43)^H46 -> 352.48027 | I47: =I41/(1+$B$43)^I46 -> 332.52856
A48: Total Present Value | B48: =SUM(B47:L47) -> 2791.1907
A50: Annuity in Advance
A52: Amount | B52: =CFMA!B36 -> 600 | C52: per period
A53: Life | B53: =CFMA!B37 -> 5 | C53: periods
B55: End of Period
B56: 0 | C56: 1 | D56: 2 | E56: 3 | F56: 4 | G56: 5 | H56: 6 | I56: 7 | J56: 8 | K56: 9 | L56: 10
...
