Workbook
Name AccountTypesUsed: _xlfn.ANCHORARRAY([1]MasterData!$L$5)
Name AccountTypesUsed: _xlfn.ANCHORARRAY(MasterData!$L$5)
Name AssetUsed: _xlfn.ANCHORARRAY([1]MasterData!$L$56)
Name AssetUsed: _xlfn.ANCHORARRAY(MasterData!$L$56)
Name BB_Inbalance: Financial_Statements_Builder!$E$559
Name BegDate: [1]ProblemData!$E$64
Name BegDate: ProblemData!$E$64
Name Begin: MasterData!$F$684:$F$703
Name Begin: MasterData!$F$684:$F$703
Name CFO_NI_Recon_NI: FSConstruction!$BA$7:$BE$7
Name DeprMethod: ProblemData!$E$72
Name End: MasterData!$G$684:$G$703
Name End: MasterData!$G$684:$G$703
Name EndDate: [1]ProblemData!$E$65
Name EndDate: ProblemData!$E$65
Name Entity: [1]ProblemData!$E$61
Name Entity: ProblemData!$E$61
Name EntityActivity: [1]ProblemData!$E$63
Name EntityActivity: ProblemData!$E$63
Name EntityType: [1]ProblemData!$E$62
Name EntityType: ProblemData!$E$62
Name EquityUsed: _xlfn.ANCHORARRAY([1]MasterData!$L$116)
Name EquityUsed: _xlfn.ANCHORARRAY(MasterData!$L$116)
Name ExpenseUsed: _xlfn.ANCHORARRAY([1]MasterData!$L$149)
Name ExpenseUsed: _xlfn.ANCHORARRAY(MasterData!$L$149)
Name FS_IssueDate: ProblemData!$E$66
Name FSBuilderAccnts: [1]MasterData!$X$56:$X$90
Name FSBuilderAccnts: MasterData!$X$71:$X$90
Name GainUsed: _xlfn.ANCHORARRAY([1]MasterData!$L$171)
Name GainUsed: _xlfn.ANCHORARRAY(MasterData!$L$171)
Name InventoryMethod: [1]ProblemData!$E$73
Name InventoryMethod: ProblemData!$E$73
Name Issue_Date: [1]ProblemData!$E$66
Name Issue_Date: ProblemData!$E$66
Name LiabilityUsed: _xlfn.ANCHORARRAY([1]MasterData!$L$83)
Name LiabilityUsed: _xlfn.ANCHORARRAY(MasterData!$L$83)
Name LossUsed: _xlfn.ANCHORARRAY([1]MasterData!$L$185)
Name LossUsed: _xlfn.ANCHORARRAY(MasterData!$L$185)
Name Net_Income: FSConstruction!$L$54
Name ParValue: ProblemData!$E$70
Name Period: [1]ProblemData!$E$67
Name Period: ProblemData!$E$67
Name PurposesUsed: _xlfn.ANCHORARRAY([1]MasterData!$F$515)
Name PurposesUsed: _xlfn.ANCHORARRAY(MasterData!$F$515)
Name RevenueUsed: _xlfn.ANCHORARRAY([1]MasterData!$L$135)
Name RevenueUsed: _xlfn.ANCHORARRAY(MasterData!$L$135)
Name RevRec: [1]ProblemData!$E$74
Name RevRec: ProblemData!$E$74
Name ShrsOut: ProblemData!$E$69
Name TreasShrs: ProblemData!$E$71
Name Units: [1]ProblemData!$E$68
Name Units: ProblemData!$E$68
Name ZZZ: FSConstruction!$BA$7:$BE$7

Sheet Instructions
B2: Basic Information
B3: Entity
B4: Entity: | C4: =IF(ProblemData!E61="","",ProblemData!E61) -> Miloslav's Magazines
B5: Type: | C5: =IF(ProblemData!E62="","",ProblemData!E62) -> For-profit corporation
B6: Activity: | C6: =IF(ProblemData!E63="","",ProblemData!E63) -> Retail
B7: Dates and Period
B8: Period Beginning: | C8: =IF(ProblemData!E64="","",ProblemData!E64) -> 12/31/20x3
B9: Period Ending: | C9: =IF(ProblemData!E65="","",ProblemData!E65) -> 12/31/20x4
B10: Period Length: | C10: =IF(ProblemData!E67="","",ProblemData!E67) -> Year
B11: Units and Shares
B12: Units: | C12: =IF(ProblemData!E68="","",ProblemData!E68) -> Dollars in Thousands
B13: Shares Outstanding: | C13: =IF(ProblemData!E69="","",ProblemData!E69) -> 0
B14: Par Value per Share: | C14: =IF(ProblemData!E70="","",ProblemData!E70) -> 0
B18: Requirements:
B19: Number | C19: Action: | D19: Item: | G19: Completed? | H19: Location:
B20: #1 | C20: {=_xlfn._xlws.FILTER(RequirementsChosen[Action],RequirementsChosen[Action]<>"Omit")} -> Review | D20: {=_xlfn._xlws.FILTER(RequirementsChosen[Item],RequirementsChosen[Action]<>"Omit")} -> Chart of Accounts | G20: TRUE | H20: {=_xlfn._xlws.FILTER(RequirementsChosen[Tab],RequirementsChosen[Action]<>"Omit")} -> Instructions
B21: #2 | C21: Review | D21: Notes to the Financial Statements | G21: TRUE | H21: Notes_to_FSs
B22: #3 | C22: Prepare | D22: Beginning Balance Sheet | G22: TRUE | H22: Financial_Statements_Builder
B23: #4 | C23: Prepare | D23: Journal entries for transactions and events of the period | G23: FALSE | H23: Journal
B24: #5 | C24: Prepare | D24: Journal entry to close temporary accounts | G24: FALSE | H24: Journal
B25: #6 | C25: Prepare | D25: Ending Balance Sheet | G25: FALSE | H25: Financial_Statements_Builder
B26: #7 | C26: Prepare | D26: Income Statement | G26: FALSE | H26: Financial_Statements_Builder
B27: #8 | C27: Prepare | D27: Statement of Shareholders' Equity | G27: FALSE | H27: Financial_Statements_Builder
B28: #9 | G28: FALSE
B29: #10 | G29: FALSE
B30: #11 | G30: FALSE
B31: #12 | G31: FALSE
B32: #13 | G32: FALSE
B33: #14 | G33: FALSE
B34: #15 | G34: FALSE
B36: Chart of Accounts
B38: Permanent Accounts | C38: Assets | E38: Liabilities | G38: Equities
C39: Name | D39: Current/Noncurrent | E39: Name | F39: Current/Noncurrent
C40: {=IFERROR(_xlfn._xlws.FILTER(MD_Asset[[#All],[Account Name]],MD_Asset[[#All],[Used]]=1),"")} -> Cash | D40: =IF(NOT(ISBLANK(C40)),_xlfn.XLOOKUP(C40,MD_Asset[Account Name],MD_Asset[C/NC],""),"") -> C | E40: {=IFERROR(_xlfn._xlws.FILTER(MD_Liability[[#All],[Account Name]],MD_Liability[[#All],[Used]]=1),"")} -> Interest Payable | F40: =IF(NOT(ISBLANK(E40)),_xlfn.XLOOKUP(E40,MD_Liability[Account Name],MD_Liability[C/NC],""),"") -> C | G40: {=IFERROR(_xlfn._xlws.FILTER(MD_Equity[[#All],[Account Name]],MD_Equity[[#All],[Used]]=1),"")} -> Common Stock
C41: Accounts Receivable | D41: =IF(NOT(ISBLANK(C41)),_xlfn.XLOOKUP(C41,MD_Asset[Account Name],MD_Asset[C/NC],""),"") -> C | E41: Dividends Payable | F41: =IF(NOT(ISBLANK(E41)),_xlfn.XLOOKUP(E41,MD_Liability[Account Name],MD_Liability[C/NC],""),"") -> C | G41: Retained Earnings
C42: Inventories | D42: =IF(NOT(ISBLANK(C42)),_xlfn.XLOOKUP(C42,MD_Asset[Account Name],MD_Asset[C/NC],""),"") -> C | E42: Notes Payable | F42: =IF(NOT(ISBLANK(E42)),_xlfn.XLOOKUP(E42,MD_Liability[Account Name],MD_Liability[C/NC],""),"") -> NC
C43: Property, Plant & Equipment | D43: =IF(NOT(ISBLANK(C43)),_xlfn.XLOOKUP(C43,MD_Asset[Account Name],MD_Asset[C/NC],""),"") -> NC | F43: =IF(NOT(ISBLANK(E43)),_xlfn.XLOOKUP(E43,MD_Liability[Account Name],MD_Liability[C/NC],""),"")
C44: Accumulated Depreciation | D44: =IF(NOT(ISBLANK(C44)),_xlfn.XLOOKUP(C44,MD_Asset[Account Name],MD_Asset[C/NC],""),"") -> NC | F44: =IF(NOT(ISBLANK(E44)),_xlfn.XLOOKUP(E44,MD_Liability[Account Name],MD_Liability[C/NC],""),"")
D45: =IF(NOT(ISBLANK(C45)),_xlfn.XLOOKUP(C45,MD_Asset[Account Name],MD_Asset[C/NC],""),"") | F45: =IF(NOT(ISBLANK(E45)),_xlfn.XLOOKUP(E45,MD_Liability[Account Name],MD_Liability[C/NC],""),"")
D46: =IF(NOT(ISBLANK(C46)),_xlfn.XLOOKUP(C46,MD_Asset[Account Name],MD_Asset[C/NC],""),"") | F46: =IF(NOT(ISBLANK(E46)),_xlfn.XLOOKUP(E46,MD_Liability[Account Name],MD_Liability[C/NC],""),"")
...

Sheet Journal
C2: Transaction # | D2: 14 | E2: =Entity&" Journal for "&BegDate&" to "&EndDate -> Miloslav's Magazines Journal for 12/31/20x3 to 12/31/20x4 | H2: Balance? | I2: =IF(ROUND(SUM(Journal[Dr Amt])-SUM(Journal[Cr Amt]),2)=0,"YES",ROUND(SUM(Journal[Dr Amt])-SUM(Journal[Cr Amt]),2)) -> YES
L3: X
C4: {=INDEX(ProblemData!D78:AN79,2,D2+1)} -> Close temporary accounts | L4: X
L5: X
L6: X
L7: X
C8: Transaction # | D8: Accnt Type | E8: Debit Account | F8: Credit Account | G8: Dr Amt | H8: Cr Amt | I8: Cash Flow | J8: Movement # | K8: Cash | L8: ref1 | M8: ref2 | N8: ref3
C9: 1 | D9: Asset | E9: Cash | G9: 3 | J9: =IF(Journal[[#This Row],[Transaction '#]]="","",IF(Journal[[#This Row],[Transaction '#]]=C8,J8+1,1)) -> 1 | K9: {=IFERROR(_xlfn.IFS(Journal[[#This Row],[Debit Account]]="Cash",Journal[[#This Row],[Dr Amt]],Journal[[#This Row],[Credit Account]]="Cash",-Journal[[#This Row],[Cr Amt]]),0)} -> 3 | L9: {=IF(Journal[[#This Row],[Transaction '#]]<>"",IFERROR(INDEX(ProblemData!$E$240:$AM$240,1,Journal[[#This Row],[Transaction '#]]),""),"")} -> ICS | M9: =IF(Journal[[#This Row],[ref1]]="","",IF(NOT(ISBLANK(Journal[[#This Row],[Transaction '#]])),Journal[[#This Row],[ref1]]&Journal[[#This Row],[Movement '#]],"")) -> ICS1 | N9: =OR(Journal[[#This Row],[ref1]]="",ISNUMBER(MATCH(Journal[[#This Row],[ref1]],Operating[Abbr], 0))) -> FALSE | P9: =Journal[[#This Row],[Accnt Type]]&"Used" -> AssetUsed
C10: 1 | D10: Equity | F10: Common Stock | H10: 3 | J10: =IF(Journal[[#This Row],[Transaction '#]]="","",IF(Journal[[#This Row],[Transaction '#]]=C9,J9+1,1)) -> 2 | K10: {=IFERROR(_xlfn.IFS(Journal[[#This Row],[Debit Account]]="Cash",Journal[[#This Row],[Dr Amt]],Journal[[#This Row],[Credit Account]]="Cash",-Journal[[#This Row],[Cr Amt]]),0)} -> 0 | L10: {=IF(Journal[[#This Row],[Transaction '#]]<>"",IFERROR(INDEX(ProblemData!$E$240:$AM$240,1,Journal[[#This Row],[Transaction '#]]),""),"")} -> ICS | M10: =IF(Journal[[#This Row],[ref1]]="","",IF(NOT(ISBLANK(Journal[[#This Row],[Transaction '#]])),Journal[[#This Row],[ref1]]&Journal[[#This Row],[Movement '#]],"")) -> ICS2 | N10: =OR(Journal[[#This Row],[ref1]]="",ISNUMBER(MATCH(Journal[[#This Row],[ref1]],Operating[Abbr], 0))) -> FALSE | P10: =Journal[[#This Row],[Accnt Type]]&"Used" -> EquityUsed
J11: =IF(Journal[[#This Row],[Transaction '#]]="","",IF(Journal[[#This Row],[Transaction '#]]=C10,J10+1,1)) | K11: {=IFERROR(_xlfn.IFS(Journal[[#This Row],[Debit Account]]="Cash",Journal[[#This Row],[Dr Amt]],Journal[[#This Row],[Credit Account]]="Cash",-Journal[[#This Row],[Cr Amt]]),0)} -> 0 | L11: {=IF(Journal[[#This Row],[Transaction '#]]<>"",IFERROR(INDEX(ProblemData!$E$240:$AM$240,1,Journal[[#This Row],[Transaction '#]]),""),"")} | M11: =IF(Journal[[#This Row],[ref1]]="","",IF(NOT(ISBLANK(Journal[[#This Row],[Transaction '#]])),Journal[[#This Row],[ref1]]&Journal[[#This Row],[Movement '#]],"")) | N11: =OR(Journal[[#This Row],[ref1]]="",ISNUMBER(MATCH(Journal[[#This Row],[ref1]],Operating[Abbr], 0))) -> TRUE | P11: =Journal[[#This Row],[Accnt Type]]&"Used" -> Used
C12: 2 | D12: Asset | E12: Cash | G12: 20 | J12: =IF(Journal[[#This Row],[Transaction '#]]="","",IF(Journal[[#This Row],[Transaction '#]]=C11,J11+1,1)) -> 1 | K12: {=IFERROR(_xlfn.IFS(Journal[[#This Row],[Debit Account]]="Cash",Journal[[#This Row],[Dr Amt]],Journal[[#This Row],[Credit Account]]="Cash",-Journal[[#This Row],[Cr Amt]]),0)} -> 20 | L12: {=IF(Journal[[#This Row],[Transaction '#]]<>"",IFERROR(INDEX(ProblemData!$E$240:$AM$240,1,Journal[[#This Row],[Transaction '#]]),""),"")} -> IN | M12: =IF(Journal[[#This Row],[ref1]]="","",IF(NOT(ISBLANK(Journal[[#This Row],[Transaction '#]])),Journal[[#This Row],[ref1]]&Journal[[#This Row],[Movement '#]],"")) -> IN1 | N12: =OR(Journal[[#This Row],[ref1]]="",ISNUMBER(MATCH(Journal[[#This Row],[ref1]],Operating[Abbr], 0))) -> FALSE | P12: =Journal[[#This Row],[Accnt Type]]&"Used" -> AssetUsed
C13: 2 | D13: Liability | F13: Notes Payable | H13: 20 | J13: =IF(Journal[[#This Row],[Transaction '#]]="","",IF(Journal[[#This Row],[Transaction '#]]=C12,J12+1,1)) -> 2 | K13: {=IFERROR(_xlfn.IFS(Journal[[#This Row],[Debit Account]]="Cash",Journal[[#This Row],[Dr Amt]],Journal[[#This Row],[Credit Account]]="Cash",-Journal[[#This Row],[Cr Amt]]),0)} -> 0 | L13: {=IF(Journal[[#This Row],[Transaction '#]]<>"",IFERROR(INDEX(ProblemData!$E$240:$AM$240,1,Journal[[#This Row],[Transaction '#]]),""),"")} -> IN | M13: =IF(Journal[[#This Row],[ref1]]="","",IF(NOT(ISBLANK(Journal[[#This Row],[Transaction '#]])),Journal[[#This Row],[ref1]]&Journal[[#This Row],[Movement '#]],"")) -> IN2 | N13: =OR(Journal[[#This Row],[ref1]]="",ISNUMBER(MATCH(Journal[[#This Row],[ref1]],Operating[Abbr], 0))) -> FALSE | P13: =Journal[[#This Row],[Accnt Type]]&"Used" -> LiabilityUsed
J14: =IF(Journal[[#This Row],[Transaction '#]]="","",IF(Journal[[#This Row],[Transaction '#]]=C13,J13+1,1)) | K14: {=IFERROR(_xlfn.IFS(Journal[[#This Row],[Debit Account]]="Cash",Journal[[#This Row],[Dr Amt]],Journal[[#This Row],[Credit Account]]="Cash",-Journal[[#This Row],[Cr Amt]]),0)} -> 0 | L14: {=IF(Journal[[#This Row],[Transaction '#]]<>"",IFERROR(INDEX(ProblemData!$E$240:$AM$240,1,Journal[[#This Row],[Transaction '#]]),""),"")} | M14: =IF(Journal[[#This Row],[ref1]]="","",IF(NOT(ISBLANK(Journal[[#This Row],[Transaction '#]])),Journal[[#This Row],[ref1]]&Journal[[#This Row],[Movement '#]],"")) | N14: =OR(Journal[[#This Row],[ref1]]="",ISNUMBER(MATCH(Journal[[#This Row],[ref1]],Operating[Abbr], 0))) -> TRUE | P14: =Journal[[#This Row],[Accnt Type]]&"Used" -> Used
C15: 3 | D15: Asset | E15: Property, Plant & Equipment | G15: 1 | J15: =IF(Journal[[#This Row],[Transaction '#]]="","",IF(Journal[[#This Row],[Transaction '#]]=C14,J14+1,1)) -> 1 | K15: {=IFERROR(_xlfn.IFS(Journal[[#This Row],[Debit Account]]="Cash",Journal[[#This Row],[Dr Amt]],Journal[[#This Row],[Credit Account]]="Cash",-Journal[[#This Row],[Cr Amt]]),0)} -> 0 | L15: {=IF(Journal[[#This Row],[Transaction '#]]<>"",IFERROR(INDEX(ProblemData!$E$240:$AM$240,1,Journal[[#This Row],[Transaction '#]]),""),"")} -> PPPE | M15: =IF(Journal[[#This Row],[ref1]]="","",IF(NOT(ISBLANK(Journal[[#This Row],[Transaction '#]])),Journal[[#This Row],[ref1]]&Journal[[#This Row],[Movement '#]],"")) -> PPPE1 | N15: =OR(Journal[[#This Row],[ref1]]="",ISNUMBER(MATCH(Journal[[#This Row],[ref1]],Operating[Abbr], 0))) -> FALSE | P15: =Journal[[#This Row],[Accnt Type]]&"Used" -> AssetUsed
C16: 3 | D16: Asset | F16: Cash | H16: 1 | J16: =IF(Journal[[#This Row],[Transaction '#]]="","",IF(Journal[[#This Row],[Transaction '#]]=C15,J15+1,1)) -> 2 | K16: {=IFERROR(_xlfn.IFS(Journal[[#This Row],[Debit Account]]="Cash",Journal[[#This Row],[Dr Amt]],Journal[[#This Row],[Credit Account]]="Cash",-Journal[[#This Row],[Cr Amt]]),0)} -> -1 | L16: {=IF(Journal[[#This Row],[Transaction '#]]<>"",IFERROR(INDEX(ProblemData!$E$240:$AM$240,1,Journal[[#This Row],[Transaction '#]]),""),"")} -> PPPE | M16: =IF(Journal[[#This Row],[ref1]]="","",IF(NOT(ISBLANK(Journal[[#This Row],[Transaction '#]])),Journal[[#This Row],[ref1]]&Journal[[#This Row],[Movement '#]],"")) -> PPPE2 | N16: =OR(Journal[[#This Row],[ref1]]="",ISNUMBER(MATCH(Journal[[#This Row],[ref1]],Operating[Abbr], 0))) -> FALSE | P16: =Journal[[#This Row],[Accnt Type]]&"Used" -> AssetUsed
J17: =IF(Journal[[#This Row],[Transaction '#]]="","",IF(Journal[[#This Row],[Transaction '#]]=C16,J16+1,1)) | K17: {=IFERROR(_xlfn.IFS(Journal[[#This Row],[Debit Account]]="Cash",Journal[[#This Row],[Dr Amt]],Journal[[#This Row],[Credit Account]]="Cash",-Journal[[#This Row],[Cr Amt]]),0)} -> 0 | L17: {=IF(Journal[[#This Row],[Transaction '#]]<>"",IFERROR(INDEX(ProblemData!$E$240:$AM$240,1,Journal[[#This Row],[Transaction '#]]),""),"")} | M17: =IF(Journal[[#This Row],[ref1]]="","",IF(NOT(ISBLANK(Journal[[#This Row],[Transaction '#]])),Journal[[#This Row],[ref1]]&Journal[[#This Row],[Movement '#]],"")) | N17: =OR(Journal[[#This Row],[ref1]]="",ISNUMBER(MATCH(Journal[[#This Row],[ref1]],Operating[Abbr], 0))) -> TRUE | P17: =Journal[[#This Row],[Accnt Type]]&"Used" -> Used
C18: 4 | D18: Asset | E18: Inventories | G18: 20 | J18: =IF(Journal[[#This Row],[Transaction '#]]="","",IF(Journal[[#This Row],[Transaction '#]]=C17,J17+1,1)) -> 1 | K18: {=IFERROR(_xlfn.IFS(Journal[[#This Row],[Debit Account]]="Cash",Journal[[#This Row],[Dr Amt]],Journal[[#This Row],[Credit Account]]="Cash",-Journal[[#This Row],[Cr Amt]]),0)} -> 0 | L18: {=IF(Journal[[#This Row],[Transaction '#]]<>"",IFERROR(INDEX(ProblemData!$E$240:$AM$240,1,Journal[[#This Row],[Transaction '#]]),""),"")} -> PdS | M18: =IF(Journal[[#This Row],[ref1]]="","",IF(NOT(ISBLANK(Journal[[#This Row],[Transaction '#]])),Journal[[#This Row],[ref1]]&Journal[[#This Row],[Movement '#]],"")) -> PdS1 | N18: =OR(Journal[[#This Row],[ref1]]="",ISNUMBER(MATCH(Journal[[#This Row],[ref1]],Operating[Abbr], 0))) -> TRUE | P18: =Journal[[#This Row],[Accnt Type]]&"Used" -> AssetUsed
C19: 4 | D19: Asset | F19: Cash | H19: 20 | J19: =IF(Journal[[#This Row],[Transaction '#]]="","",IF(Journal[[#This Row],[Transaction '#]]=C18,J18+1,1)) -> 2 | K19: {=IFERROR(_xlfn.IFS(Journal[[#This Row],[Debit Account]]="Cash",Journal[[#This Row],[Dr Amt]],Journal[[#This Row],[Credit Account]]="Cash",-Journal[[#This Row],[Cr Amt]]),0)} -> -20 | L19: {=IF(Journal[[#This Row],[Transaction '#]]<>"",IFERROR(INDEX(ProblemData!$E$240:$AM$240,1,Journal[[#This Row],[Transaction '#]]),""),"")} -> PdS | M19: =IF(Journal[[#This Row],[ref1]]="","",IF(NOT(ISBLANK(Journal[[#This Row],[Transaction '#]])),Journal[[#This Row],[ref1]]&Journal[[#This Row],[Movement '#]],"")) -> PdS2 | N19: =OR(Journal[[#This Row],[ref1]]="",ISNUMBER(MATCH(Journal[[#This Row],[ref1]],Operating[Abbr], 0))) -> TRUE | P19: =Journal[[#This Row],[Accnt Type]]&"Used" -> AssetUsed
J20: =IF(Journal[[#This Row],[Transaction '#]]="","",IF(Journal[[#This Row],[Transaction '#]]=C19,J19+1,1)) | K20: {=IFERROR(_xlfn.IFS(Journal[[#This Row],[Debit Account]]="Cash",Journal[[#This Row],[Dr Amt]],Journal[[#This Row],[Credit Account]]="Cash",-Journal[[#This Row],[Cr Amt]]),0)} -> 0 | L20: {=IF(Journal[[#This Row],[Transaction '#]]<>"",IFERROR(INDEX(ProblemData!$E$240:$AM$240,1,Journal[[#This Row],[Transaction '#]]),""),"")} | M20: =IF(Journal[[#This Row],[ref1]]="","",IF(NOT(ISBLANK(Journal[[#This Row],[Transaction '#]])),Journal[[#This Row],[ref1]]&Journal[[#This Row],[Movement '#]],"")) | N20: =OR(Journal[[#This Row],[ref1]]="",ISNUMBER(MATCH(Journal[[#This Row],[ref1]],Operating[Abbr], 0))) -> TRUE | P20: =Journal[[#This Row],[Accnt Type]]&"Used" -> Used
C21: 5 | D21: Asset | E21: Accounts Receivable | G21: 25 | J21: =IF(Journal[[#This Row],[Transaction '#]]="","",IF(Journal[[#This Row],[Transaction '#]]=C20,J20+1,1)) -> 1 | K21: {=IFERROR(_xlfn.IFS(Journal[[#This Row],[Debit Account]]="Cash",Journal[[#This Row],[Dr Amt]],Journal[[#This Row],[Credit Account]]="Cash",-Journal[[#This Row],[Cr Amt]]),0)} -> 0 | L21: {=IF(Journal[[#This Row],[Transaction '#]]<>"",IFERROR(INDEX(ProblemData!$E$240:$AM$240,1,Journal[[#This Row],[Transaction '#]]),""),"")} | M21: =IF(Journal[[#This Row],[ref1]]="","",IF(NOT(ISBLANK(Journal[[#This Row],[Transaction '#]])),Journal[[#This Row],[ref1]]&Journal[[#This Row],[Movement '#]],"")) | N21: =OR(Journal[[#This Row],[ref1]]="",ISNUMBER(MATCH(Journal[[#This Row],[ref1]],Operating[Abbr], 0))) -> TRUE | P21: =Journal[[#This Row],[Accnt Type]]&"Used" -> AssetUsed
C22: 5 | D22: Revenue | F22: Sales | H22: 25 | J22: =IF(Journal[[#This Row],[Transaction '#]]="","",IF(Journal[[#This Row],[Transaction '#]]=C21,J21+1,1)) -> 2 | K22: {=IFERROR(_xlfn.IFS(Journal[[#This Row],[Debit Account]]="Cash",Journal[[#This Row],[Dr Amt]],Journal[[#This Row],[Credit Account]]="Cash",-Journal[[#This Row],[Cr Amt]]),0)} -> 0 | L22: {=IF(Journal[[#This Row],[Transaction '#]]<>"",IFERROR(INDEX(ProblemData!$E$240:$AM$240,1,Journal[[#This Row],[Transaction '#]]),""),"")} | M22: =IF(Journal[[#This Row],[ref1]]="","",IF(NOT(ISBLANK(Journal[[#This Row],[Transaction '#]])),Journal[[#This Row],[ref1]]&Journal[[#This Row],[Movement '#]],"")) | N22: =OR(Journal[[#This Row],[ref1]]="",ISNUMBER(MATCH(Journal[[#This Row],[ref1]],Operating[Abbr], 0))) -> TRUE | P22: =Journal[[#This Row],[Accnt Type]]&"Used" -> RevenueUsed
J23: =IF(Journal[[#This Row],[Transaction '#]]="","",IF(Journal[[#This Row],[Transaction '#]]=C22,J22+1,1)) | K23: {=IFERROR(_xlfn.IFS(Journal[[#This Row],[Debit Account]]="Cash",Journal[[#This Row],[Dr Amt]],Journal[[#This Row],[Credit Account]]="Cash",-Journal[[#This Row],[Cr Amt]]),0)} -> 0 | L23: {=IF(Journal[[#This Row],[Transaction '#]]<>"",IFERROR(INDEX(ProblemData!$E$240:$AM$240,1,Journal[[#This Row],[Transaction '#]]),""),"")} | M23: =IF(Journal[[#This Row],[ref1]]="","",IF(NOT(ISBLANK(Journal[[#This Row],[Transaction '#]])),Journal[[#This Row],[ref1]]&Journal[[#This Row],[Movement '#]],"")) | N23: =OR(Journal[[#This Row],[ref1]]="",ISNUMBER(MATCH(Journal[[#This Row],[ref1]],Operating[Abbr], 0))) -> TRUE | P23: =Journal[[#This Row],[Accnt Type]]&"Used" -> Used
C24: 6 | D24: Asset | E24: Cash | G24: 20.5 | J24: =IF(Journal[[#This Row],[Transaction '#]]="","",IF(Journal[[#This Row],[Transaction '#]]=C23,J23+1,1)) -> 1 | K24: {=IFERROR(_xlfn.IFS(Journal[[#This Row],[Debit Account]]="Cash",Journal[[#This Row],[Dr Amt]],Journal[[#This Row],[Credit Account]]="Cash",-Journal[[#This Row],[Cr Amt]]),0)} -> 20.5 | L24: {=IF(Journal[[#This Row],[Transaction '#]]<>"",IFERROR(INDEX(ProblemData!$E$240:$AM$240,1,Journal[[#This Row],[Transaction '#]]),""),"")} -> ColC | M24: =IF(Journal[[#This Row],[ref1]]="","",IF(NOT(ISBLANK(Journal[[#This Row],[Transaction '#]])),Journal[[#This Row],[ref1]]&Journal[[#This Row],[Movement '#]],"")) -> ColC1 | N24: =OR(Journal[[#This Row],[ref1]]="",ISNUMBER(MATCH(Journal[[#This Row],[ref1]],Operating[Abbr], 0))) -> TRUE | P24: =Journal[[#This Row],[Accnt Type]]&"Used" -> AssetUsed
C25: 6 | D25: Asset | F25: Accounts Receivable | H25: 20.5 | J25: =IF(Journal[[#This Row],[Transaction '#]]="","",IF(Journal[[#This Row],[Transaction '#]]=C24,J24+1,1)) -> 2 | K25: {=IFERROR(_xlfn.IFS(Journal[[#This Row],[Debit Account]]="Cash",Journal[[#This Row],[Dr Amt]],Journal[[#This Row],[Credit Account]]="Cash",-Journal[[#This Row],[Cr Amt]]),0)} -> 0 | L25: {=IF(Journal[[#This Row],[Transaction '#]]<>"",IFERROR(INDEX(ProblemData!$E$240:$AM$240,1,Journal[[#This Row],[Transaction '#]]),""),"")} -> ColC | M25: =IF(Journal[[#This Row],[ref1]]="","",IF(NOT(ISBLANK(Journal[[#This Row],[Transaction '#]])),Journal[[#This Row],[ref1]]&Journal[[#This Row],[Movement '#]],"")) -> ColC2 | N25: =OR(Journal[[#This Row],[ref1]]="",ISNUMBER(MATCH(Journal[[#This Row],[ref1]],Operating[Abbr], 0))) -> TRUE | P25: =Journal[[#This Row],[Accnt Type]]&"Used" -> AssetUsed
J26: =IF(Journal[[#This Row],[Transaction '#]]="","",IF(Journal[[#This Row],[Transaction '#]]=C25,J25+1,1)) | K26: {=IFERROR(_xlfn.IFS(Journal[[#This Row],[Debit Account]]="Cash",Journal[[#This Row],[Dr Amt]],Journal[[#This Row],[Credit Account]]="Cash",-Journal[[#This Row],[Cr Amt]]),0)} -> 0 | L26: {=IF(Journal[[#This Row],[Transaction '#]]<>"",IFERROR(INDEX(ProblemData!$E$240:$AM$240,1,Journal[[#This Row],[Transaction '#]]),""),"")} | M26: =IF(Journal[[#This Row],[ref1]]="","",IF(NOT(ISBLANK(Journal[[#This Row],[Transaction '#]])),Journal[[#This Row],[ref1]]&Journal[[#This Row],[Movement '#]],"")) | N26: =OR(Journal[[#This Row],[ref1]]="",ISNUMBER(MATCH(Journal[[#This Row],[ref1]],Operating[Abbr], 0))) -> TRUE | P26: =Journal[[#This Row],[Accnt Type]]&"Used" -> Used
C27: 7 | D27: Expense | E27: Salaries & Wages Expense | G27: 3 | J27: =IF(Journal[[#This Row],[Transaction '#]]="","",IF(Journal[[#This Row],[Transaction '#]]=C26,J26+1,1)) -> 1 | K27: {=IFERROR(_xlfn.IFS(Journal[[#This Row],[Debit Account]]="Cash",Journal[[#This Row],[Dr Amt]],Journal[[#This Row],[Credit Account]]="Cash",-Journal[[#This Row],[Cr Amt]]),0)} -> 0 | L27: {=IF(Journal[[#This Row],[Transaction '#]]<>"",IFERROR(INDEX(ProblemData!$E$240:$AM$240,1,Journal[[#This Row],[Transaction '#]]),""),"")} -> PdSW | M27: =IF(Journal[[#This Row],[ref1]]="","",IF(NOT(ISBLANK(Journal[[#This Row],[Transaction '#]])),Journal[[#This Row],[ref1]]&Journal[[#This Row],[Movement '#]],"")) -> PdSW1 | N27: =OR(Journal[[#This Row],[ref1]]="",ISNUMBER(MATCH(Journal[[#This Row],[ref1]],Operating[Abbr], 0))) -> TRUE | P27: =Journal[[#This Row],[Accnt Type]]&"Used" -> ExpenseUsed
C28: 7 | D28: Asset | F28: Cash | H28: 3 | J28: =IF(Journal[[#This Row],[Transaction '#]]="","",IF(Journal[[#This Row],[Transaction '#]]=C27,J27+1,1)) -> 2 | K28: {=IFERROR(_xlfn.IFS(Journal[[#This Row],[Debit Account]]="Cash",Journal[[#This Row],[Dr Amt]],Journal[[#This Row],[Credit Account]]="Cash",-Journal[[#This Row],[Cr Amt]]),0)} -> -3 | L28: {=IF(Journal[[#This Row],[Transaction '#]]<>"",IFERROR(INDEX(ProblemData!$E$240:$AM$240,1,Journal[[#This Row],[Transaction '#]]),""),"")} -> PdSW | M28: =IF(Journal[[#This Row],[ref1]]="","",IF(NOT(ISBLANK(Journal[[#This Row],[Transaction '#]])),Journal[[#This Row],[ref1]]&Journal[[#This Row],[Movement '#]],"")) -> PdSW2 | N28: =OR(Journal[[#This Row],[ref1]]="",ISNUMBER(MATCH(Journal[[#This Row],[ref1]],Operating[Abbr], 0))) -> TRUE | P28: =Journal[[#This Row],[Accnt Type]]&"Used" -> AssetUsed
J29: =IF(Journal[[#This Row],[Transaction '#]]="","",IF(Journal[[#This Row],[Transaction '#]]=C28,J28+1,1)) | K29: {=IFERROR(_xlfn.IFS(Journal[[#This Row],[Debit Account]]="Cash",Journal[[#This Row],[Dr Amt]],Journal[[#This Row],[Credit Account]]="Cash",-Journal[[#This Row],[Cr Amt]]),0)} -> 0 | L29: {=IF(Journal[[#This Row],[Transaction '#]]<>"",IFERROR(INDEX(ProblemData!$E$240:$AM$240,1,Journal[[#This Row],[Transaction '#]]),""),"")} | M29: =IF(Journal[[#This Row],[ref1]]="","",IF(NOT(ISBLANK(Journal[[#This Row],[Transaction '#]])),Journal[[#This Row],[ref1]]&Journal[[#This Row],[Movement '#]],"")) | N29: =OR(Journal[[#This Row],[ref1]]="",ISNUMBER(MATCH(Journal[[#This Row],[ref1]],Operating[Abbr], 0))) -> TRUE | P29: =Journal[[#This Row],[Accnt Type]]&"Used" -> Used
C30: 8 | D30: Equity | E30: Retained Earnings | G30: 0.05 | J30: =IF(Journal[[#This Row],[Transaction '#]]="","",IF(Journal[[#This Row],[Transaction '#]]=C29,J29+1,1)) -> 1 | K30: {=IFERROR(_xlfn.IFS(Journal[[#This Row],[Debit Account]]="Cash",Journal[[#This Row],[Dr Amt]],Journal[[#This Row],[Credit Account]]="Cash",-Journal[[#This Row],[Cr Amt]]),0)} -> 0 | L30: {=IF(Journal[[#This Row],[Transaction '#]]<>"",IFERROR(INDEX(ProblemData!$E$240:$AM$240,1,Journal[[#This Row],[Transaction '#]]),""),"")} -> DD | M30: =IF(Journal[[#This Row],[ref1]]="","",IF(NOT(ISBLANK(Journal[[#This Row],[Transaction '#]])),Journal[[#This Row],[ref1]]&Journal[[#This Row],[Movement '#]],"")) -> DD1 | N30: =OR(Journal[[#This Row],[ref1]]="",ISNUMBER(MATCH(Journal[[#This Row],[ref1]],Operating[Abbr], 0))) -> FALSE | P30: =Journal[[#This Row],[Accnt Type]]&"Used" -> EquityUsed
C31: 8 | D31: Liability | F31: Dividends Payable | H31: 0.05 | J31: =IF(Journal[[#This Row],[Transaction '#]]="","",IF(Journal[[#This Row],[Transaction '#]]=C30,J30+1,1)) -> 2 | K31: {=IFERROR(_xlfn.IFS(Journal[[#This Row],[Debit Account]]="Cash",Journal[[#This Row],[Dr Amt]],Journal[[#This Row],[Credit Account]]="Cash",-Journal[[#This Row],[Cr Amt]]),0)} -> 0 | L31: {=IF(Journal[[#This Row],[Transaction '#]]<>"",IFERROR(INDEX(ProblemData!$E$240:$AM$240,1,Journal[[#This Row],[Transaction '#]]),""),"")} -> DD | M31: =IF(Journal[[#This Row],[ref1]]="","",IF(NOT(ISBLANK(Journal[[#This Row],[Transaction '#]])),Journal[[#This Row],[ref1]]&Journal[[#This Row],[Movement '#]],"")) -> DD2 | N31: =OR(Journal[[#This Row],[ref1]]="",ISNUMBER(MATCH(Journal[[#This Row],[ref1]],Operating[Abbr], 0))) -> FALSE | P31: =Journal[[#This Row],[Accnt Type]]&"Used" -> LiabilityUsed
J32: =IF(Journal[[#This Row],[Transaction '#]]="","",IF(Journal[[#This Row],[Transaction '#]]=C31,J31+1,1)) | K32: {=IFERROR(_xlfn.IFS(Journal[[#This Row],[Debit Account]]="Cash",Journal[[#This Row],[Dr Amt]],Journal[[#This Row],[Credit Account]]="Cash",-Journal[[#This Row],[Cr Amt]]),0)} -> 0 | L32: {=IF(Journal[[#This Row],[Transaction '#]]<>"",IFERROR(INDEX(ProblemData!$E$240:$AM$240,1,Journal[[#This Row],[Transaction '#]]),""),"")} | M32: =IF(Journal[[#This Row],[ref1]]="","",IF(NOT(ISBLANK(Journal[[#This Row],[Transaction '#]])),Journal[[#This Row],[ref1]]&Journal[[#This Row],[Movement '#]],"")) | N32: =OR(Journal[[#This Row],[ref1]]="",ISNUMBER(MATCH(Journal[[#This Row],[ref1]],Operating[Abbr], 0))) -> TRUE | P32: =Journal[[#This Row],[Accnt Type]]&"Used" -> Used
C33: 9 | D33: Liability | E33: Dividends Payable | G33: 0.05 | J33: =IF(Journal[[#This Row],[Transaction '#]]="","",IF(Journal[[#This Row],[Transaction '#]]=C32,J32+1,1)) -> 1 | K33: {=IFERROR(_xlfn.IFS(Journal[[#This Row],[Debit Account]]="Cash",Journal[[#This Row],[Dr Amt]],Journal[[#This Row],[Credit Account]]="Cash",-Journal[[#This Row],[Cr Amt]]),0)} -> 0 | L33: {=IF(Journal[[#This Row],[Transaction '#]]<>"",IFERROR(INDEX(ProblemData!$E$240:$AM$240,1,Journal[[#This Row],[Transaction '#]]),""),"")} -> PD | M33: =IF(Journal[[#This Row],[ref1]]="","",IF(NOT(ISBLANK(Journal[[#This Row],[Transaction '#]])),Journal[[#This Row],[ref1]]&Journal[[#This Row],[Movement '#]],"")) -> PD1 | N33: =OR(Journal[[#This Row],[ref1]]="",ISNUMBER(MATCH(Journal[[#This Row],[ref1]],Operating[Abbr], 0))) -> FALSE | P33: =Journal[[#This Row],[Accnt Type]]&"Used" -> LiabilityUsed
C34: 9 | D34: Asset | F34: Cash | H34: 0.05 | J34: =IF(Journal[[#This Row],[Transaction '#]]="","",IF(Journal[[#This Row],[Transaction '#]]=C33,J33+1,1)) -> 2 | K34: {=IFERROR(_xlfn.IFS(Journal[[#This Row],[Debit Account]]="Cash",Journal[[#This Row],[Dr Amt]],Journal[[#This Row],[Credit Account]]="Cash",-Journal[[#This Row],[Cr Amt]]),0)} -> -0.05 | L34: {=IF(Journal[[#This Row],[Transaction '#]]<>"",IFERROR(INDEX(ProblemData!$E$240:$AM$240,1,Journal[[#This Row],[Transaction '#]]),""),"")} -> PD | M34: =IF(Journal[[#This Row],[ref1]]="","",IF(NOT(ISBLANK(Journal[[#This Row],[Transaction '#]])),Journal[[#This Row],[ref1]]&Journal[[#This Row],[Movement '#]],"")) -> PD2 | N34: =OR(Journal[[#This Row],[ref1]]="",ISNUMBER(MATCH(Journal[[#This Row],[ref1]],Operating[Abbr], 0))) -> FALSE | P34: =Journal[[#This Row],[Accnt Type]]&"Used" -> AssetUsed
J35: =IF(Journal[[#This Row],[Transaction '#]]="","",IF(Journal[[#This Row],[Transaction '#]]=C34,J34+1,1)) | K35: {=IFERROR(_xlfn.IFS(Journal[[#This Row],[Debit Account]]="Cash",Journal[[#This Row],[Dr Amt]],Journal[[#This Row],[Credit Account]]="Cash",-Journal[[#This Row],[Cr Amt]]),0)} -> 0 | L35: {=IF(Journal[[#This Row],[Transaction '#]]<>"",IFERROR(INDEX(ProblemData!$E$240:$AM$240,1,Journal[[#This Row],[Transaction '#]]),""),"")} | M35: =IF(Journal[[#This Row],[ref1]]="","",IF(NOT(ISBLANK(Journal[[#This Row],[Transaction '#]])),Journal[[#This Row],[ref1]]&Journal[[#This Row],[Movement '#]],"")) | N35: =OR(Journal[[#This Row],[ref1]]="",ISNUMBER(MATCH(Journal[[#This Row],[ref1]],Operating[Abbr], 0))) -> TRUE | P35: =Journal[[#This Row],[Accnt Type]]&"Used" -> Used
J36: =IF(Journal[[#This Row],[Transaction '#]]="","",IF(Journal[[#This Row],[Transaction '#]]=C35,J35+1,1)) | K36: {=IFERROR(_xlfn.IFS(Journal[[#This Row],[Debit Account]]="Cash",Journal[[#This Row],[Dr Amt]],Journal[[#This Row],[Credit Account]]="Cash",-Journal[[#This Row],[Cr Amt]]),0)} -> 0 | L36: {=IF(Journal[[#This Row],[Transaction '#]]<>"",IFERROR(INDEX(ProblemData!$E$240:$AM$240,1,Journal[[#This Row],[Transaction '#]]),""),"")} | M36: =IF(Journal[[#This Row],[ref1]]="","",IF(NOT(ISBLANK(Journal[[#This Row],[Transaction '#]])),Journal[[#This Row],[ref1]]&Journal[[#This Row],[Movement '#]],"")) | N36: =OR(Journal[[#This Row],[ref1]]="",ISNUMBER(MATCH(Journal[[#This Row],[ref1]],Operating[Abbr], 0))) -> TRUE | P36: =Journal[[#This Row],[Accnt Type]]&"Used" -> Used
C37: 10 | D37: Expense | E37: Interest Expense | G37: 1.87 | J37: =IF(Journal[[#This Row],[Transaction '#]]="","",IF(Journal[[#This Row],[Transaction '#]]=C36,J36+1,1)) -> 1 | K37: {=IFERROR(_xlfn.IFS(Journal[[#This Row],[Debit Account]]="Cash",Journal[[#This Row],[Dr Amt]],Journal[[#This Row],[Credit Account]]="Cash",-Journal[[#This Row],[Cr Amt]]),0)} -> 0 | L37: {=IF(Journal[[#This Row],[Transaction '#]]<>"",IFERROR(INDEX(ProblemData!$E$240:$AM$240,1,Journal[[#This Row],[Transaction '#]]),""),"")} | M37: =IF(Journal[[#This Row],[ref1]]="","",IF(NOT(ISBLANK(Journal[[#This Row],[Transaction '#]])),Journal[[#This Row],[ref1]]&Journal[[#This Row],[Movement '#]],"")) | N37: =OR(Journal[[#This Row],[ref1]]="",ISNUMBER(MATCH(Journal[[#This Row],[ref1]],Operating[Abbr], 0))) -> TRUE | P37: =Journal[[#This Row],[Accnt Type]]&"Used" -> ExpenseUsed
C38: 10 | D38: Liability | F38: Interest Payable | H38: 1.87 | J38: =IF(Journal[[#This Row],[Transaction '#]]="","",IF(Journal[[#This Row],[Transaction '#]]=C37,J37+1,1)) -> 2 | K38: {=IFERROR(_xlfn.IFS(Journal[[#This Row],[Debit Account]]="Cash",Journal[[#This Row],[Dr Amt]],Journal[[#This Row],[Credit Account]]="Cash",-Journal[[#This Row],[Cr Amt]]),0)} -> 0 | L38: {=IF(Journal[[#This Row],[Transaction '#]]<>"",IFERROR(INDEX(ProblemData!$E$240:$AM$240,1,Journal[[#This Row],[Transaction '#]]),""),"")} | M38: =IF(Journal[[#This Row],[ref1]]="","",IF(NOT(ISBLANK(Journal[[#This Row],[Transaction '#]])),Journal[[#This Row],[ref1]]&Journal[[#This Row],[Movement '#]],"")) | N38: =OR(Journal[[#This Row],[ref1]]="",ISNUMBER(MATCH(Journal[[#This Row],[ref1]],Operating[Abbr], 0))) -> TRUE | P38: =Journal[[#This Row],[Accnt Type]]&"Used" -> LiabilityUsed
J39: =IF(Journal[[#This Row],[Transaction '#]]="","",IF(Journal[[#This Row],[Transaction '#]]=C38,J38+1,1)) | K39: {=IFERROR(_xlfn.IFS(Journal[[#This Row],[Debit Account]]="Cash",Journal[[#This Row],[Dr Amt]],Journal[[#This Row],[Credit Account]]="Cash",-Journal[[#This Row],[Cr Amt]]),0)} -> 0 | L39: {=IF(Journal[[#This Row],[Transaction '#]]<>"",IFERROR(INDEX(ProblemData!$E$240:$AM$240,1,Journal[[#This Row],[Transaction '#]]),""),"")} | M39: =IF(Journal[[#This Row],[ref1]]="","",IF(NOT(ISBLANK(Journal[[#This Row],[Transaction '#]])),Journal[[#This Row],[ref1]]&Journal[[#This Row],[Movement '#]],"")) | N39: =OR(Journal[[#This Row],[ref1]]="",ISNUMBER(MATCH(Journal[[#This Row],[ref1]],Operating[Abbr], 0))) -> TRUE | P39: =Journal[[#This Row],[Accnt Type]]&"Used" -> Used
C40: 11 | D40: Liability | E40: Interest Payable | G40: 1.87 | J40: =IF(Journal[[#This Row],[Transaction '#]]="","",IF(Journal[[#This Row],[Transaction '#]]=C39,J39+1,1)) -> 1 | K40: {=IFERROR(_xlfn.IFS(Journal[[#This Row],[Debit Account]]="Cash",Journal[[#This Row],[Dr Amt]],Journal[[#This Row],[Credit Account]]="Cash",-Journal[[#This Row],[Cr Amt]]),0)} -> 0 | L40: {=IF(Journal[[#This Row],[Transaction '#]]<>"",IFERROR(INDEX(ProblemData!$E$240:$AM$240,1,Journal[[#This Row],[Transaction '#]]),""),"")} -> PdInt | M40: =IF(Journal[[#This Row],[ref1]]="","",IF(NOT(ISBLANK(Journal[[#This Row],[Transaction '#]])),Journal[[#This Row],[ref1]]&Journal[[#This Row],[Movement '#]],"")) -> PdInt1 | N40: =OR(Journal[[#This Row],[ref1]]="",ISNUMBER(MATCH(Journal[[#This Row],[ref1]],Operating[Abbr], 0))) -> TRUE | P40: =Journal[[#This Row],[Accnt Type]]&"Used" -> LiabilityUsed
C41: 11 | D41: Asset | F41: Cash | H41: 1.87 | J41: =IF(Journal[[#This Row],[Transaction '#]]="","",IF(Journal[[#This Row],[Transaction '#]]=C40,J40+1,1)) -> 2 | K41: {=IFERROR(_xlfn.IFS(Journal[[#This Row],[Debit Account]]="Cash",Journal[[#This Row],[Dr Amt]],Journal[[#This Row],[Credit Account]]="Cash",-Journal[[#This Row],[Cr Amt]]),0)} -> -1.87 | L41: {=IF(Journal[[#This Row],[Transaction '#]]<>"",IFERROR(INDEX(ProblemData!$E$240:$AM$240,1,Journal[[#This Row],[Transaction '#]]),""),"")} -> PdInt | M41: =IF(Journal[[#This Row],[ref1]]="","",IF(NOT(ISBLANK(Journal[[#This Row],[Transaction '#]])),Journal[[#This Row],[ref1]]&Journal[[#This Row],[Movement '#]],"")) -> PdInt2 | N41: =OR(Journal[[#This Row],[ref1]]="",ISNUMBER(MATCH(Journal[[#This Row],[ref1]],Operating[Abbr], 0))) -> TRUE | P41: =Journal[[#This Row],[Accnt Type]]&"Used" -> AssetUsed
...

Sheet Financial_Statements_Builder
C1: Financial Statement Builder | J1: =IF(D4<>"",D4,"") -> Miloslav's Magazines | P1: =IF(N1<>"",COUNTIFS($AK$183:$AK$200,N1),0) -> 0
J2: =IF(D5<>"",D5,"") -> Dollars in Thousands | P2: =IF(N2<>"",COUNTIFS($AK$183:$AK$200,N2),0) -> 0
C3: Item | D3: Selection | N3: Presentation Mode | O3: TRUE
C4: Entity | D4: =Entity -> Miloslav's Magazines | J4: =IF(D6<>"",D6,"") -> 12/31/20x3 | N4: =IF(D8<>"","Explanations of Changes over the "&D8,"") -> Explanations of Changes over the Year | Y4: =IF(D7<>"",D7,"") -> 12/31/20x4
C5: Units | D5: =Units -> Dollars in Thousands
C6: Beginning Balance Sheet Date | D6: =BegDate -> 12/31/20x3 | J6: =IF(OR(E101,F101),"Balance Sheet","") -> Balance Sheet | L6: 1 | N6: =IF(S111,"Income Statement","") -> Income Statement | Q6: 1 | R6: =IF($S$118,"Statement of Changes in Shareholders' Equity","") -> Statement of Changes in Shareholders' Equity | T6: 1 | U6: =IF($S$126,"Cash Flow Statement","") -> Cash Flow Statement | X6: 1 | Y6: =IF($S$146,"Balance Sheet","") -> Balance Sheet
C7: Ending Balance Sheet Date | D7: =EndDate -> 12/31/20x4 | I7: {=_xlfn.VSTACK(_xlfn.ANCHORARRAY(B609),{"","",""},_xlfn.ANCHORARRAY(B689),{"","",""},_xlfn.ANCHORARRAY(B744))} -> 2 | J7: Assets | M7: {=_xlfn.VSTACK(_xlfn.IFS(L564,_xlfn.ANCHORARRAY(I719),L565,_xlfn.ANCHORARRAY(I764),L566,_xlfn.ANCHORARRAY(I799),L567,_xlfn.ANCHORARRAY(I839),L568,{"","",""}),{"","",""},{"","",""},{"","",""},{"","",""},_xlfn.ANCHORARRAY(M557),{"","",""},_xlfn.ANCHORARRAY(M558),_xlfn.ANCHORARRAY(M559),_xlfn.ANCHORARRAY(M560),_xlfn.ANCHORARRAY(M562))} -> 2 | N7: Revenues | Q7: {=_xlfn.IFS(S566=1,_xlfn.ANCHORARRAY(Q653),S566=2,_xlfn.ANCHORARRAY(Q688),S566=3,_xlfn.ANCHORARRAY(Q728),S566=4,_xlfn.ANCHORARRAY(Q778))} -> 2 | R7: Total Shareholders' Equity @ 12/31/20x3 | S7: 0 | T7: {=_xlfn.VSTACK(_xlfn.ANCHORARRAY(T567),{"","",""},_xlfn.ANCHORARRAY(T569),_xlfn.ANCHORARRAY(T571),_xlfn.ANCHORARRAY(T594),_xlfn.ANCHORARRAY(T596),_xlfn.ANCHORARRAY(T614),_xlfn.ANCHORARRAY(T616),_xlfn.ANCHORARRAY(T627),{"","",""},_xlfn.ANCHORARRAY(T629),{"","",""},{"","",""},{"","",""},{"","",""},_xlfn.ANCHORARRAY(T635),{"","",""},{"","",""},{"","",""},{"","",""},_xlfn.ANCHORARRAY(T652),{"","",""},_xlfn.ANCHORARRAY(T654),{"","",""},_xlfn.ANCHORARRAY(T656),_xlfn.ANCHORARRAY(T657),{"","",""},_xlfn.ANCHORARRAY(T670),_xlfn.ANCHORARRAY(T671),{"","",""},_xlfn.ANCHORARRAY(T685))} -> 2 | U7: Cash @ 12/31/20x3 | V7: 0 | X7: {=_xlfn.VSTACK(_xlfn.ANCHORARRAY(AB609),{"","",""},_xlfn.ANCHORARRAY(AB689),{"","",""},_xlfn.ANCHORARRAY(AB744))} -> 2 | Y7: Assets | AC7: Income Statement | AF7: Statement of Changes in Shareholders' Equity | AJ7: Cash Flow Statement | AN7: Ending Balance Sheet
C8: Period | D8: =Period -> Year | AC8: Line in Statement before the latest entry? | AD8: Line not a total or Net Income | AE8: Highlight line | AF8: Line in Statement before the latest entry? | AG8: Line not a total or Balance | AH8: Highlight line | AJ8: Line in Statement before? | AK8: Line not Total or Increase (Derease) | AL8: Highlight | AN8: Line in Statement before? | AO8: Line not Total or Increase (Derease) | AP8: Highlight
C9: Income Statement | D9: ="for the "&D8&" ended "&D7 -> for the Year ended 12/31/20x4 | I9: 4 | J9: Current Assets: | M9: 6 | N9: Sales | O9: 25 | Q9: 3 | R9: Common Stock | X9: 4 | Y9: Current Assets: | AC9: =ISNUMBER(MATCH(N9&O9,FSData!$V$7:$V$95,0)) -> TRUE | AD9: =OR(ISNUMBER(SEARCH("Total",N9,1)),ISNUMBER(SEARCH("Net Income",N9,1))) -> FALSE | AE9: =AND(NOT(AC9),NOT(AD9)) -> FALSE | AF9: =ISNUMBER(MATCH(R9&S9,FSData!$X$7:$X$95,0)) -> TRUE | AG9: =OR(ISNUMBER(SEARCH("Total",R9,1)),ISNUMBER(SEARCH("Balance",R9,1))) -> FALSE | AH9: =AND(NOT(AF9),NOT(AG9)) -> FALSE | AJ9: =ISNUMBER(MATCH(U9&V9,FSData!$Z$7:$Z$95,0)) -> TRUE | AK9: =OR(ISNUMBER(SEARCH("Total",U9,1)),ISNUMBER(SEARCH("Increase (decrease)",U9,1)),ISNUMBER(SEARCH("Operating Activities",U9,1)),ISNUMBER(SEARCH("Investing Activities",U9,1)),ISNUMBER(SEARCH("Financing Activities",U9,1)),ISNUMBER(SEARCH("Cash @",U9,1)),ISNUMBER(SEARCH("Net Income",U9,1)),ISNUMBER(SEARCH("Cash Flow from Operations",U9,1))) -> FALSE | AL9: =AND(NOT(AJ9),NOT(AK9)) -> FALSE | AN9: =ISNUMBER(MATCH(Y9&Z9,FSData!$AB$7:$AB$95,0)) -> TRUE | AO9: =OR(ISNUMBER(SEARCH("Total",Y9,1))) -> FALSE | AP9: =AND(NOT(AN9),NOT(AO9)) -> FALSE
C10: Statement of Changes in Shareholders' Equity | D10: ="for the "&D8&" ended "&D7 -> for the Year ended 12/31/20x4 | I10: 6 | J10: Cash | K10: 0 | M10: 5 | N10: Total Revenues | O10: 25 | Q10: 5 | R10: Balance @ 12/31/20x3 | S10: 0 | X10: 6 | Y10: Cash | Z10: 17.58 | AC10: =ISNUMBER(MATCH(N10&O10,FSData!$V$7:$V$95,0)) -> TRUE | AD10: =OR(ISNUMBER(SEARCH("Total",N10,1)),ISNUMBER(SEARCH("Net Income",N10,1))) -> TRUE | AE10: =AND(NOT(AC10),NOT(AD10)) -> FALSE | AF10: =ISNUMBER(MATCH(R10&S10,FSData!$X$7:$X$95,0)) -> TRUE | AG10: =OR(ISNUMBER(SEARCH("Total",R10,1)),ISNUMBER(SEARCH("Balance",R10,1))) -> TRUE | AH10: =AND(NOT(AF10),NOT(AG10)) -> FALSE | AJ10: =ISNUMBER(MATCH(U10&V10,FSData!$Z$7:$Z$95,0)) -> TRUE | AK10: =OR(ISNUMBER(SEARCH("Total",U10,1)),ISNUMBER(SEARCH("Increase (decrease)",U10,1)),ISNUMBER(SEARCH("Operating Activities",U10,1)),ISNUMBER(SEARCH("Investing Activities",U10,1)),ISNUMBER(SEARCH("Financing Activities",U10,1)),ISNUMBER(SEARCH("Cash @",U10,1)),ISNUMBER(SEARCH("Net Income",U10,1)),ISNUMBER(SEARCH("Cash Flow from Operations",U10,1))) -> FALSE | AL10: =AND(NOT(AJ10),NOT(AK10)) -> FALSE | AN10: =ISNUMBER(MATCH(Y10&Z10,FSData!$AB$7:$AB$95,0)) -> TRUE | AO10: =OR(ISNUMBER(SEARCH("Total",Y10,1))) -> FALSE | AP10: =AND(NOT(AN10),NOT(AO10)) -> FALSE
C11: Cash Flow Statement | D11: ="for the "&D8&" ended "&D7 -> for the Year ended 12/31/20x4 | I11: 7 | J11: Accounts Receivable | K11: 0 | Q11: 7 | R11: Issued common stock | S11: 3 | X11: 7 | Y11: Accounts Receivable | Z11: 4.5 | AC11: =ISNUMBER(MATCH(N11&O11,FSData!$V$7:$V$95,0)) -> TRUE | AD11: =OR(ISNUMBER(SEARCH("Total",N11,1)),ISNUMBER(SEARCH("Net Income",N11,1))) -> FALSE | AE11: =AND(NOT(AC11),NOT(AD11)) -> FALSE | AF11: =ISNUMBER(MATCH(R11&S11,FSData!$X$7:$X$95,0)) -> TRUE | AG11: =OR(ISNUMBER(SEARCH("Total",R11,1)),ISNUMBER(SEARCH("Balance",R11,1))) -> FALSE | AH11: =AND(NOT(AF11),NOT(AG11)) -> FALSE | AJ11: =ISNUMBER(MATCH(U11&V11,FSData!$Z$7:$Z$95,0)) -> TRUE | AK11: =OR(ISNUMBER(SEARCH("Total",U11,1)),ISNUMBER(SEARCH("Increase (decrease)",U11,1)),ISNUMBER(SEARCH("Operating Activities",U11,1)),ISNUMBER(SEARCH("Investing Activities",U11,1)),ISNUMBER(SEARCH("Financing Activities",U11,1)),ISNUMBER(SEARCH("Cash @",U11,1)),ISNUMBER(SEARCH("Net Income",U11,1)),ISNUMBER(SEARCH("Cash Flow from Operations",U11,1))) -> FALSE | AL11: =AND(NOT(AJ11),NOT(AK11)) -> FALSE | AN11: =ISNUMBER(MATCH(Y11&Z11,FSData!$AB$7:$AB$95,0)) -> TRUE | AO11: =OR(ISNUMBER(SEARCH("Total",Y11,1))) -> FALSE | AP11: =AND(NOT(AN11),NOT(AO11)) -> FALSE
I12: 7 | J12: Inventories | K12: 0 | M12: 2 | N12: Expenses | Q12: 5 | R12: Balance @ 12/31/20x4 | S12: 3 | X12: 7 | Y12: Inventories | Z12: 2 | AC12: =ISNUMBER(MATCH(N12&O12,FSData!$V$7:$V$95,0)) -> TRUE | AD12: =OR(ISNUMBER(SEARCH("Total",N12,1)),ISNUMBER(SEARCH("Net Income",N12,1))) -> FALSE | AE12: =AND(NOT(AC12),NOT(AD12)) -> FALSE | AF12: =ISNUMBER(MATCH(R12&S12,FSData!$X$7:$X$95,0)) -> TRUE | AG12: =OR(ISNUMBER(SEARCH("Total",R12,1)),ISNUMBER(SEARCH("Balance",R12,1))) -> TRUE | AH12: =AND(NOT(AF12),NOT(AG12)) -> FALSE | AJ12: =ISNUMBER(MATCH(U12&V12,FSData!$Z$7:$Z$95,0)) -> TRUE | AK12: =OR(ISNUMBER(SEARCH("Total",U12,1)),ISNUMBER(SEARCH("Increase (decrease)",U12,1)),ISNUMBER(SEARCH("Operating Activities",U12,1)),ISNUMBER(SEARCH("Investing Activities",U12,1)),ISNUMBER(SEARCH("Financing Activities",U12,1)),ISNUMBER(SEARCH("Cash @",U12,1)),ISNUMBER(SEARCH("Net Income",U12,1)),ISNUMBER(SEARCH("Cash Flow from Operations",U12,1))) -> FALSE | AL12: =AND(NOT(AJ12),NOT(AK12)) -> FALSE | AN12: =ISNUMBER(MATCH(Y12&Z12,FSData!$AB$7:$AB$95,0)) -> TRUE | AO12: =OR(ISNUMBER(SEARCH("Total",Y12,1))) -> FALSE | AP12: =AND(NOT(AN12),NOT(AO12)) -> FALSE
C13: Financial Statement | D13: Automate? | I13: 5 | J13: Total Current Assets | K13: 0 | Q13: 3 | R13: Retained Earnings | X13: 5 | Y13: Total Current Assets | Z13: 24.08 | AC13: =ISNUMBER(MATCH(N13&O13,FSData!$V$7:$V$95,0)) -> TRUE | AD13: =OR(ISNUMBER(SEARCH("Total",N13,1)),ISNUMBER(SEARCH("Net Income",N13,1))) -> FALSE | AE13: =AND(NOT(AC13),NOT(AD13)) -> FALSE | AF13: =ISNUMBER(MATCH(R13&S13,FSData!$X$7:$X$95,0)) -> TRUE | AG13: =OR(ISNUMBER(SEARCH("Total",R13,1)),ISNUMBER(SEARCH("Balance",R13,1))) -> FALSE | AH13: =AND(NOT(AF13),NOT(AG13)) -> FALSE | AJ13: =ISNUMBER(MATCH(U13&V13,FSData!$Z$7:$Z$95,0)) -> TRUE | AK13: =OR(ISNUMBER(SEARCH("Total",U13,1)),ISNUMBER(SEARCH("Increase (decrease)",U13,1)),ISNUMBER(SEARCH("Operating Activities",U13,1)),ISNUMBER(SEARCH("Investing Activities",U13,1)),ISNUMBER(SEARCH("Financing Activities",U13,1)),ISNUMBER(SEARCH("Cash @",U13,1)),ISNUMBER(SEARCH("Net Income",U13,1)),ISNUMBER(SEARCH("Cash Flow from Operations",U13,1))) -> FALSE | AL13: =AND(NOT(AJ13),NOT(AK13)) -> FALSE | AN13: =ISNUMBER(MATCH(Y13&Z13,FSData!$AB$7:$AB$95,0)) -> TRUE | AO13: =OR(ISNUMBER(SEARCH("Total",Y13,1))) -> TRUE | AP13: =AND(NOT(AN13),NOT(AO13)) -> FALSE
C14: {=IFERROR(_xlfn._xlws.FILTER(ProblemData!D10:D17,ProblemData!E10:E17),"")} -> Beginning Balance Sheet | D14: TRUE | M14: 6 | N14: Cost of Goods Sold | O14: 18 | Q14: 5 | R14: Balance @ 12/31/20x3 | S14: 0 | AC14: =ISNUMBER(MATCH(N14&O14,FSData!$V$7:$V$95,0)) -> TRUE | AD14: =OR(ISNUMBER(SEARCH("Total",N14,1)),ISNUMBER(SEARCH("Net Income",N14,1))) -> FALSE | AE14: =AND(NOT(AC14),NOT(AD14)) -> FALSE | AF14: =ISNUMBER(MATCH(R14&S14,FSData!$X$7:$X$95,0)) -> TRUE | AG14: =OR(ISNUMBER(SEARCH("Total",R14,1)),ISNUMBER(SEARCH("Balance",R14,1))) -> TRUE | AH14: =AND(NOT(AF14),NOT(AG14)) -> FALSE | AJ14: =ISNUMBER(MATCH(U14&V14,FSData!$Z$7:$Z$95,0)) -> TRUE | AK14: =OR(ISNUMBER(SEARCH("Total",U14,1)),ISNUMBER(SEARCH("Increase (decrease)",U14,1)),ISNUMBER(SEARCH("Operating Activities",U14,1)),ISNUMBER(SEARCH("Investing Activities",U14,1)),ISNUMBER(SEARCH("Financing Activities",U14,1)),ISNUMBER(SEARCH("Cash @",U14,1)),ISNUMBER(SEARCH("Net Income",U14,1)),ISNUMBER(SEARCH("Cash Flow from Operations",U14,1))) -> FALSE | AL14: =AND(NOT(AJ14),NOT(AK14)) -> FALSE | AN14: =ISNUMBER(MATCH(Y14&Z14,FSData!$AB$7:$AB$95,0)) -> TRUE | AO14: =OR(ISNUMBER(SEARCH("Total",Y14,1))) -> FALSE | AP14: =AND(NOT(AN14),NOT(AO14)) -> FALSE
C15: Income Statement | D15: TRUE | I15: 4 | J15: Noncurrent Assets: | M15: 7 | N15: Interest Expense | O15: 1.87 | Q15: 7 | R15: Declared Dividends | S15: -0.05 | X15: 4 | Y15: Noncurrent Assets: | AC15: =ISNUMBER(MATCH(N15&O15,FSData!$V$7:$V$95,0)) -> TRUE | AD15: =OR(ISNUMBER(SEARCH("Total",N15,1)),ISNUMBER(SEARCH("Net Income",N15,1))) -> FALSE | AE15: =AND(NOT(AC15),NOT(AD15)) -> FALSE | AF15: =ISNUMBER(MATCH(R15&S15,FSData!$X$7:$X$95,0)) -> TRUE | AG15: =OR(ISNUMBER(SEARCH("Total",R15,1)),ISNUMBER(SEARCH("Balance",R15,1))) -> FALSE | AH15: =AND(NOT(AF15),NOT(AG15)) -> FALSE | AJ15: =ISNUMBER(MATCH(U15&V15,FSData!$Z$7:$Z$95,0)) -> TRUE | AK15: =OR(ISNUMBER(SEARCH("Total",U15,1)),ISNUMBER(SEARCH("Increase (decrease)",U15,1)),ISNUMBER(SEARCH("Operating Activities",U15,1)),ISNUMBER(SEARCH("Investing Activities",U15,1)),ISNUMBER(SEARCH("Financing Activities",U15,1)),ISNUMBER(SEARCH("Cash @",U15,1)),ISNUMBER(SEARCH("Net Income",U15,1)),ISNUMBER(SEARCH("Cash Flow from Operations",U15,1))) -> FALSE | AL15: =AND(NOT(AJ15),NOT(AK15)) -> FALSE | AN15: =ISNUMBER(MATCH(Y15&Z15,FSData!$AB$7:$AB$95,0)) -> TRUE | AO15: =OR(ISNUMBER(SEARCH("Total",Y15,1))) -> FALSE | AP15: =AND(NOT(AN15),NOT(AO15)) -> FALSE
C16: Statement of Changes in Shareholders' Equity | D16: TRUE | I16: 6 | J16: Property, Plant & Equipment | K16: 0 | M16: 7 | N16: Depreciation Expense | O16: 0.2 | Q16: 7 | R16: Net Income (Loss) | S16: 1.93 | X16: 6 | Y16: Property, Plant & Equipment | Z16: 1 | AC16: =ISNUMBER(MATCH(N16&O16,FSData!$V$7:$V$95,0)) -> TRUE | AD16: =OR(ISNUMBER(SEARCH("Total",N16,1)),ISNUMBER(SEARCH("Net Income",N16,1))) -> FALSE | AE16: =AND(NOT(AC16),NOT(AD16)) -> FALSE | AF16: =ISNUMBER(MATCH(R16&S16,FSData!$X$7:$X$95,0)) -> TRUE | AG16: =OR(ISNUMBER(SEARCH("Total",R16,1)),ISNUMBER(SEARCH("Balance",R16,1))) -> FALSE | AH16: =AND(NOT(AF16),NOT(AG16)) -> FALSE | AJ16: =ISNUMBER(MATCH(U16&V16,FSData!$Z$7:$Z$95,0)) -> TRUE | AK16: =OR(ISNUMBER(SEARCH("Total",U16,1)),ISNUMBER(SEARCH("Increase (decrease)",U16,1)),ISNUMBER(SEARCH("Operating Activities",U16,1)),ISNUMBER(SEARCH("Investing Activities",U16,1)),ISNUMBER(SEARCH("Financing Activities",U16,1)),ISNUMBER(SEARCH("Cash @",U16,1)),ISNUMBER(SEARCH("Net Income",U16,1)),ISNUMBER(SEARCH("Cash Flow from Operations",U16,1))) -> FALSE | AL16: =AND(NOT(AJ16),NOT(AK16)) -> FALSE | AN16: =ISNUMBER(MATCH(Y16&Z16,FSData!$AB$7:$AB$95,0)) -> TRUE | AO16: =OR(ISNUMBER(SEARCH("Total",Y16,1))) -> FALSE | AP16: =AND(NOT(AN16),NOT(AO16)) -> FALSE
C17: Ending Balance Sheet | D17: TRUE | I17: 7 | J17: Accumulated Depreciation | K17: 0 | M17: 7 | N17: Salaries & Wages Expense | O17: 3 | Q17: 5 | R17: Balance @ 12/31/20x4 | S17: 1.88 | T17: 2 | U17: Cash @ 12/31/20x4 | V17: 17.58 | X17: 7 | Y17: Accumulated Depreciation | Z17: -0.2 | AC17: =ISNUMBER(MATCH(N17&O17,FSData!$V$7:$V$95,0)) -> TRUE | AD17: =OR(ISNUMBER(SEARCH("Total",N17,1)),ISNUMBER(SEARCH("Net Income",N17,1))) -> FALSE | AE17: =AND(NOT(AC17),NOT(AD17)) -> FALSE | AF17: =ISNUMBER(MATCH(R17&S17,FSData!$X$7:$X$95,0)) -> FALSE | AG17: =OR(ISNUMBER(SEARCH("Total",R17,1)),ISNUMBER(SEARCH("Balance",R17,1))) -> TRUE | AH17: =AND(NOT(AF17),NOT(AG17)) -> FALSE | AJ17: =ISNUMBER(MATCH(U17&V17,FSData!$Z$7:$Z$95,0)) -> TRUE | AK17: =OR(ISNUMBER(SEARCH("Total",U17,1)),ISNUMBER(SEARCH("Increase (decrease)",U17,1)),ISNUMBER(SEARCH("Operating Activities",U17,1)),ISNUMBER(SEARCH("Investing Activities",U17,1)),ISNUMBER(SEARCH("Financing Activities",U17,1)),ISNUMBER(SEARCH("Cash @",U17,1)),ISNUMBER(SEARCH("Net Income",U17,1)),ISNUMBER(SEARCH("Cash Flow from Operations",U17,1))) -> TRUE | AL17: =AND(NOT(AJ17),NOT(AK17)) -> FALSE | AN17: =ISNUMBER(MATCH(Y17&Z17,FSData!$AB$7:$AB$95,0)) -> TRUE | AO17: =OR(ISNUMBER(SEARCH("Total",Y17,1))) -> FALSE | AP17: =AND(NOT(AN17),NOT(AO17)) -> FALSE
D18: FALSE | I18: 5 | J18: Total Noncurrent Assets | K18: 0 | M18: 5 | N18: Total Expenses | O18: 23.07 | Q18: 2 | R18: Total Shareholders' Equity @ 12/31/20x4 | S18: 4.88 | X18: 5 | Y18: Total Noncurrent Assets | Z18: 0.8 | AC18: =ISNUMBER(MATCH(N18&O18,FSData!$V$7:$V$95,0)) -> TRUE | AD18: =OR(ISNUMBER(SEARCH("Total",N18,1)),ISNUMBER(SEARCH("Net Income",N18,1))) -> TRUE | AE18: =AND(NOT(AC18),NOT(AD18)) -> FALSE | AF18: =ISNUMBER(MATCH(R18&S18,FSData!$X$7:$X$95,0)) -> FALSE | AG18: =OR(ISNUMBER(SEARCH("Total",R18,1)),ISNUMBER(SEARCH("Balance",R18,1))) -> TRUE | AH18: =AND(NOT(AF18),NOT(AG18)) -> FALSE | AJ18: =ISNUMBER(MATCH(U18&V18,FSData!$Z$7:$Z$95,0)) -> TRUE | AK18: =OR(ISNUMBER(SEARCH("Total",U18,1)),ISNUMBER(SEARCH("Increase (decrease)",U18,1)),ISNUMBER(SEARCH("Operating Activities",U18,1)),ISNUMBER(SEARCH("Investing Activities",U18,1)),ISNUMBER(SEARCH("Financing Activities",U18,1)),ISNUMBER(SEARCH("Cash @",U18,1)),ISNUMBER(SEARCH("Net Income",U18,1)),ISNUMBER(SEARCH("Cash Flow from Operations",U18,1))) -> FALSE | AL18: =AND(NOT(AJ18),NOT(AK18)) -> FALSE | AN18: =ISNUMBER(MATCH(Y18&Z18,FSData!$AB$7:$AB$95,0)) -> TRUE | AO18: =OR(ISNUMBER(SEARCH("Total",Y18,1))) -> TRUE | AP18: =AND(NOT(AN18),NOT(AO18)) -> FALSE
D19: FALSE | AC19: =ISNUMBER(MATCH(N19&O19,FSData!$V$7:$V$95,0)) -> TRUE | AD19: =OR(ISNUMBER(SEARCH("Total",N19,1)),ISNUMBER(SEARCH("Net Income",N19,1))) -> FALSE | AE19: =AND(NOT(AC19),NOT(AD19)) -> FALSE | AF19: =ISNUMBER(MATCH(R19&S19,FSData!$X$7:$X$95,0)) -> TRUE | AG19: =OR(ISNUMBER(SEARCH("Total",R19,1)),ISNUMBER(SEARCH("Balance",R19,1))) -> FALSE | AH19: =AND(NOT(AF19),NOT(AG19)) -> FALSE | AJ19: =ISNUMBER(MATCH(U19&V19,FSData!$Z$7:$Z$95,0)) -> TRUE | AK19: =OR(ISNUMBER(SEARCH("Total",U19,1)),ISNUMBER(SEARCH("Increase (decrease)",U19,1)),ISNUMBER(SEARCH("Operating Activities",U19,1)),ISNUMBER(SEARCH("Investing Activities",U19,1)),ISNUMBER(SEARCH("Financing Activities",U19,1)),ISNUMBER(SEARCH("Cash @",U19,1)),ISNUMBER(SEARCH("Net Income",U19,1)),ISNUMBER(SEARCH("Cash Flow from Operations",U19,1))) -> FALSE | AL19: =AND(NOT(AJ19),NOT(AK19)) -> FALSE | AN19: =ISNUMBER(MATCH(Y19&Z19,FSData!$AB$7:$AB$95,0)) -> TRUE | AO19: =OR(ISNUMBER(SEARCH("Total",Y19,1))) -> FALSE | AP19: =AND(NOT(AN19),NOT(AO19)) -> FALSE
D20: FALSE | I20: 3 | J20: Total Assets | K20: 0 | M20: 3 | N20: Net Income | O20: 1.93 | X20: 3 | Y20: Total Assets | Z20: 24.88 | AC20: =ISNUMBER(MATCH(N20&O20,FSData!$V$7:$V$95,0)) -> TRUE | AD20: =OR(ISNUMBER(SEARCH("Total",N20,1)),ISNUMBER(SEARCH("Net Income",N20,1))) -> TRUE | AE20: =AND(NOT(AC20),NOT(AD20)) -> FALSE | AF20: =ISNUMBER(MATCH(R20&S20,FSData!$X$7:$X$95,0)) -> TRUE | AG20: =OR(ISNUMBER(SEARCH("Total",R20,1)),ISNUMBER(SEARCH("Balance",R20,1))) -> FALSE | AH20: =AND(NOT(AF20),NOT(AG20)) -> FALSE | AJ20: =ISNUMBER(MATCH(U20&V20,FSData!$Z$7:$Z$95,0)) -> TRUE | AK20: =OR(ISNUMBER(SEARCH("Total",U20,1)),ISNUMBER(SEARCH("Increase (decrease)",U20,1)),ISNUMBER(SEARCH("Operating Activities",U20,1)),ISNUMBER(SEARCH("Investing Activities",U20,1)),ISNUMBER(SEARCH("Financing Activities",U20,1)),ISNUMBER(SEARCH("Cash @",U20,1)),ISNUMBER(SEARCH("Net Income",U20,1)),ISNUMBER(SEARCH("Cash Flow from Operations",U20,1))) -> FALSE | AL20: =AND(NOT(AJ20),NOT(AK20)) -> FALSE | AN20: =ISNUMBER(MATCH(Y20&Z20,FSData!$AB$7:$AB$95,0)) -> TRUE | AO20: =OR(ISNUMBER(SEARCH("Total",Y20,1))) -> TRUE | AP20: =AND(NOT(AN20),NOT(AO20)) -> FALSE
D21: FALSE | AC21: =ISNUMBER(MATCH(N21&O21,FSData!$V$7:$V$95,0)) -> TRUE | AD21: =OR(ISNUMBER(SEARCH("Total",N21,1)),ISNUMBER(SEARCH("Net Income",N21,1))) -> FALSE | AE21: =AND(NOT(AC21),NOT(AD21)) -> FALSE | AF21: =ISNUMBER(MATCH(R21&S21,FSData!$X$7:$X$95,0)) -> TRUE | AG21: =OR(ISNUMBER(SEARCH("Total",R21,1)),ISNUMBER(SEARCH("Balance",R21,1))) -> FALSE | AH21: =AND(NOT(AF21),NOT(AG21)) -> FALSE | AJ21: =ISNUMBER(MATCH(U21&V21,FSData!$Z$7:$Z$95,0)) -> TRUE | AK21: =OR(ISNUMBER(SEARCH("Total",U21,1)),ISNUMBER(SEARCH("Increase (decrease)",U21,1)),ISNUMBER(SEARCH("Operating Activities",U21,1)),ISNUMBER(SEARCH("Investing Activities",U21,1)),ISNUMBER(SEARCH("Financing Activities",U21,1)),ISNUMBER(SEARCH("Cash @",U21,1)),ISNUMBER(SEARCH("Net Income",U21,1)),ISNUMBER(SEARCH("Cash Flow from Operations",U21,1))) -> FALSE | AL21: =AND(NOT(AJ21),NOT(AK21)) -> FALSE | AN21: =ISNUMBER(MATCH(Y21&Z21,FSData!$AB$7:$AB$95,0)) -> TRUE | AO21: =OR(ISNUMBER(SEARCH("Total",Y21,1))) -> FALSE | AP21: =AND(NOT(AN21),NOT(AO21)) -> FALSE
I22: 2 | J22: Liabilities | X22: 2 | Y22: Liabilities | AC22: =ISNUMBER(MATCH(N22&O22,FSData!$V$7:$V$95,0)) -> TRUE | AD22: =OR(ISNUMBER(SEARCH("Total",N22,1)),ISNUMBER(SEARCH("Net Income",N22,1))) -> FALSE | AE22: =AND(NOT(AC22),NOT(AD22)) -> FALSE | AF22: =ISNUMBER(MATCH(R22&S22,FSData!$X$7:$X$95,0)) -> TRUE | AG22: =OR(ISNUMBER(SEARCH("Total",R22,1)),ISNUMBER(SEARCH("Balance",R22,1))) -> FALSE | AH22: =AND(NOT(AF22),NOT(AG22)) -> FALSE | AJ22: =ISNUMBER(MATCH(U22&V22,FSData!$Z$7:$Z$95,0)) -> TRUE | AK22: =OR(ISNUMBER(SEARCH("Total",U22,1)),ISNUMBER(SEARCH("Increase (decrease)",U22,1)),ISNUMBER(SEARCH("Operating Activities",U22,1)),ISNUMBER(SEARCH("Investing Activities",U22,1)),ISNUMBER(SEARCH("Financing Activities",U22,1)),ISNUMBER(SEARCH("Cash @",U22,1)),ISNUMBER(SEARCH("Net Income",U22,1)),ISNUMBER(SEARCH("Cash Flow from Operations",U22,1))) -> FALSE | AL22: =AND(NOT(AJ22),NOT(AK22)) -> FALSE | AN22: =ISNUMBER(MATCH(Y22&Z22,FSData!$AB$7:$AB$95,0)) -> TRUE | AO22: =OR(ISNUMBER(SEARCH("Total",Y22,1))) -> FALSE | AP22: =AND(NOT(AN22),NOT(AO22)) -> FALSE
AC23: =ISNUMBER(MATCH(N23&O23,FSData!$V$7:$V$95,0)) -> TRUE | AD23: =OR(ISNUMBER(SEARCH("Total",N23,1)),ISNUMBER(SEARCH("Net Income",N23,1))) -> FALSE | AE23: =AND(NOT(AC23),NOT(AD23)) -> FALSE | AF23: =ISNUMBER(MATCH(R23&S23,FSData!$X$7:$X$95,0)) -> TRUE | AG23: =OR(ISNUMBER(SEARCH("Total",R23,1)),ISNUMBER(SEARCH("Balance",R23,1))) -> FALSE | AH23: =AND(NOT(AF23),NOT(AG23)) -> FALSE | AJ23: =ISNUMBER(MATCH(U23&V23,FSData!$Z$7:$Z$95,0)) -> TRUE | AK23: =OR(ISNUMBER(SEARCH("Total",U23,1)),ISNUMBER(SEARCH("Increase (decrease)",U23,1)),ISNUMBER(SEARCH("Operating Activities",U23,1)),ISNUMBER(SEARCH("Investing Activities",U23,1)),ISNUMBER(SEARCH("Financing Activities",U23,1)),ISNUMBER(SEARCH("Cash @",U23,1)),ISNUMBER(SEARCH("Net Income",U23,1)),ISNUMBER(SEARCH("Cash Flow from Operations",U23,1))) -> FALSE | AL23: =AND(NOT(AJ23),NOT(AK23)) -> FALSE | AN23: =ISNUMBER(MATCH(Y23&Z23,FSData!$AB$7:$AB$95,0)) -> TRUE | AO23: =OR(ISNUMBER(SEARCH("Total",Y23,1))) -> FALSE | AP23: =AND(NOT(AN23),NOT(AO23)) -> FALSE | AR23: FSBuilder Menu construction
C24: Statement | D24: Category | E24: Account or Explanation | F24: Amount | I24: 4 | J24: Current Liabilities: | X24: 4 | Y24: Current Liabilities: | AC24: =ISNUMBER(MATCH(N24&O24,FSData!$V$7:$V$95,0)) -> TRUE | AD24: =OR(ISNUMBER(SEARCH("Total",N24,1)),ISNUMBER(SEARCH("Net Income",N24,1))) -> FALSE | AE24: =AND(NOT(AC24),NOT(AD24)) -> FALSE | AF24: =ISNUMBER(MATCH(R24&S24,FSData!$X$7:$X$95,0)) -> TRUE | AG24: =OR(ISNUMBER(SEARCH("Total",R24,1)),ISNUMBER(SEARCH("Balance",R24,1))) -> FALSE | AH24: =AND(NOT(AF24),NOT(AG24)) -> FALSE | AJ24: =ISNUMBER(MATCH(U24&V24,FSData!$Z$7:$Z$95,0)) -> TRUE | AK24: =OR(ISNUMBER(SEARCH("Total",U24,1)),ISNUMBER(SEARCH("Increase (decrease)",U24,1)),ISNUMBER(SEARCH("Operating Activities",U24,1)),ISNUMBER(SEARCH("Investing Activities",U24,1)),ISNUMBER(SEARCH("Financing Activities",U24,1)),ISNUMBER(SEARCH("Cash @",U24,1)),ISNUMBER(SEARCH("Net Income",U24,1)),ISNUMBER(SEARCH("Cash Flow from Operations",U24,1))) -> FALSE | AL24: =AND(NOT(AJ24),NOT(AK24)) -> FALSE | AN24: =ISNUMBER(MATCH(Y24&Z24,FSData!$AB$7:$AB$95,0)) -> TRUE | AO24: =OR(ISNUMBER(SEARCH("Total",Y24,1))) -> FALSE | AP24: =AND(NOT(AN24),NOT(AO24)) -> FALSE | AR24: Accnt | AS24: Category
C25: Beginning Balance Sheet | D25: Noncurrent Liabilities | E25: Notes Payable | F25: 0 | H25: =_xlfn.TEXTJOIN(6,1,FSBuilder[[#This Row],[Statement]:[Account or Explanation]]) -> Beginning Balance Sheet6 Noncurrent Liabilities6Notes Payable | I25: 6 | J25: Interest Payable | K25: 0 | X25: 6 | Y25: Interest Payable | Z25: 0 | AC25: =ISNUMBER(MATCH(N25&O25,FSData!$V$7:$V$95,0)) -> TRUE | AD25: =OR(ISNUMBER(SEARCH("Total",N25,1)),ISNUMBER(SEARCH("Net Income",N25,1))) -> FALSE | AE25: =AND(NOT(AC25),NOT(AD25)) -> FALSE | AF25: =ISNUMBER(MATCH(R25&S25,FSData!$X$7:$X$95,0)) -> TRUE | AG25: =OR(ISNUMBER(SEARCH("Total",R25,1)),ISNUMBER(SEARCH("Balance",R25,1))) -> FALSE | AH25: =AND(NOT(AF25),NOT(AG25)) -> FALSE | AJ25: =ISNUMBER(MATCH(U25&V25,FSData!$Z$7:$Z$95,0)) -> TRUE | AK25: =OR(ISNUMBER(SEARCH("Total",U25,1)),ISNUMBER(SEARCH("Increase (decrease)",U25,1)),ISNUMBER(SEARCH("Operating Activities",U25,1)),ISNUMBER(SEARCH("Investing Activities",U25,1)),ISNUMBER(SEARCH("Financing Activities",U25,1)),ISNUMBER(SEARCH("Cash @",U25,1)),ISNUMBER(SEARCH("Net Income",U25,1)),ISNUMBER(SEARCH("Cash Flow from Operations",U25,1))) -> FALSE | AL25: =AND(NOT(AJ25),NOT(AK25)) -> FALSE | AN25: =ISNUMBER(MATCH(Y25&Z25,FSData!$AB$7:$AB$95,0)) -> TRUE | AO25: =OR(ISNUMBER(SEARCH("Total",Y25,1))) -> FALSE | AP25: =AND(NOT(AN25),NOT(AO25)) -> FALSE | AR25: {=_xlfn.IFS(ISNUMBER(SEARCH("Balance",C25,1)),"MasterData!O56#",ISNUMBER(SEARCH("Income St",C25,1)),"MasterData!O116#",ISNUMBER(SEARCH("Shareholders",C25,1)),"D115#",ISNUMBER(SEARCH("Cash Flow",C25,1)),"E115#",ISNUMBER(SEARCH("Noncash",C25,1)),"C139#",ISNUMBER(SEARCH("Comprehensive",C25,1)),"E145",ISNUMBER(SEARCH("Reconciliation",C25,1)),"D137#")} -> MasterData!O56# | AS25: {=_xlfn.IFS(ISNUMBER(SEARCH("Balance",C25,1)),"AX25:AX29",ISNUMBER(SEARCH("Income St",C25,1)),"AY25:AY28",ISNUMBER(SEARCH("Shareholders",C25,1)),"EquityUsed",ISNUMBER(SEARCH("Cash Flow",C25,1)),"BA25:BA27",ISNUMBER(SEARCH("Noncash",C25,1)),"AZ25",ISNUMBER(SEARCH("Comprehensive",C25,1)),"AZ25",ISNUMBER(SEARCH("Reconciliation",C25,1)),"BB25:BB26")} -> AX25:AX29 | AU25: {=INDIRECT(AR25)} -> Accounts Receivable | AX25: Current Assets | AY25: Revenues | AZ25: None | BA25: Operating Activities | BB25: Adjustments
