Workbook
Name College1: 'Student-Names'!$B$171
Name College10: 'Student-Names'!$B$180
Name College11: 'Student-Names'!$B$181
Name College2: 'Student-Names'!$B$172
Name College3: 'Student-Names'!$B$173
Name College4: 'Student-Names'!$B$174
Name College5: 'Student-Names'!$B$175
Name College6: 'Student-Names'!$B$176
Name College7: 'Student-Names'!$B$177
Name College8: 'Student-Names'!$B$178
Name College9: 'Student-Names'!$B$179
Name Name1: 'Student-Names'!$B$158
Name Name10: 'Student-Names'!$B$167
Name Name11: 'Student-Names'!$B$168
Name Name2: 'Student-Names'!$B$159
Name Name3: 'Student-Names'!$B$160
Name Name4: 'Student-Names'!$B$161
Name Name5: 'Student-Names'!$B$162
Name Name6: 'Student-Names'!$B$163
Name Name7: 'Student-Names'!$B$164
Name Name8: 'Student-Names'!$B$165
Name Name9: 'Student-Names'!$B$166
Name Slicer_College: #N/A
Name Slicer_Major__Primary: #N/A
Name Slicer_Year: #N/A

Sheet Ponzi-Game-Data
A1: Person | B1: Endowment | C1: Round 1 | E1: Round 2 | G1: Round 3 | I1: Ending Bitcoin | J1: Won(Lost) | K1: Final Bal per Statements | Q1: US Justice System | R1: Ends Up | U1: Exchange Rate | X1: US Justice System | Y1: Ends Up
A2: =Name1 -> Meena Ambati | B2: 5 | C2: -5 | D2: 10 | I2: =B2+SUM(C2:H2) -> 10 | J2: =I2-B2 -> 5 | K2: 0 | M2: Winner | O2: Net Winners Won | P2: =SUMIF(J2:J12,">0") -> 20 | Q2: =-P2 -> -20 | R2: =SUM(P2:Q2) -> 0 | U2: 26102.69 | V2: Net Winners Won | W2: =P2*$U$2 -> 522053.8 | X2: =Q2*$U$2 -> -522053.8 | Y2: =R2*$U$2 -> 0
A3: =Name2 -> Erin Daniels | B3: 5 | C3: -5 | D3: 5 | F3: 10 | I3: =B3+SUM(C3:H3) -> 15 | J3: =I3-B3 -> 10 | M3: Winner | O3: Net Losers Lost | P3: =SUMIF(J2:J12,"<0") -> -155 | Q3: =-Q2 -> 20 | R3: =SUM(P3:Q3) -> -135 | V3: Net Losers Lost | W3: =P3*$U$2 -> -4045916.9 | X3: =Q3*$U$2 -> 522053.8 | Y3: =R3*$U$2 -> -3523863.1
A4: =Name3 -> Sydney Mitchell | B4: 5 | C4: -5 | F4: 10 | I4: =B4+SUM(C4:H4) -> 10 | J4: =I4-B4 -> 5 | M4: Winner | O4: Rick Took | P4: =J13 -> 135 | R4: =SUM(P4:Q4) -> 135 | S4: In Jail!! | V4: Rick Took | W4: =P4*$U$2 -> 3523863.1 | X4: =Q4*$U$2 -> 0 | Y4: =R4*$U$2 -> 3523863.1
A5: =Name4 -> Claiborne Tompkins | B5: 5 | C5: -5 | I5: =B5+SUM(C5:H5) -> 0 | J5: =I5-B5 -> -5 | M5: Winner | O5: Total | P5: =SUM(P2:P4) -> 0 | Q5: =SUM(Q2:Q4) -> 0 | R5: =SUM(P5:Q5) -> 0 | V5: Total | W5: =SUM(W2:W4) -> 0 | X5: =SUM(X2:X4) -> 0 | Y5: =SUM(W5:X5) -> 0
A6: =Name5 -> Olivia Kim | B6: 10 | E6: -10 | I6: =B6+SUM(C6:H6) -> 0 | J6: =I6-B6 -> -10 | M6: Winner
A7: =Name6 -> Kiley Capstraw | B7: 10 | E7: -10 | F7: 10 | I7: =B7+SUM(C7:H7) -> 10 | J7: =I7-B7 -> 0 | M7: Loser | O7: Attorneys, Trustees, etc. Fees?
A8: =Name7 -> Isaac Monks | B8: 10 | E8: -10 | I8: =B8+SUM(C8:H8) -> 0 | J8: =I8-B8 -> -10 | M8: Loser | O8: Last time I looked (almost 10 years ago): | R8: $900 million in Madoff Case
A9: =Name8 -> Ruben Berreby | B9: 10 | E9: -10 | I9: =B9+SUM(C9:H9) -> 0 | J9: =I9-B9 -> -10 | M9: Loser | O9: More recently, $1.25 billion --- to one law firm alone!
A10: =Name9 -> Joya Xu | B10: 40 | G10: -40 | I10: =B10+SUM(C10:H10) -> 0 | J10: =I10-B10 -> -40 | M10: Loser
A11: =Name10 -> Emma Lee | B11: 40 | G11: -40 | I11: =B11+SUM(C11:H11) -> 0 | J11: =I11-B11 -> -40 | M11: Loser
A12: =Name11 -> Lucas Szydlowski | B12: 40 | G12: -40 | I12: =B12+SUM(C12:H12) -> 0 | J12: =I12-B12 -> -40 | M12: Loser
A13: RICK | B13: 0 | D13: =-SUM(C2:C12)-SUM(D2:D12) -> 5 | F13: =D13-SUM(E2:E12)-SUM(F2:F12) -> 15 | H13: =F13-SUM(G2:G12)-SUM(H2:H12) -> 135 | I13: =H13 -> 135 | J13: =-SUM(J2:J12) -> 135 | M13: BIG Winner!
A14: Total | B14: =SUM(B2:B13) -> 180 | I14: =SUM(I2:I13) -> 180
B17: First Name | C17: Last Name | D17: Amount | E17: USD
A18: 1 | D18: 5 | E18: =D18*$F$30 -> 458482.4
A19: 2 | D19: 5 | E19: =D19*$F$30 -> 458482.4
A20: 3 | D20: 5 | E20: =D20*$F$30 -> 458482.4
A21: 4 | D21: 5 | E21: =D21*$F$30 -> 458482.4
A22: 5 | D22: 10 | E22: =D22*$F$30 -> 916964.8
A23: 6 | D23: 10 | E23: =D23*$F$30 -> 916964.8
A24: 7 | D24: 10 | E24: =D24*$F$30 -> 916964.8
A25: 8 | D25: 10 | E25: =D25*$F$30 -> 916964.8
A26: 9 | D26: 40 | E26: =D26*$F$30 -> 3667859.2
A27: 10 | D27: 40 | E27: =D27*$F$30 -> 3667859.2
A28: 11 | D28: 40 | E28: =D28*$F$30 -> 3667859.2
E29: =SUM(E18:E28) -> 16505366 | F29: $/₿
E30: #VALUE! | F30: {=_FV(E30,"Price")} -> 91696.48
A45: All deposits occur at the beginning of the round.
A46: All withdrawals occur at the end of the round.
C49: Round 1
D50: Beg Bal | E50: Deposit | F50: "Earnings" | G50: Withdrawals | H50: Balance
C51: =Name1 -> Meena Ambati | D51: 0 | E51: 5 | F51: =(D51+E51) -> 5 | G51: 10 | H51: =D51+E51+F51-G51 -> 0
C52: =Name2 -> Erin Daniels | D52: 0 | E52: 5 | F52: =(D52+E52) -> 5 | G52: 5 | H52: =D52+E52+F52-G52 -> 5
C53: =Name3 -> Sydney Mitchell | D53: 0 | E53: 5 | F53: =(D53+E53) -> 5 | G53: 0 | H53: =D53+E53+F53-G53 -> 10
C54: =Name4 -> Claiborne Tompkins | D54: 0 | E54: 5 | F54: =(D54+E54) -> 5 | G54: 0 | H54: =D54+E54+F54-G54 -> 10
C55: Total | D55: =SUM(D51:D54) -> 0 | E55: =SUM(E51:E54) -> 20 | F55: =SUM(F51:F54) -> 20 | G55: =SUM(G51:G54) -> 15 | H55: =SUM(H51:H54) -> 25
C58: Round 2
D59: Beg Bal | E59: Deposit | F59: "Earnings" | G59: Withdrawals | H59: Balance
C60: =Name1 -> Meena Ambati | D60: =H51 -> 0 | E60: 0 | F60: =(D60+E60) -> 0 | H60: =D60+E60+F60-G60 -> 0
...

Sheet Game-Data
B2: Acct # | C2: Name | D2: Endowment | I2: From RLAIS
B3: 1 | C3: ='Student-Names'!B158 -> Meena Ambati | D3: 5 | G3: Investor | H3: Endowment | I3: Deposits | J3: Withdrawals | K3: Net | L3: Ending Wealth
B4: 2 | C4: ='Student-Names'!B159 -> Erin Daniels | D4: 5 | G4: =C3 -> Meena Ambati | H4: 5 | I4: 5 | J4: 10 | K4: 5 | L4: 10
B5: 3 | C5: ='Student-Names'!B160 -> Sydney Mitchell | D5: 5 | G5: =C4 -> Erin Daniels | H5: 5 | I5: 5 | J5: 15 | K5: 10 | L5: 15
B6: 4 | C6: ='Student-Names'!B161 -> Claiborne Tompkins | D6: 5 | G6: =C5 -> Sydney Mitchell | H6: 5 | I6: 5 | J6: 10 | K6: 5 | L6: 10
B7: 5 | C7: ='Student-Names'!B162 -> Olivia Kim | D7: 10 | G7: =C6 -> Claiborne Tompkins | H7: 5 | I7: 5 | K7: -5 | L7: 0
B8: 6 | C8: ='Student-Names'!B163 -> Kiley Capstraw | D8: 10 | G8: =C7 -> Olivia Kim | H8: 10 | I8: 10 | K8: -10 | L8: 0
B9: 7 | C9: ='Student-Names'!B164 -> Isaac Monks | D9: 10 | G9: =C8 -> Kiley Capstraw | H9: 10 | I9: 10 | J9: 10 | K9: 0 | L9: 10
B10: 8 | C10: ='Student-Names'!B165 -> Ruben Berreby | D10: 10 | G10: =C9 -> Isaac Monks | H10: 10 | I10: 10 | K10: -10 | L10: 0
B11: 9 | C11: ='Student-Names'!B166 -> Joya Xu | D11: 40 | G11: =C10 -> Ruben Berreby | H11: 10 | I11: 10 | K11: -10 | L11: 0
B12: 10 | C12: ='Student-Names'!B167 -> Emma Lee | D12: 40 | G12: =C11 -> Joya Xu | H12: 40 | I12: 40 | K12: -40 | L12: 0
B13: 11 | C13: ='Student-Names'!B168 -> Lucas Szydlowski | D13: 40 | G13: =C12 -> Emma Lee | H13: 40 | I13: 40 | K13: -40 | L13: 0
G14: =C13 -> Lucas Szydlowski | H14: 40 | I14: 40 | K14: -40 | L14: 0
G15: Total | H15: =SUM(H4:H14) -> 180 | K15: =SUM(K4:K14) -> -135 | L15: =SUM(L4:L14) -> 45
C20: Substitutes
C21: ='Student-Names'!A184&" "&'Student-Names'!B184 -> Claire Zhong
C22: ='Student-Names'!A185&" "&'Student-Names'!B185 -> Hettie Whittington
C23: ='Student-Names'!A186&" "&'Student-Names'!B186 -> Jonathan Bernard
C24: ='Student-Names'!A187&" "&'Student-Names'!B187 -> Jack Pankey
C25: ='Student-Names'!A188&" "&'Student-Names'!B188 -> Edward Liao
C26: ='Student-Names'!A189&" "&'Student-Names'!B189 -> Krish Gupta
C27: ='Student-Names'!A190&" "&'Student-Names'!B190 -> Shaurya Sharma
C28: ='Student-Names'!A191&" "&'Student-Names'!B191 -> Joseph Farouz
C29: ='Student-Names'!A192&" "&'Student-Names'!B192 -> Jonathan Adler
C30: ='Student-Names'!A193&" "&'Student-Names'!B193 -> Tom Monaghan

Sheet Account-Statements
A2: RLA Investment Securities LLC
C4: Acct#
C5: 1
B7: Beginning balance | C7: 0
B8: Deposits | C8: 5
B9: Earnings | C9: 5
B10: Withdrawals | C10: -10
B11: Balance | C11: =SUM(C7:C10) -> 0
A15: RLA Investment Securities LLC | E15: RLA Investment Securities LLC
C17: Acct# | G17: Acct#
C18: 2 | G18: 2
B20: Beginning balance | C20: 0 | F20: Beginning balance | G20: 5
B21: Deposits | C21: 5 | F21: Deposits | G21: 0
B22: Earnings | C22: 5 | F22: Earnings | G22: 5
B23: Withdrawals | C23: -5 | F23: Withdrawals | G23: -10
B24: Balance | C24: =SUM(C20:C23) -> 5 | F24: Balance | G24: =SUM(G20:G23) -> 0
A28: RLA Investment Securities LLC | E28: RLA Investment Securities LLC | I28: RLA Investment Securities LLC
C30: Acct# | G30: Acct# | K30: Acct#
C31: 3 | G31: 3 | K31: 3
B33: Beginning balance | C33: 0 | F33: Beginning balance | G33: 10 | J33: Beginning balance | K33: 10
B34: Deposits | C34: 5 | F34: Deposits | G34: 0 | J34: Deposits | K34: 0
B35: Earnings | C35: 5 | F35: Earnings | G35: 10 | J35: Earnings | K35: 10
B36: Withdrawals | C36: 0 | F36: Withdrawals | G36: -10 | J36: Withdrawals | K36: 0
B37: Balance | C37: =SUM(C33:C36) -> 10 | F37: Balance | G37: =SUM(G33:G36) -> 10 | J37: Balance | K37: =SUM(K33:K36) -> 20
A41: RLA Investment Securities LLC | E41: RLA Investment Securities LLC | I41: RLA Investment Securities LLC
C43: Acct# | G43: Acct# | K43: Acct#
C44: 4 | G44: 4 | K44: 4
B46: Beginning balance | C46: 0 | F46: Beginning balance | G46: 10 | J46: Beginning balance | K46: 20
B47: Deposits | C47: 5 | F47: Deposits | G47: 0 | J47: Deposits | K47: 0
B48: Earnings | C48: 5 | F48: Earnings | G48: 10 | J48: Earnings | K48: 20
B49: Withdrawals | C49: 0 | F49: Withdrawals | G49: 0 | J49: Withdrawals | K49: 0
B50: Balance | C50: =SUM(C46:C49) -> 10 | F50: Balance | G50: =SUM(G46:G49) -> 20 | J50: Balance | K50: =SUM(K46:K49) -> 40
E54: RLA Investment Securities LLC
G56: Acct#
G57: 5
F59: Beginning balance | G59: 0
F60: Deposits | G60: 10
F61: Earnings | G61: 10
F62: Withdrawals | G62: 0
F63: Balance | G63: =SUM(G59:G62) -> 20
...

Sheet Student-Names
A1: Last Name | B1: First Name | C1: Role | D1: College | E1: Major (Primary) | F1: Year | G1: Rand | H1: Present | J1: # of players
A2: Ambati | B2: Meena | C2: Visitor | D2: Trumbull College | E2: Ecology & Evolutionary Biology | F2: 26 | G2: 1 | H2: Yes | J2: =COUNTIF(Table1[Present],"Yes") -> 139
A3: Daniels | B3: Erin | C3: Student | D3: Benjamin Franklin College | E3: Economics | F3: 27 | G3: 2 | H3: Yes
A4: Mitchell | B4: Sydney | C4: Student | D4: Pierson College | E4: Political Science | F4: 27 | G4: 3 | H4: Yes
A5: Tompkins | B5: Claiborne | C5: Visitor | D5: Saybrook College | E5: Undeclared | F5: 29 | G5: 4 | H5: Yes
A6: Kim | B6: Olivia | C6: Student | D6: Pauli Murray College | E6: Undeclared | F6: 29 | G6: 5 | H6: Yes
A7: Capstraw | B7: Kiley | C7: Student | D7: Pauli Murray College | E7: Psychology | F7: 26 | G7: 6 | H7: Yes
A8: Monks | B8: Isaac | C8: Student | D8: Timothy Dwight College | E8: American Studies | F8: 28 | G8: 7 | H8: Yes
A9: Berreby | B9: Ruben | C9: Student | D9: Saybrook College | E9: Undeclared | F9: 29 | G9: 8 | H9: Yes
A10: Xu | B10: Joya | C10: Student | D10: Saybrook College | E10: Undeclared | F10: 29 | G10: 9 | H10: Yes
A11: Lee | B11: Emma | C11: Student | D11: Grace Hopper College | E11: Undeclared | F11: 29 | G11: 10 | H11: Yes
A12: Szydlowski | B12: Lucas | C12: Student | D12: Jonathan Edwards College | E12: Undeclared | F12: 29 | G12: 11 | H12: Yes
A13: Wang | B13: Noria | C13: Student | D13: School of Public Health | E13: Biostatistics | F13: 27 | G13: 12 | H13: Yes
A14: Zhong | B14: Claire | C14: Visitor | D14: Branford College | E14: Computer Science & Mathematics | F14: 28 | G14: 13 | H14: Yes
... A41: Hansen | B41: Sophie | C41: Student | D41: Davenport College | E41: Economics & Mathematics | F41: 28 | G41: 40 | H41: Yes
H42: Yes
H43: Yes
H44: Yes
H45: Yes
H46: Yes
H47: Yes
H48: Yes
H49: Yes
H50: Yes
H51: Yes
H52: Yes
H53: Yes
... H140: Yes
A144: =I144 -> Meena | B144: =J144 -> Ambati | C144: =K144 -> Trumbull College | I144: {=_xlfn._xlws.FILTER(CHOOSE({1,2,3},Table1[First Name],Table1[Last Name],Table1[College]),Table1[Present]="Yes","")} -> Meena | J144: Ambati | K144: Trumbull College
A145: =I145 -> Erin | B145: =J145 -> Daniels | C145: =K145 -> Benjamin Franklin College | I145: Erin | J145: Daniels | K145: Benjamin Franklin College
A146: =I146 -> Sydney | B146: =J146 -> Mitchell | C146: =K146 -> Pierson College | I146: Sydney | J146: Mitchell | K146: Pierson College
A147: =I147 -> Claiborne | B147: =J147 -> Tompkins | C147: =K147 -> Saybrook College | I147: Claiborne | J147: Tompkins | K147: Saybrook College
A148: =I148 -> Olivia | B148: =J148 -> Kim | C148: =K148 -> Pauli Murray College | I148: Olivia | J148: Kim | K148: Pauli Murray College
A149: =I149 -> Kiley | B149: =J149 -> Capstraw | C149: =K149 -> Pauli Murray College | I149: Kiley | J149: Capstraw | K149: Pauli Murray College
A150: =I150 -> Isaac | B150: =J150 -> Monks | C150: =K150 -> Timothy Dwight College | I150: Isaac | J150: Monks | K150: Timothy Dwight College
A151: =I151 -> Ruben | B151: =J151 -> Berreby | C151: =K151 -> Saybrook College | I151: Ruben | J151: Berreby | K151: Saybrook College
A152: =I152 -> Joya | B152: =J152 -> Xu | C152: =K152 -> Saybrook College | I152: Joya | J152: Xu | K152: Saybrook College
A153: =I153 -> Emma | B153: =J153 -> Lee | C153: =K153 -> Grace Hopper College | I153: Emma | J153: Lee | K153: Grace Hopper College
A154: =I154 -> Lucas | B154: =J154 -> Szydlowski | C154: =K154 -> Jonathan Edwards College | I154: Lucas | J154: Szydlowski | K154: Jonathan Edwards College
I155: Noria | J155: Wang | K155: School of Public Health
...
